Workbook

Sheet Dashboard
B2: US LEADING INDICATORS — USEFULNESS IN TRACKING GDP
B3: Top-10 ranking from 'Table 1: Usefulness in tracking GDP' (intrinsic values as published; Goldman Sachs research ranking). Full free-data history + Analysis-3.0 statistical layer + 3 charts per sheet · refreshed 2026-08-10
B5: Rank | C5: Indicator (as ranked) | D5: Intrinsic value | E5: Sheet | F5: Coverage | G5: Latest date | H5: Latest | I5: Z-metric | J5: Z (hist) | K5: Pctl | L5: Economy read
B6: 1 | C6: Philadelphia Fed index | D6: 2.92 | E6: PHILLY | F6: =TEXT(MIN(PHILLY!$A$5:$A$703),"yyyy")&"–"&TEXT(MAX(PHILLY!$A$5:$A$703),"yyyy-mm")&" ("&COUNT(PHILLY!$B$5:$B$703)&")" -> 1968–2026-07 (699) | G6: =MAX(PHILLY!$A$5:$A$703) -> 46204 | H6: =PHILLY!$B$703 -> 41.4 | I6: level | J6: =PHILLY!$G$6 -> 1.7450718 | K6: =PHILLY!$G$7 -> 0.975 | L6: =PHILLY!$G$9 -> STRONG vs history
B7: 2 | C7: Initial unemployment claims | D7: 2.77 | E7: CLAIMS | F7: =TEXT(MIN(CLAIMS!$A$5:$A$3113),"yyyy")&"–"&TEXT(MAX(CLAIMS!$A$5:$A$3113),"yyyy-mm")&" ("&COUNT(CLAIMS!$B$5:$B$3113)&")" -> 1967–2026-08 (3109) | G7: =MAX(CLAIMS!$A$5:$A$3113) -> 46235 | H7: =CLAIMS!$B$3113 -> 199000 | I7: level | J7: =CLAIMS!$G$6 -> -0.67270244 | K7: =CLAIMS!$G$7 -> 0.025 | L7: =CLAIMS!$G$9 -> NEUTRAL vs history (inverted: high = weakness)
B8: 3 | C8: UM consumer confidence preliminary | D8: 2.06 | E8: UMCSI | F8: =TEXT(MIN(UMCSI!$A$5:$A$679),"yyyy")&"–"&TEXT(MAX(UMCSI!$A$5:$A$679),"yyyy-mm")&" ("&COUNT(UMCSI!$B$5:$B$679)&")" -> 1952–2026-07 (675) | G8: =MAX(UMCSI!$A$5:$A$679) -> 46204 | H8: =UMCSI!$B$679 -> 55.2 | I8: level | J8: =UMCSI!$G$6 -> -2.131849 | K8: =UMCSI!$G$7 -> 0.02 | L8: =UMCSI!$G$9 -> WEAK vs history
B9: 4 | C9: Chicago PMI | D9: 1.53 | E9: CHIPMI | F9: =TEXT(MIN(CHIPMI!$A$5:$A$716),"yyyy")&"–"&TEXT(MAX(CHIPMI!$A$5:$A$716),"yyyy-mm")&" ("&COUNT(CHIPMI!$B$5:$B$716)&")" -> 1967–2026-06 (712) | G9: =MAX(CHIPMI!$A$5:$A$716) -> 46174 | H9: =CHIPMI!$B$716 -> -0.02 | I9: level | J9: =CHIPMI!$G$6 -> -0.019659417 | K9: =CHIPMI!$G$7 -> 0.426 | L9: =CHIPMI!$G$9 -> NEUTRAL vs history
B10: 5 | C10: Nonfarm payroll employment | D10: 1.19 | E10: NFP | F10: =TEXT(MIN(NFP!$A$5:$A$1055),"yyyy")&"–"&TEXT(MAX(NFP!$A$5:$A$1055),"yyyy-mm")&" ("&COUNT(NFP!$B$5:$B$1055)&")" -> 1939–2026-07 (1051) | G10: =MAX(NFP!$A$5:$A$1055) -> 46204 | H10: =NFP!$B$1055 -> 158858 | I10: MoM chg | J10: =NFP!$G$6 -> -0.20873632 | K10: =NFP!$G$7 -> 0.193 | L10: =NFP!$G$9 -> NEUTRAL vs history
B11: 6 | C11: Unemployment report | D11: 1.15 | E11: UNEMP | F11: =TEXT(MIN(UNEMP!$A$5:$A$946),"yyyy")&"–"&TEXT(MAX(UNEMP!$A$5:$A$946),"yyyy-mm")&" ("&COUNT(UNEMP!$B$5:$B$946)&")" -> 1948–2026-07 (942) | G11: =MAX(UNEMP!$A$5:$A$946) -> 46204 | H11: =UNEMP!$B$946 -> 4.1 | I11: level | J11: =UNEMP!$G$6 -> -0.91327507 | K11: =UNEMP!$G$7 -> 0.183 | L11: =UNEMP!$G$9 -> NEUTRAL vs history (inverted: high = weakness)
B12: 7 | C12: Capacity utilization | D12: 1 | E12: CAPU | F12: =TEXT(MIN(CAPU!$A$5:$A$718),"yyyy")&"–"&TEXT(MAX(CAPU!$A$5:$A$718),"yyyy-mm")&" ("&COUNT(CAPU!$B$5:$B$718)&")" -> 1967–2026-06 (714) | G12: =MAX(CAPU!$A$5:$A$718) -> 46174 | H12: =CAPU!$B$718 -> 76.1 | I12: level | J12: =CAPU!$G$6 -> -0.88093047 | K12: =CAPU!$G$7 -> 0.179 | L12: =CAPU!$G$9 -> NEUTRAL vs history
B13: 8 | C13: ISM PMI | D13: 0.99 | E13: ISM | F13: =TEXT(MIN(ISM!$A$5:$A$947),"yyyy")&"–"&TEXT(MAX(ISM!$A$5:$A$947),"yyyy-mm")&" ("&COUNT(ISM!$B$5:$B$947)&")" -> 1948–2026-07 (943) | G13: =MAX(ISM!$A$5:$A$947) -> 46204 | H13: =ISM!$B$947 -> 55.6 | I13: level | J13: =ISM!$G$6 -> 0.38886833 | K13: =ISM!$G$7 -> 0.658 | L13: =ISM!$G$9 -> NEUTRAL vs history
B14: 9 | C14: UM consumer confidence final | D14: 0.87 | E14: UMCSI | F14: =TEXT(MIN(UMCSI!$A$5:$A$679),"yyyy")&"–"&TEXT(MAX(UMCSI!$A$5:$A$679),"yyyy-mm")&" ("&COUNT(UMCSI!$B$5:$B$679)&")" -> 1952–2026-07 (675) | G14: =MAX(UMCSI!$A$5:$A$679) -> 46204 | H14: =UMCSI!$B$679 -> 55.2 | I14: level | J14: =UMCSI!$G$6 -> -2.131849 | K14: =UMCSI!$G$7 -> 0.02 | L14: =UMCSI!$G$9 -> WEAK vs history
B15: 10 | C15: Retail sales less automobiles | D15: 0.69 | E15: RETX | F15: =TEXT(MIN(RETX!$A$5:$A$418),"yyyy")&"–"&TEXT(MAX(RETX!$A$5:$A$418),"yyyy-mm")&" ("&COUNT(RETX!$B$5:$B$418)&")" -> 1992–2026-06 (414) | G15: =MAX(RETX!$A$5:$A$418) -> 46174 | H15: =RETX!$B$418 -> 625024 | I15: YoY % | J15: =RETX!$G$6 -> 0.42287306 | K15: =RETX!$G$7 -> 0.775 | L15: =RETX!$G$9 -> NEUTRAL vs history
B17: HONEST NOTES
B18: • Rank 4: Chicago PMI is proprietary (MNI Indicators) — the sheet shows the Chicago Fed National Activity Index (CFNAI) as a free substitute; a DIFFERENT indicator, disclosed.
B19: • Ranks 3 & 9: the UMich preliminary vintage is not freely archived — both rows point to the final sentiment series; July 2026 final is from the University of Michigan release pending FRED's one-month delay.
B20: • Rank 8: ISM PMI left FRED (proprietary) — data from the local full-history ISM file (1948→), maintained from ISM releases.
B21: • Claims & unemployment are INVERTED for the economy read (high = weakness). NFP z-scored on the monthly change; retail ex-autos on YoY %.
B22: • All other series from FRED. Intrinsic-value column is the published ranking's metric, not recomputed here.
B23: • Each sheet: full history, change transform, 12-bin histogram + probabilities, descriptive stats (kurtosis/skew), ±1/2/3σ bands, actual-vs-normal, Z-analysis, 3 charts.

Sheet PHILLY
A1: Philadelphia Fed index (current activity, SA) · PHILLY · FRED GACDFSA066MSFRBPHI
A2: Source: https://fred.stlouisfed.org/series/GACDFSA066MSFRBPHI · refreshed 2026-08-10 · monthly | F2: Z-ANALYSIS — latest level vs full history | Q2: PHILLY Stats — Chg MoM (pts) | U2: Std Dev bands
F3: Latest | G3: =B$703 -> 41.4 | Q3: Mean | R3: =AVERAGE($C$6:$C$703) -> 0.013180516 | U3: k | V3: 1 | W3: 2 | X3: 3
A4: Date | B4: Value | C4: Chg MoM (pts) | F4: Hist mean | G4: =AVERAGE($B$5:$B$703) -> 8.8344778 | Q4: Standard Error | R4: =_xlfn.STDEV.S($C$6:$C$703)/SQRT(COUNT($C$6:$C$703)) -> 0.4216049 | U4: Upper | V4: =$R$3+V$3*$R$7 -> 11.151851 | W4: =$R$3+W$3*$R$7 -> 22.290522 | X4: =$R$3+X$3*$R$7 -> 33.429192
A5: 24959 | B5: 32.2 | F5: Hist std dev | G5: =_xlfn.STDEV.S($B$5:$B$703) -> 18.661422 | Q5: Median | R5: =MEDIAN($C$6:$C$703) -> -0.1 | U5: Lower | V5: =$R$3-V$3*$R$7 -> -11.12549 | W5: =$R$3-W$3*$R$7 -> -22.264161 | X5: =$R$3-X$3*$R$7 -> -33.402831
A6: 24990 | B6: 18.4 | C6: -13.8 | F6: Z-score | G6: =(G3-G4)/G5 -> 1.7450718 | Q6: Mode | R6: =_xlfn.MODE.SNGL($C$6:$C$703) -> -1.5
A7: 25020 | B7: 33.3 | C7: 14.9 | F7: Percentile | G7: =_xlfn.PERCENTRANK.INC($B$5:$B$703,G3) -> 0.975 | Q7: Standard Deviation | R7: =_xlfn.STDEV.S($C$6:$C$703) -> 11.138671 | U7: Actual vs Normal distribution
A8: 25051 | B8: -3.9 | C8: -37.2 | F8: Read | G8: =IF(G6>=2,"EXTREME HIGH",IF(G6>=1,"HIGH (+1 to +2σ)",IF(G6<=-2,"EXTREME LOW",IF(G6<=-1,"LOW (-1 to -2σ)","NORMAL (±1σ)")))) -> HIGH (+1 to +2σ) | Q8: Sample Variance | R8: =_xlfn.VAR.S($C$6:$C$703) -> 124.06998 | U8: ±kσ | V8: Actual % | W8: Normal % | X8: Verdict
A9: 25082 | B9: 9.5 | C9: 13.4 | F9: Economy read | G9: =IF(G6>=1,"STRONG vs history",IF(G6<=-1,"WEAK vs history","NEUTRAL vs history")) -> STRONG vs history | Q9: Kurtosis | R9: =KURT($C$6:$C$703) -> 3.7652746 | S9: =IF(R9>0,"More peaked than normal — fat tails (excess kurtosis > 0)",IF(R9<0,"Flatter than normal — thin tails (excess kurtosis < 0)","Approximately normal kurtosis")) -> More peaked than normal — fat tails (excess kurtosis > 0) | U9: 1 | V9: =COUNTIFS($C$6:$C$703,">="&($R$3-$R$7*$U9),$C$6:$C$703,"<="&($R$3+$R$7*$U9))/$R$15 -> 0.75358166 | W9: 0.682 | X9: =IF(V9>W9+0.02,"fat tails",IF(V9<W9-0.02,"thin tails","≈ normal")) -> fat tails
A10: 25112 | B10: 6.8 | C10: -2.7 | Q10: Skewness | R10: =SKEW($C$6:$C$703) -> 0.066312362 | S10: =IF(R10>0,"Positive skew — bigger fat tail on the upside",IF(R10<0,"Negative skew — bigger fat tail on the downside","Approximately symmetric")) -> Positive skew — bigger fat tail on the upside | U10: 2 | V10: =COUNTIFS($C$6:$C$703,">="&($R$3-$R$7*$U10),$C$6:$C$703,"<="&($R$3+$R$7*$U10))/$R$15 -> 0.9469914 | W10: 0.954 | X10: =IF(V10>W10+0.02,"fat tails",IF(V10<W10-0.02,"thin tails","≈ normal")) -> ≈ normal
A11: 25143 | B11: 13.2 | C11: 6.4 | H11: Histogram — Chg MoM (pts) | Q11: Range | R11: =MAX($C$6:$C$703)-MIN($C$6:$C$703) -> 127 | U11: 3 | V11: =COUNTIFS($C$6:$C$703,">="&($R$3-$R$7*$U11),$C$6:$C$703,"<="&($R$3+$R$7*$U11))/$R$15 -> 0.98710602 | W11: 0.997 | X11: =IF(V11>W11+0.02,"fat tails",IF(V11<W11-0.02,"thin tails","≈ normal")) -> ≈ normal
A12: 25173 | B12: 23.5 | C12: 10.3 | H12: Bin | I12: Frequency | J12: Range | K12: Probability | L12: Cumulative | Q12: Minimum | R12: =MIN($C$6:$C$703) -> -55.8
A13: 25204 | B13: -11.3 | C13: -34.8 | H13: =$R$12+($R$11/12)*(ROW()-12) -> -45.216667 | I13: =COUNTIFS($C$6:$C$703,">="&$R$12,$C$6:$C$703,"<="&H13) -> 1 | J13: =TEXT($R$12,"0.00")&" to "&TEXT(H13,"0.00") -> -55.80 to -45.22 | K13: =I13/$R$15 -> 0.0014326648 | L13: =SUM($K$13:K13) -> 0.0014326648 | Q13: Maximum | R13: =MAX($C$6:$C$703) -> 71.2
A14: 25235 | B14: 16.8 | C14: 28.1 | H14: =$R$12+($R$11/12)*(ROW()-12) -> -34.633333 | I14: =COUNTIFS($C$6:$C$703,">"&H13,$C$6:$C$703,"<="&H14) -> 4 | J14: =TEXT(H13,"0.00")&" to "&TEXT(H14,"0.00") -> -45.22 to -34.63 | K14: =I14/$R$15 -> 0.005730659 | L14: =SUM($K$13:K14) -> 0.0071633238 | Q14: Sum | R14: =SUM($C$6:$C$703) -> 9.2
A15: 25263 | B15: 27.8 | C15: 11 | H15: =$R$12+($R$11/12)*(ROW()-12) -> -24.05 | I15: =COUNTIFS($C$6:$C$703,">"&H14,$C$6:$C$703,"<="&H15) -> 13 | J15: =TEXT(H14,"0.00")&" to "&TEXT(H15,"0.00") -> -34.63 to -24.05 | K15: =I15/$R$15 -> 0.018624642 | L15: =SUM($K$13:K15) -> 0.025787966 | Q15: Count | R15: =COUNT($C$6:$C$703) -> 698 | S15: observations of Chg MoM (pts)
A16: 25294 | B16: 18.1 | C16: -9.7 | H16: =$R$12+($R$11/12)*(ROW()-12) -> -13.466667 | I16: =COUNTIFS($C$6:$C$703,">"&H15,$C$6:$C$703,"<="&H16) -> 40 | J16: =TEXT(H15,"0.00")&" to "&TEXT(H16,"0.00") -> -24.05 to -13.47 | K16: =I16/$R$15 -> 0.05730659 | L16: =SUM($K$13:K16) -> 0.083094556
A17: 25324 | B17: 12.7 | C17: -5.4 | H17: =$R$12+($R$11/12)*(ROW()-12) -> -2.8833333 | I17: =COUNTIFS($C$6:$C$703,">"&H16,$C$6:$C$703,"<="&H17) -> 207 | J17: =TEXT(H16,"0.00")&" to "&TEXT(H17,"0.00") -> -13.47 to -2.88 | K17: =I17/$R$15 -> 0.2965616 | L17: =SUM($K$13:K17) -> 0.37965616
A18: 25355 | B18: 18.5 | C18: 5.8 | H18: =$R$12+($R$11/12)*(ROW()-12) -> 7.7 | I18: =COUNTIFS($C$6:$C$703,">"&H17,$C$6:$C$703,"<="&H18) -> 281 | J18: =TEXT(H17,"0.00")&" to "&TEXT(H18,"0.00") -> -2.88 to 7.70 | K18: =I18/$R$15 -> 0.4025788 | L18: =SUM($K$13:K18) -> 0.78223496
A19: 25385 | B19: -1.1 | C19: -19.6 | H19: =$R$12+($R$11/12)*(ROW()-12) -> 18.283333 | I19: =COUNTIFS($C$6:$C$703,">"&H18,$C$6:$C$703,"<="&H19) -> 123 | J19: =TEXT(H18,"0.00")&" to "&TEXT(H19,"0.00") -> 7.70 to 18.28 | K19: =I19/$R$15 -> 0.17621777 | L19: =SUM($K$13:K19) -> 0.95845272
A20: 25416 | B20: 8 | C20: 9.1 | H20: =$R$12+($R$11/12)*(ROW()-12) -> 28.866667 | I20: =COUNTIFS($C$6:$C$703,">"&H19,$C$6:$C$703,"<="&H20) -> 24 | J20: =TEXT(H19,"0.00")&" to "&TEXT(H20,"0.00") -> 18.28 to 28.87 | K20: =I20/$R$15 -> 0.034383954 | L20: =SUM($K$13:K20) -> 0.99283668
A21: 25447 | B21: -1.6 | C21: -9.6 | H21: =$R$12+($R$11/12)*(ROW()-12) -> 39.45 | I21: =COUNTIFS($C$6:$C$703,">"&H20,$C$6:$C$703,"<="&H21) -> 3 | J21: =TEXT(H20,"0.00")&" to "&TEXT(H21,"0.00") -> 28.87 to 39.45 | K21: =I21/$R$15 -> 0.0042979943 | L21: =SUM($K$13:K21) -> 0.99713467
A22: 25477 | B22: 12.1 | C22: 13.7 | H22: =$R$12+($R$11/12)*(ROW()-12) -> 50.033333 | I22: =COUNTIFS($C$6:$C$703,">"&H21,$C$6:$C$703,"<="&H22) -> 1 | J22: =TEXT(H21,"0.00")&" to "&TEXT(H22,"0.00") -> 39.45 to 50.03 | K22: =I22/$R$15 -> 0.0014326648 | L22: =SUM($K$13:K22) -> 0.99856734
A23: 25508 | B23: -3.4 | C23: -15.5 | H23: =$R$12+($R$11/12)*(ROW()-12) -> 60.616667 | I23: =COUNTIFS($C$6:$C$703,">"&H22,$C$6:$C$703,"<="&H23) -> 0 | J23: =TEXT(H22,"0.00")&" to "&TEXT(H23,"0.00") -> 50.03 to 60.62 | K23: =I23/$R$15 -> 0 | L23: =SUM($K$13:K23) -> 0.99856734
A24: 25538 | B24: -7.9 | C24: -4.5 | H24: =$R$12+($R$11/12)*(ROW()-12) -> 71.2 | I24: =COUNTIFS($C$6:$C$703,">"&H23,$C$6:$C$703,"<="&H24) -> 1 | J24: =TEXT(H23,"0.00")&" to "&TEXT(H24,"0.00") -> 60.62 to 71.20 | K24: =I24/$R$15 -> 0.0014326648 | L24: =SUM($K$13:K24) -> 1
A25: 25569 | B25: -13.1 | C25: -5.2
A26: 25600 | B26: -18.1 | C26: -5
A27: 25628 | B27: -31.2 | C27: -13.1
A28: 25659 | B28: -16.9 | C28: 14.3
A29: 25689 | B29: -21.5 | C29: -4.6
A30: 25720 | B30: -8.4 | C30: 13.1
A31: 25750 | B31: 7 | C31: 15.4
A32: 25781 | B32: 6.9 | C32: -0.1
A33: 25812 | B33: 14 | C33: 7.1
A34: 25842 | B34: 3.7 | C34: -10.3
A35: 25873 | B35: 6.4 | C35: 2.7
A36: 25903 | B36: 10.2 | C36: 3.8
... A703: 46204 | B703: 41.4 | C703: 31.1

Sheet CLAIMS
A1: Initial unemployment claims (weekly, SA) · CLAIMS · FRED ICSA
A2: Source: https://fred.stlouisfed.org/series/ICSA · refreshed 2026-08-10 · weekly | F2: Z-ANALYSIS — latest level vs full history | Q2: CLAIMS Stats — WoW % | U2: Std Dev bands
F3: Latest | G3: =B$3113 -> 199000 | Q3: Mean | R3: =AVERAGE($C$6:$C$3113) -> 0.0037324096 | U3: k | V3: 1 | W3: 2 | X3: 3
A4: Date | B4: Value | C4: WoW % | F4: Hist mean | G4: =AVERAGE($B$5:$B$3113) -> 359463.17 | Q4: Standard Error | R4: =_xlfn.STDEV.S($C$6:$C$3113)/SQRT(COUNT($C$6:$C$3113)) -> 0.0032631357 | U4: Upper | V4: =$R$3+V$3*$R$7 -> 0.1856504 | W4: =$R$3+W$3*$R$7 -> 0.36756838 | X4: =$R$3+X$3*$R$7 -> 0.54948637
A5: 24479 | B5: 208000 | F5: Hist std dev | G5: =_xlfn.STDEV.S($B$5:$B$3113) -> 238535.14 | Q5: Median | R5: =MEDIAN($C$6:$C$3113) -> -0.0023585037 | U5: Lower | V5: =$R$3-V$3*$R$7 -> -0.17818558 | W5: =$R$3-W$3*$R$7 -> -0.36010356 | X5: =$R$3-X$3*$R$7 -> -0.54202155
A6: 24486 | B6: 207000 | C6: -0.0048076923 | F6: Z-score | G6: =(G3-G4)/G5 -> -0.67270244 | Q6: Mode | R6: =_xlfn.MODE.SNGL($C$6:$C$3113) -> 0
A7: 24493 | B7: 217000 | C7: 0.048309179 | F7: Percentile | G7: =_xlfn.PERCENTRANK.INC($B$5:$B$3113,G3) -> 0.025 | Q7: Standard Deviation | R7: =_xlfn.STDEV.S($C$6:$C$3113) -> 0.18191799 | U7: Actual vs Normal distribution
A8: 24500 | B8: 204000 | C8: -0.059907834 | F8: Read | G8: =IF(G6>=2,"EXTREME HIGH",IF(G6>=1,"HIGH (+1 to +2σ)",IF(G6<=-2,"EXTREME LOW",IF(G6<=-1,"LOW (-1 to -2σ)","NORMAL (±1σ)")))) -> NORMAL (±1σ) | Q8: Sample Variance | R8: =_xlfn.VAR.S($C$6:$C$3113) -> 0.033094154 | U8: ±kσ | V8: Actual % | W8: Normal % | X8: Verdict
A9: 24507 | B9: 216000 | C9: 0.058823529 | F9: Economy read | G9: =IF(G6>=1,"WEAK vs history",IF(G6<=-1,"STRONG vs history","NEUTRAL vs history (inverted: high = weakness)")) -> NEUTRAL vs history (inverted: high = weakness) | Q9: Kurtosis | R9: =KURT($C$6:$C$3113) -> 2572.2205 | S9: =IF(R9>0,"More peaked than normal — fat tails (excess kurtosis > 0)",IF(R9<0,"Flatter than normal — thin tails (excess kurtosis < 0)","Approximately normal kurtosis")) -> More peaked than normal — fat tails (excess kurtosis > 0) | U9: 1 | V9: =COUNTIFS($C$6:$C$3113,">="&($R$3-$R$7*$U9),$C$6:$C$3113,"<="&($R$3+$R$7*$U9))/$R$15 -> 0.99099099 | W9: 0.682 | X9: =IF(V9>W9+0.02,"fat tails",IF(V9<W9-0.02,"thin tails","≈ normal")) -> fat tails
A10: 24514 | B10: 229000 | C10: 0.060185185 | Q10: Skewness | R10: =SKEW($C$6:$C$3113) -> 48.45166 | S10: =IF(R10>0,"Positive skew — bigger fat tail on the upside",IF(R10<0,"Negative skew — bigger fat tail on the downside","Approximately symmetric")) -> Positive skew — bigger fat tail on the upside | U10: 2 | V10: =COUNTIFS($C$6:$C$3113,">="&($R$3-$R$7*$U10),$C$6:$C$3113,"<="&($R$3+$R$7*$U10))/$R$15 -> 0.998713 | W10: 0.954 | X10: =IF(V10>W10+0.02,"fat tails",IF(V10<W10-0.02,"thin tails","≈ normal")) -> fat tails
A11: 24521 | B11: 229000 | C11: 0 | H11: Histogram — WoW % | Q11: Range | R11: =MAX($C$6:$C$3113)-MIN($C$6:$C$3113) -> 9.9239927 | U11: 3 | V11: =COUNTIFS($C$6:$C$3113,">="&($R$3-$R$7*$U11),$C$6:$C$3113,"<="&($R$3+$R$7*$U11))/$R$15 -> 0.9993565 | W11: 0.997 | X11: =IF(V11>W11+0.02,"fat tails",IF(V11<W11-0.02,"thin tails","≈ normal")) -> ≈ normal
A12: 24528 | B12: 242000 | C12: 0.056768559 | H12: Bin | I12: Frequency | J12: Range | K12: Probability | L12: Cumulative | Q12: Minimum | R12: =MIN($C$6:$C$3113) -> -0.25
A13: 24535 | B13: 310000 | C13: 0.28099174 | H13: =$R$12+($R$11/12)*(ROW()-12) -> 0.57699939 | I13: =COUNTIFS($C$6:$C$3113,">="&$R$12,$C$6:$C$3113,"<="&H13) -> 3106 | J13: =TEXT($R$12,"0.00%")&" to "&TEXT(H13,"0.00%") -> -25.00% to 57.70% | K13: =I13/$R$15 -> 0.9993565 | L13: =SUM($K$13:K13) -> 0.9993565 | Q13: Maximum | R13: =MAX($C$6:$C$3113) -> 9.6739927
A14: 24542 | B14: 241000 | C14: -0.22258065 | H14: =$R$12+($R$11/12)*(ROW()-12) -> 1.4039988 | I14: =COUNTIFS($C$6:$C$3113,">"&H13,$C$6:$C$3113,"<="&H14) -> 1 | J14: =TEXT(H13,"0.00%")&" to "&TEXT(H14,"0.00%") -> 57.70% to 140.40% | K14: =I14/$R$15 -> 0.00032175032 | L14: =SUM($K$13:K14) -> 0.99967825 | Q14: Sum | R14: =SUM($C$6:$C$3113) -> 11.600329
A15: 24549 | B15: 245000 | C15: 0.01659751 | H15: =$R$12+($R$11/12)*(ROW()-12) -> 2.2309982 | I15: =COUNTIFS($C$6:$C$3113,">"&H14,$C$6:$C$3113,"<="&H15) -> 0 | J15: =TEXT(H14,"0.00%")&" to "&TEXT(H15,"0.00%") -> 140.40% to 223.10% | K15: =I15/$R$15 -> 0 | L15: =SUM($K$13:K15) -> 0.99967825 | Q15: Count | R15: =COUNT($C$6:$C$3113) -> 3108 | S15: observations of WoW %
A16: 24556 | B16: 247000 | C16: 0.0081632653 | H16: =$R$12+($R$11/12)*(ROW()-12) -> 3.0579976 | I16: =COUNTIFS($C$6:$C$3113,">"&H15,$C$6:$C$3113,"<="&H16) -> 0 | J16: =TEXT(H15,"0.00%")&" to "&TEXT(H16,"0.00%") -> 223.10% to 305.80% | K16: =I16/$R$15 -> 0 | L16: =SUM($K$13:K16) -> 0.99967825
A17: 24563 | B17: 259000 | C17: 0.048582996 | H17: =$R$12+($R$11/12)*(ROW()-12) -> 3.8849969 | I17: =COUNTIFS($C$6:$C$3113,">"&H16,$C$6:$C$3113,"<="&H17) -> 0 | J17: =TEXT(H16,"0.00%")&" to "&TEXT(H17,"0.00%") -> 305.80% to 388.50% | K17: =I17/$R$15 -> 0 | L17: =SUM($K$13:K17) -> 0.99967825
A18: 24570 | B18: 257000 | C18: -0.0077220077 | H18: =$R$12+($R$11/12)*(ROW()-12) -> 4.7119963 | I18: =COUNTIFS($C$6:$C$3113,">"&H17,$C$6:$C$3113,"<="&H18) -> 0 | J18: =TEXT(H17,"0.00%")&" to "&TEXT(H18,"0.00%") -> 388.50% to 471.20% | K18: =I18/$R$15 -> 0 | L18: =SUM($K$13:K18) -> 0.99967825
A19: 24577 | B19: 299000 | C19: 0.16342412 | H19: =$R$12+($R$11/12)*(ROW()-12) -> 5.5389957 | I19: =COUNTIFS($C$6:$C$3113,">"&H18,$C$6:$C$3113,"<="&H19) -> 0 | J19: =TEXT(H18,"0.00%")&" to "&TEXT(H19,"0.00%") -> 471.20% to 553.90% | K19: =I19/$R$15 -> 0 | L19: =SUM($K$13:K19) -> 0.99967825
A20: 24584 | B20: 245000 | C20: -0.18060201 | H20: =$R$12+($R$11/12)*(ROW()-12) -> 6.3659951 | I20: =COUNTIFS($C$6:$C$3113,">"&H19,$C$6:$C$3113,"<="&H20) -> 0 | J20: =TEXT(H19,"0.00%")&" to "&TEXT(H20,"0.00%") -> 553.90% to 636.60% | K20: =I20/$R$15 -> 0 | L20: =SUM($K$13:K20) -> 0.99967825
A21: 24591 | B21: 255000 | C21: 0.040816327 | H21: =$R$12+($R$11/12)*(ROW()-12) -> 7.1929945 | I21: =COUNTIFS($C$6:$C$3113,">"&H20,$C$6:$C$3113,"<="&H21) -> 0 | J21: =TEXT(H20,"0.00%")&" to "&TEXT(H21,"0.00%") -> 636.60% to 719.30% | K21: =I21/$R$15 -> 0 | L21: =SUM($K$13:K21) -> 0.99967825
A22: 24598 | B22: 254000 | C22: -0.0039215686 | H22: =$R$12+($R$11/12)*(ROW()-12) -> 8.0199939 | I22: =COUNTIFS($C$6:$C$3113,">"&H21,$C$6:$C$3113,"<="&H22) -> 0 | J22: =TEXT(H21,"0.00%")&" to "&TEXT(H22,"0.00%") -> 719.30% to 802.00% | K22: =I22/$R$15 -> 0 | L22: =SUM($K$13:K22) -> 0.99967825
A23: 24605 | B23: 231000 | C23: -0.090551181 | H23: =$R$12+($R$11/12)*(ROW()-12) -> 8.8469933 | I23: =COUNTIFS($C$6:$C$3113,">"&H22,$C$6:$C$3113,"<="&H23) -> 0 | J23: =TEXT(H22,"0.00%")&" to "&TEXT(H23,"0.00%") -> 802.00% to 884.70% | K23: =I23/$R$15 -> 0 | L23: =SUM($K$13:K23) -> 0.99967825
A24: 24612 | B24: 230000 | C24: -0.0043290043 | H24: =$R$12+($R$11/12)*(ROW()-12) -> 9.6739927 | I24: =COUNTIFS($C$6:$C$3113,">"&H23,$C$6:$C$3113,"<="&H24) -> 1 | J24: =TEXT(H23,"0.00%")&" to "&TEXT(H24,"0.00%") -> 884.70% to 967.40% | K24: =I24/$R$15 -> 0.00032175032 | L24: =SUM($K$13:K24) -> 1
A25: 24619 | B25: 228000 | C25: -0.0086956522
A26: 24626 | B26: 248000 | C26: 0.087719298
A27: 24633 | B27: 238000 | C27: -0.040322581
A28: 24640 | B28: 224000 | C28: -0.058823529
A29: 24647 | B29: 218000 | C29: -0.026785714
A30: 24654 | B30: 209000 | C30: -0.041284404
A31: 24661 | B31: 240000 | C31: 0.14832536
A32: 24668 | B32: 241000 | C32: 0.0041666667
A33: 24675 | B33: 240000 | C33: -0.0041493776
A34: 24682 | B34: 209000 | C34: -0.12916667
A35: 24689 | B35: 221000 | C35: 0.057416268
A36: 24696 | B36: 202000 | C36: -0.085972851
... A3108: 46200 | B3108: 215000 | C3108: -0.0046296296
A3109: 46207 | B3109: 217000 | C3109: =B3109/B3108-1 -> 0.0093023256
A3110: 46214 | B3110: 209000 | C3110: =B3110/B3109-1 -> -0.036866359
A3111: 46221 | B3111: 188000 | C3111: =B3111/B3110-1 -> -0.10047847
...

Sheet UMCSI
A1: UM consumer confidence (final; prelim not archived free) · UMCSI · FRED UMCSENT
A2: Source: University of Michigan Surveys of Consumers final July 2026 release / FRED UMCSENT history · refreshed 2026-08-10 · monthly | F2: Z-ANALYSIS — latest level vs full history | Q2: UMCSI Stats — Chg MoM (pts) | U2: Std Dev bands
F3: Latest | G3: =B$679 -> 55.2 | Q3: Mean | R3: =AVERAGE($C$6:$C$679) -> -0.045994065 | U3: k | V3: 1 | W3: 2 | X3: 3
A4: Date | B4: Value | C4: Chg MoM (pts) | F4: Hist mean | G4: =AVERAGE($B$5:$B$679) -> 84.416148 | Q4: Standard Error | R4: =_xlfn.STDEV.S($C$6:$C$679)/SQRT(COUNT($C$6:$C$679)) -> 0.1629988 | U4: Upper | V4: =$R$3+V$3*$R$7 -> 4.1857009 | W4: =$R$3+W$3*$R$7 -> 8.4173959 | X4: =$R$3+X$3*$R$7 -> 12.649091
A5: 19299 | B5: 86.2 | F5: Hist std dev | G5: =_xlfn.STDEV.S($B$5:$B$679) -> 13.704605 | Q5: Median | R5: =MEDIAN($C$6:$C$679) -> -0.1 | U5: Lower | V5: =$R$3-V$3*$R$7 -> -4.2776891 | W5: =$R$3-W$3*$R$7 -> -8.509384 | X5: =$R$3-X$3*$R$7 -> -12.741079
A6: 19391 | B6: 90.7 | C6: 4.5 | F6: Z-score | G6: =(G3-G4)/G5 -> -2.131849 | Q6: Mode | R6: =_xlfn.MODE.SNGL($C$6:$C$679) -> 1.3
A7: 19572 | B7: 80.8 | C7: -9.9 | F7: Percentile | G7: =_xlfn.PERCENTRANK.INC($B$5:$B$679,G3) -> 0.02 | Q7: Standard Deviation | R7: =_xlfn.STDEV.S($C$6:$C$679) -> 4.231695 | U7: Actual vs Normal distribution
A8: 19664 | B8: 80.7 | C8: -0.1 | F8: Read | G8: =IF(G6>=2,"EXTREME HIGH",IF(G6>=1,"HIGH (+1 to +2σ)",IF(G6<=-2,"EXTREME LOW",IF(G6<=-1,"LOW (-1 to -2σ)","NORMAL (±1σ)")))) -> EXTREME LOW | Q8: Sample Variance | R8: =_xlfn.VAR.S($C$6:$C$679) -> 17.907242 | U8: ±kσ | V8: Actual % | W8: Normal % | X8: Verdict
A9: 19756 | B9: 82 | C9: 1.3 | F9: Economy read | G9: =IF(G6>=1,"STRONG vs history",IF(G6<=-1,"WEAK vs history","NEUTRAL vs history")) -> WEAK vs history | Q9: Kurtosis | R9: =KURT($C$6:$C$679) -> 1.0402968 | S9: =IF(R9>0,"More peaked than normal — fat tails (excess kurtosis > 0)",IF(R9<0,"Flatter than normal — thin tails (excess kurtosis < 0)","Approximately normal kurtosis")) -> More peaked than normal — fat tails (excess kurtosis > 0) | U9: 1 | V9: =COUNTIFS($C$6:$C$679,">="&($R$3-$R$7*$U9),$C$6:$C$679,"<="&($R$3+$R$7*$U9))/$R$15 -> 0.70623145 | W9: 0.682 | X9: =IF(V9>W9+0.02,"fat tails",IF(V9<W9-0.02,"thin tails","≈ normal")) -> fat tails
A10: 19845 | B10: 82.9 | C10: 0.9 | Q10: Skewness | R10: =SKEW($C$6:$C$679) -> -0.10781329 | S10: =IF(R10>0,"Positive skew — bigger fat tail on the upside",IF(R10<0,"Negative skew — bigger fat tail on the downside","Approximately symmetric")) -> Negative skew — bigger fat tail on the downside | U10: 2 | V10: =COUNTIFS($C$6:$C$679,">="&($R$3-$R$7*$U10),$C$6:$C$679,"<="&($R$3+$R$7*$U10))/$R$15 -> 0.9495549 | W10: 0.954 | X10: =IF(V10>W10+0.02,"fat tails",IF(V10<W10-0.02,"thin tails","≈ normal")) -> ≈ normal
A11: 20029 | B11: 87 | C11: 4.1 | H11: Histogram — Chg MoM (pts) | Q11: Range | R11: =MAX($C$6:$C$679)-MIN($C$6:$C$679) -> 34.6 | U11: 3 | V11: =COUNTIFS($C$6:$C$679,">="&($R$3-$R$7*$U11),$C$6:$C$679,"<="&($R$3+$R$7*$U11))/$R$15 -> 0.99406528 | W11: 0.997 | X11: =IF(V11>W11+0.02,"fat tails",IF(V11<W11-0.02,"thin tails","≈ normal")) -> ≈ normal
A12: 20121 | B12: 95.9 | C12: 8.9 | H12: Bin | I12: Frequency | J12: Range | K12: Probability | L12: Cumulative | Q12: Minimum | R12: =MIN($C$6:$C$679) -> -17.3
A13: 20210 | B13: 99.1 | C13: 3.2 | H13: =$R$12+($R$11/12)*(ROW()-12) -> -14.416667 | I13: =COUNTIFS($C$6:$C$679,">="&$R$12,$C$6:$C$679,"<="&H13) -> 2 | J13: =TEXT($R$12,"0.00")&" to "&TEXT(H13,"0.00") -> -17.30 to -14.42 | K13: =I13/$R$15 -> 0.0029673591 | L13: =SUM($K$13:K13) -> 0.0029673591 | Q13: Maximum | R13: =MAX($C$6:$C$679) -> 17.3
A14: 20394 | B14: 99.7 | C14: 0.6 | H14: =$R$12+($R$11/12)*(ROW()-12) -> -11.533333 | I14: =COUNTIFS($C$6:$C$679,">"&H13,$C$6:$C$679,"<="&H14) -> 5 | J14: =TEXT(H13,"0.00")&" to "&TEXT(H14,"0.00") -> -14.42 to -11.53 | K14: =I14/$R$15 -> 0.0074183976 | L14: =SUM($K$13:K14) -> 0.010385757 | Q14: Sum | R14: =SUM($C$6:$C$679) -> -31
A15: 20576 | B15: 98.2 | C15: -1.5 | H15: =$R$12+($R$11/12)*(ROW()-12) -> -8.65 | I15: =COUNTIFS($C$6:$C$679,">"&H14,$C$6:$C$679,"<="&H15) -> 13 | J15: =TEXT(H14,"0.00")&" to "&TEXT(H15,"0.00") -> -11.53 to -8.65 | K15: =I15/$R$15 -> 0.019287834 | L15: =SUM($K$13:K15) -> 0.029673591 | Q15: Count | R15: =COUNT($C$6:$C$679) -> 674 | S15: observations of Chg MoM (pts)
A16: 20668 | B16: 99.9 | C16: 1.7 | H16: =$R$12+($R$11/12)*(ROW()-12) -> -5.7666667 | I16: =COUNTIFS($C$6:$C$679,">"&H15,$C$6:$C$679,"<="&H16) -> 28 | J16: =TEXT(H15,"0.00")&" to "&TEXT(H16,"0.00") -> -8.65 to -5.77 | K16: =I16/$R$15 -> 0.041543027 | L16: =SUM($K$13:K16) -> 0.071216617
A17: 20760 | B17: 100.2 | C17: 0.3 | H17: =$R$12+($R$11/12)*(ROW()-12) -> -2.8833333 | I17: =COUNTIFS($C$6:$C$679,">"&H16,$C$6:$C$679,"<="&H17) -> 101 | J17: =TEXT(H16,"0.00")&" to "&TEXT(H17,"0.00") -> -5.77 to -2.88 | K17: =I17/$R$15 -> 0.14985163 | L17: =SUM($K$13:K17) -> 0.22106825
A18: 20941 | B18: 92.9 | C18: -7.3 | H18: =$R$12+($R$11/12)*(ROW()-12) -> 0 | I18: =COUNTIFS($C$6:$C$679,">"&H17,$C$6:$C$679,"<="&H18) -> 199 | J18: =TEXT(H17,"0.00")&" to "&TEXT(H18,"0.00") -> -2.88 to 0.00 | K18: =I18/$R$15 -> 0.29525223 | L18: =SUM($K$13:K18) -> 0.51632047
A19: 21125 | B19: 83.7 | C19: -9.2 | H19: =$R$12+($R$11/12)*(ROW()-12) -> 2.8833333 | I19: =COUNTIFS($C$6:$C$679,">"&H18,$C$6:$C$679,"<="&H19) -> 170 | J19: =TEXT(H18,"0.00")&" to "&TEXT(H19,"0.00") -> 0.00 to 2.88 | K19: =I19/$R$15 -> 0.25222552 | L19: =SUM($K$13:K19) -> 0.76854599
A20: 21217 | B20: 78.5 | C20: -5.2 | H20: =$R$12+($R$11/12)*(ROW()-12) -> 5.7666667 | I20: =COUNTIFS($C$6:$C$679,">"&H19,$C$6:$C$679,"<="&H20) -> 101 | J20: =TEXT(H19,"0.00")&" to "&TEXT(H20,"0.00") -> 2.88 to 5.77 | K20: =I20/$R$15 -> 0.14985163 | L20: =SUM($K$13:K20) -> 0.91839763
A21: 21306 | B21: 80.9 | C21: 2.4 | H21: =$R$12+($R$11/12)*(ROW()-12) -> 8.65 | I21: =COUNTIFS($C$6:$C$679,">"&H20,$C$6:$C$679,"<="&H21) -> 43 | J21: =TEXT(H20,"0.00")&" to "&TEXT(H21,"0.00") -> 5.77 to 8.65 | K21: =I21/$R$15 -> 0.06379822 | L21: =SUM($K$13:K21) -> 0.98219585
A22: 21490 | B22: 90.8 | C22: 9.9 | H22: =$R$12+($R$11/12)*(ROW()-12) -> 11.533333 | I22: =COUNTIFS($C$6:$C$679,">"&H21,$C$6:$C$679,"<="&H22) -> 9 | J22: =TEXT(H21,"0.00")&" to "&TEXT(H22,"0.00") -> 8.65 to 11.53 | K22: =I22/$R$15 -> 0.013353116 | L22: =SUM($K$13:K22) -> 0.99554896
A23: 21671 | B23: 95.3 | C23: 4.5 | H23: =$R$12+($R$11/12)*(ROW()-12) -> 14.416667 | I23: =COUNTIFS($C$6:$C$679,">"&H22,$C$6:$C$679,"<="&H23) -> 1 | J23: =TEXT(H22,"0.00")&" to "&TEXT(H23,"0.00") -> 11.53 to 14.42 | K23: =I23/$R$15 -> 0.0014836795 | L23: =SUM($K$13:K23) -> 0.99703264
A24: 21855 | B24: 93.8 | C24: -1.5 | H24: =$R$12+($R$11/12)*(ROW()-12) -> 17.3 | I24: =COUNTIFS($C$6:$C$679,">"&H23,$C$6:$C$679,"<="&H24) -> 2 | J24: =TEXT(H23,"0.00")&" to "&TEXT(H24,"0.00") -> 14.42 to 17.30 | K24: =I24/$R$15 -> 0.0029673591 | L24: =SUM($K$13:K24) -> 1
A25: 21947 | B25: 100 | C25: 6.2
A26: 22037 | B26: 93.3 | C26: -6.7
A27: 22129 | B27: 97.2 | C27: 3.9
A28: 22221 | B28: 90.1 | C28: -7.1
A29: 22313 | B29: 91.6 | C29: 1.5
A30: 22402 | B30: 92.5 | C30: 0.9
A31: 22494 | B31: 99.2 | C31: 6.7
A32: 22586 | B32: 93 | C32: -6.2
A33: 22678 | B33: 99.9 | C33: 6.9
A34: 22767 | B34: 95.4 | C34: -4.5
A35: 22859 | B35: 91.6 | C35: -3.8
A36: 22951 | B36: 95 | C36: 3.4
... A678: 46174 | B678: 49.5 | C678: 4.7
A679: 46204 | B679: 55.2 | C679: =B679-B678 -> 5.7

Sheet CHIPMI
A1: Chicago Fed National Activity Index — FREE SUBSTITUTE for Chicago PMI (paid/MNI) · CHIPMI · FRED CFNAI
A2: Source: https://fred.stlouisfed.org/series/CFNAI · refreshed 2026-08-10 · monthly (latest available: June 2026) | F2: Z-ANALYSIS — latest level vs full history | Q2: CHIPMI Stats — Chg MoM | U2: Std Dev bands
F3: Latest | G3: =B$716 -> -0.02 | Q3: Mean | R3: =AVERAGE($C$6:$C$716) -> 0.00046413502 | U3: k | V3: 1 | W3: 2 | X3: 3
A4: Date | B4: Value | C4: Chg MoM | F4: Hist mean | G4: =AVERAGE($B$5:$B$716) -> -0.0003511236 | Q4: Standard Error | R4: =_xlfn.STDEV.S($C$6:$C$716)/SQRT(COUNT($C$6:$C$716)) -> 0.045358363 | U4: Upper | V4: =$R$3+V$3*$R$7 -> 1.209926 | W4: =$R$3+W$3*$R$7 -> 2.4193878 | X4: =$R$3+X$3*$R$7 -> 3.6288497
A5: 24532 | B5: -0.35 | F5: Hist std dev | G5: =_xlfn.STDEV.S($B$5:$B$716) -> 0.99946386 | Q5: Median | R5: =MEDIAN($C$6:$C$716) -> -0.02 | U5: Lower | V5: =$R$3-V$3*$R$7 -> -1.2089977 | W5: =$R$3-W$3*$R$7 -> -2.4184596 | X5: =$R$3-X$3*$R$7 -> -3.6279214
A6: 24563 | B6: 0 | C6: 0.35 | F6: Z-score | G6: =(G3-G4)/G5 -> -0.019659417 | Q6: Mode | R6: =_xlfn.MODE.SNGL($C$6:$C$716) -> 0.29
A7: 24593 | B7: -0.56 | C7: -0.56 | F7: Percentile | G7: =_xlfn.PERCENTRANK.INC($B$5:$B$716,G3) -> 0.426 | Q7: Standard Deviation | R7: =_xlfn.STDEV.S($C$6:$C$716) -> 1.2094618 | U7: Actual vs Normal distribution
A8: 24624 | B8: 0.04 | C8: 0.6 | F8: Read | G8: =IF(G6>=2,"EXTREME HIGH",IF(G6>=1,"HIGH (+1 to +2σ)",IF(G6<=-2,"EXTREME LOW",IF(G6<=-1,"LOW (-1 to -2σ)","NORMAL (±1σ)")))) -> NORMAL (±1σ) | Q8: Sample Variance | R8: =_xlfn.VAR.S($C$6:$C$716) -> 1.462798 | U8: ±kσ | V8: Actual % | W8: Normal % | X8: Verdict
A9: 24654 | B9: -0.32 | C9: -0.36 | F9: Economy read | G9: =IF(G6>=1,"STRONG vs history",IF(G6<=-1,"WEAK vs history","NEUTRAL vs history")) -> NEUTRAL vs history | Q9: Kurtosis | R9: =KURT($C$6:$C$716) -> 210.99047 | S9: =IF(R9>0,"More peaked than normal — fat tails (excess kurtosis > 0)",IF(R9<0,"Flatter than normal — thin tails (excess kurtosis < 0)","Approximately normal kurtosis")) -> More peaked than normal — fat tails (excess kurtosis > 0) | U9: 1 | V9: =COUNTIFS($C$6:$C$716,">="&($R$3-$R$7*$U9),$C$6:$C$716,"<="&($R$3+$R$7*$U9))/$R$15 -> 0.93530239 | W9: 0.682 | X9: =IF(V9>W9+0.02,"fat tails",IF(V9<W9-0.02,"thin tails","≈ normal")) -> fat tails
A10: 24685 | B10: 1.04 | C10: 1.36 | Q10: Skewness | R10: =SKEW($C$6:$C$716) -> 7.6246866 | S10: =IF(R10>0,"Positive skew — bigger fat tail on the upside",IF(R10<0,"Negative skew — bigger fat tail on the downside","Approximately symmetric")) -> Positive skew — bigger fat tail on the upside | U10: 2 | V10: =COUNTIFS($C$6:$C$716,">="&($R$3-$R$7*$U10),$C$6:$C$716,"<="&($R$3+$R$7*$U10))/$R$15 -> 0.98452883 | W10: 0.954 | X10: =IF(V10>W10+0.02,"fat tails",IF(V10<W10-0.02,"thin tails","≈ normal")) -> fat tails
A11: 24716 | B11: -0.05 | C11: -1.09 | H11: Histogram — Chg MoM | Q11: Range | R11: =MAX($C$6:$C$716)-MIN($C$6:$C$716) -> 37 | U11: 3 | V11: =COUNTIFS($C$6:$C$716,">="&($R$3-$R$7*$U11),$C$6:$C$716,"<="&($R$3+$R$7*$U11))/$R$15 -> 0.99296765 | W11: 0.997 | X11: =IF(V11>W11+0.02,"fat tails",IF(V11<W11-0.02,"thin tails","≈ normal")) -> ≈ normal
A12: 24746 | B12: 0.03 | C12: 0.08 | H12: Bin | I12: Frequency | J12: Range | K12: Probability | L12: Cumulative | Q12: Minimum | R12: =MIN($C$6:$C$716) -> -13.93
A13: 24777 | B13: 1.36 | C13: 1.33 | H13: =$R$12+($R$11/12)*(ROW()-12) -> -10.846667 | I13: =COUNTIFS($C$6:$C$716,">="&$R$12,$C$6:$C$716,"<="&H13) -> 1 | J13: =TEXT($R$12,"0.00")&" to "&TEXT(H13,"0.00") -> -13.93 to -10.85 | K13: =I13/$R$15 -> 0.0014064698 | L13: =SUM($K$13:K13) -> 0.0014064698 | Q13: Maximum | R13: =MAX($C$6:$C$716) -> 23.07
A14: 24807 | B14: 1.01 | C14: -0.35 | H14: =$R$12+($R$11/12)*(ROW()-12) -> -7.7633333 | I14: =COUNTIFS($C$6:$C$716,">"&H13,$C$6:$C$716,"<="&H14) -> 0 | J14: =TEXT(H13,"0.00")&" to "&TEXT(H14,"0.00") -> -10.85 to -7.76 | K14: =I14/$R$15 -> 0 | L14: =SUM($K$13:K14) -> 0.0014064698 | Q14: Sum | R14: =SUM($C$6:$C$716) -> 0.33
A15: 24838 | B15: -0.46 | C15: -1.47 | H15: =$R$12+($R$11/12)*(ROW()-12) -> -4.68 | I15: =COUNTIFS($C$6:$C$716,">"&H14,$C$6:$C$716,"<="&H15) -> 0 | J15: =TEXT(H14,"0.00")&" to "&TEXT(H15,"0.00") -> -7.76 to -4.68 | K15: =I15/$R$15 -> 0 | L15: =SUM($K$13:K15) -> 0.0014064698 | Q15: Count | R15: =COUNT($C$6:$C$716) -> 711 | S15: observations of Chg MoM
A16: 24869 | B16: 0.43 | C16: 0.89 | H16: =$R$12+($R$11/12)*(ROW()-12) -> -1.5966667 | I16: =COUNTIFS($C$6:$C$716,">"&H15,$C$6:$C$716,"<="&H16) -> 8 | J16: =TEXT(H15,"0.00")&" to "&TEXT(H16,"0.00") -> -4.68 to -1.60 | K16: =I16/$R$15 -> 0.011251758 | L16: =SUM($K$13:K16) -> 0.012658228
A17: 24898 | B17: 0.39 | C17: -0.04 | H17: =$R$12+($R$11/12)*(ROW()-12) -> 1.4866667 | I17: =COUNTIFS($C$6:$C$716,">"&H16,$C$6:$C$716,"<="&H17) -> 686 | J17: =TEXT(H16,"0.00")&" to "&TEXT(H17,"0.00") -> -1.60 to 1.49 | K17: =I17/$R$15 -> 0.96483826 | L17: =SUM($K$13:K17) -> 0.97749648
A18: 24929 | B18: 0.13 | C18: -0.26 | H18: =$R$12+($R$11/12)*(ROW()-12) -> 4.57 | I18: =COUNTIFS($C$6:$C$716,">"&H17,$C$6:$C$716,"<="&H18) -> 15 | J18: =TEXT(H17,"0.00")&" to "&TEXT(H18,"0.00") -> 1.49 to 4.57 | K18: =I18/$R$15 -> 0.021097046 | L18: =SUM($K$13:K18) -> 0.99859353
A19: 24959 | B19: 0.67 | C19: 0.54 | H19: =$R$12+($R$11/12)*(ROW()-12) -> 7.6533333 | I19: =COUNTIFS($C$6:$C$716,">"&H18,$C$6:$C$716,"<="&H19) -> 0 | J19: =TEXT(H18,"0.00")&" to "&TEXT(H19,"0.00") -> 4.57 to 7.65 | K19: =I19/$R$15 -> 0 | L19: =SUM($K$13:K19) -> 0.99859353
A20: 24990 | B20: 0.27 | C20: -0.4 | H20: =$R$12+($R$11/12)*(ROW()-12) -> 10.736667 | I20: =COUNTIFS($C$6:$C$716,">"&H19,$C$6:$C$716,"<="&H20) -> 0 | J20: =TEXT(H19,"0.00")&" to "&TEXT(H20,"0.00") -> 7.65 to 10.74 | K20: =I20/$R$15 -> 0 | L20: =SUM($K$13:K20) -> 0.99859353
A21: 25020 | B21: 0.23 | C21: -0.04 | H21: =$R$12+($R$11/12)*(ROW()-12) -> 13.82 | I21: =COUNTIFS($C$6:$C$716,">"&H20,$C$6:$C$716,"<="&H21) -> 0 | J21: =TEXT(H20,"0.00")&" to "&TEXT(H21,"0.00") -> 10.74 to 13.82 | K21: =I21/$R$15 -> 0 | L21: =SUM($K$13:K21) -> 0.99859353
A22: 25051 | B22: 0.02 | C22: -0.21 | H22: =$R$12+($R$11/12)*(ROW()-12) -> 16.903333 | I22: =COUNTIFS($C$6:$C$716,">"&H21,$C$6:$C$716,"<="&H22) -> 0 | J22: =TEXT(H21,"0.00")&" to "&TEXT(H22,"0.00") -> 13.82 to 16.90 | K22: =I22/$R$15 -> 0 | L22: =SUM($K$13:K22) -> 0.99859353
A23: 25082 | B23: 0.49 | C23: 0.47 | H23: =$R$12+($R$11/12)*(ROW()-12) -> 19.986667 | I23: =COUNTIFS($C$6:$C$716,">"&H22,$C$6:$C$716,"<="&H23) -> 0 | J23: =TEXT(H22,"0.00")&" to "&TEXT(H23,"0.00") -> 16.90 to 19.99 | K23: =I23/$R$15 -> 0 | L23: =SUM($K$13:K23) -> 0.99859353
A24: 25112 | B24: 0.56 | C24: 0.07 | H24: =$R$12+($R$11/12)*(ROW()-12) -> 23.07 | I24: =COUNTIFS($C$6:$C$716,">"&H23,$C$6:$C$716,"<="&H24) -> 1 | J24: =TEXT(H23,"0.00")&" to "&TEXT(H24,"0.00") -> 19.99 to 23.07 | K24: =I24/$R$15 -> 0.0014064698 | L24: =SUM($K$13:K24) -> 1
A25: 25143 | B25: 0.82 | C25: 0.26
A26: 25173 | B26: 0.01 | C26: -0.81
A27: 25204 | B27: 0.34 | C27: 0.33
A28: 25235 | B28: 0.51 | C28: 0.17
A29: 25263 | B29: 0.5 | C29: -0.01
A30: 25294 | B30: 0.05 | C30: -0.45
A31: 25324 | B31: -0.02 | C31: -0.07
A32: 25355 | B32: 0.38 | C32: 0.4
A33: 25385 | B33: 0.17 | C33: -0.21
A34: 25416 | B34: 0.45 | C34: 0.28
A35: 25447 | B35: -0.09 | C35: -0.54
A36: 25477 | B36: 0.2 | C36: 0.29
... A710: 45992 | B710: -0.06 | C710: 0.24
A711: 46023 | B711: -0.07 | C711: =B711-B710 -> -0.01
A712: 46054 | B712: 0.22 | C712: =B712-B711 -> 0.29
A713: 46082 | B713: -0.17 | C713: =B713-B712 -> -0.39
...

Sheet NFP
A1: Nonfarm payroll employment (thousands) · NFP · FRED PAYEMS
A2: Source: https://fred.stlouisfed.org/series/PAYEMS · refreshed 2026-08-10 · monthly | F2: Z-ANALYSIS — latest MoM change vs full history | Q2: NFP Stats — Chg MoM (k) | U2: Std Dev bands
F3: Latest | G3: =C$1055 -> -23 | Q3: Mean | R3: =AVERAGE($C$6:$C$1055) -> 122.79524 | U3: k | V3: 1 | W3: 2 | X3: 3
A4: Date | B4: Value | C4: Chg MoM (k) | F4: Hist mean | G4: =AVERAGE($C$6:$C$1055) -> 122.79524 | Q4: Standard Error | R4: =_xlfn.STDEV.S($C$6:$C$1055)/SQRT(COUNT($C$6:$C$1055)) -> 21.555131 | U4: Upper | V4: =$R$3+V$3*$R$7 -> 821.2613 | W4: =$R$3+W$3*$R$7 -> 1519.7274 | X4: =$R$3+X$3*$R$7 -> 2218.1934
A5: 14246 | B5: 29923 | F5: Hist std dev | G5: =_xlfn.STDEV.S($C$6:$C$1055) -> 698.46606 | Q5: Median | R5: =MEDIAN($C$6:$C$1055) -> 158.5 | U5: Lower | V5: =$R$3-V$3*$R$7 -> -575.67082 | W5: =$R$3-W$3*$R$7 -> -1274.1369 | X5: =$R$3-X$3*$R$7 -> -1972.6029
A6: 14277 | B6: 30100 | C6: 177 | F6: Z-score | G6: =(G3-G4)/G5 -> -0.20873632 | Q6: Mode | R6: =_xlfn.MODE.SNGL($C$6:$C$1055) -> 273
A7: 14305 | B7: 30280 | C7: 180 | F7: Percentile | G7: =_xlfn.PERCENTRANK.INC($C$6:$C$1055,G3) -> 0.193 | Q7: Standard Deviation | R7: =_xlfn.STDEV.S($C$6:$C$1055) -> 698.46606 | U7: Actual vs Normal distribution
A8: 14336 | B8: 30094 | C8: -186 | F8: Read | G8: =IF(G6>=2,"EXTREME HIGH",IF(G6>=1,"HIGH (+1 to +2σ)",IF(G6<=-2,"EXTREME LOW",IF(G6<=-1,"LOW (-1 to -2σ)","NORMAL (±1σ)")))) -> NORMAL (±1σ) | Q8: Sample Variance | R8: =_xlfn.VAR.S($C$6:$C$1055) -> 487854.84 | U8: ±kσ | V8: Actual % | W8: Normal % | X8: Verdict
A9: 14366 | B9: 30299 | C9: 205 | F9: Economy read | G9: =IF(G6>=1,"STRONG vs history",IF(G6<=-1,"WEAK vs history","NEUTRAL vs history")) -> NEUTRAL vs history | Q9: Kurtosis | R9: =KURT($C$6:$C$1055) -> 723.27441 | S9: =IF(R9>0,"More peaked than normal — fat tails (excess kurtosis > 0)",IF(R9<0,"Flatter than normal — thin tails (excess kurtosis < 0)","Approximately normal kurtosis")) -> More peaked than normal — fat tails (excess kurtosis > 0) | U9: 1 | V9: =COUNTIFS($C$6:$C$1055,">="&($R$3-$R$7*$U9),$C$6:$C$1055,"<="&($R$3+$R$7*$U9))/$R$15 -> 0.97904762 | W9: 0.682 | X9: =IF(V9>W9+0.02,"fat tails",IF(V9<W9-0.02,"thin tails","≈ normal")) -> fat tails
A10: 14397 | B10: 30502 | C10: 203 | Q10: Skewness | R10: =SKEW($C$6:$C$1055) -> -24.199176 | S10: =IF(R10>0,"Positive skew — bigger fat tail on the upside",IF(R10<0,"Negative skew — bigger fat tail on the downside","Approximately symmetric")) -> Negative skew — bigger fat tail on the downside | U10: 2 | V10: =COUNTIFS($C$6:$C$1055,">="&($R$3-$R$7*$U10),$C$6:$C$1055,"<="&($R$3+$R$7*$U10))/$R$15 -> 0.99333333 | W10: 0.954 | X10: =IF(V10>W10+0.02,"fat tails",IF(V10<W10-0.02,"thin tails","≈ normal")) -> fat tails
A11: 14427 | B11: 30419 | C11: -83 | H11: Histogram — Chg MoM (k) | Q11: Range | R11: =MAX($C$6:$C$1055)-MIN($C$6:$C$1055) -> 25100 | U11: 3 | V11: =COUNTIFS($C$6:$C$1055,">="&($R$3-$R$7*$U11),$C$6:$C$1055,"<="&($R$3+$R$7*$U11))/$R$15 -> 0.99714286 | W11: 0.997 | X11: =IF(V11>W11+0.02,"fat tails",IF(V11<W11-0.02,"thin tails","≈ normal")) -> ≈ normal
A12: 14458 | B12: 30663 | C12: 244 | H12: Bin | I12: Frequency | J12: Range | K12: Probability | L12: Cumulative | Q12: Minimum | R12: =MIN($C$6:$C$1055) -> -20469
A13: 14489 | B13: 31031 | C13: 368 | H13: =$R$12+($R$11/12)*(ROW()-12) -> -18377.333 | I13: =COUNTIFS($C$6:$C$1055,">="&$R$12,$C$6:$C$1055,"<="&H13) -> 1 | J13: =TEXT($R$12,"0.00")&" to "&TEXT(H13,"0.00") -> -20469.00 to -18377.33 | K13: =I13/$R$15 -> 0.00095238095 | L13: =SUM($K$13:K13) -> 0.00095238095 | Q13: Maximum | R13: =MAX($C$6:$C$1055) -> 4631
A14: 14519 | B14: 31411 | C14: 380 | H14: =$R$12+($R$11/12)*(ROW()-12) -> -16285.667 | I14: =COUNTIFS($C$6:$C$1055,">"&H13,$C$6:$C$1055,"<="&H14) -> 0 | J14: =TEXT(H13,"0.00")&" to "&TEXT(H14,"0.00") -> -18377.33 to -16285.67 | K14: =I14/$R$15 -> 0 | L14: =SUM($K$13:K14) -> 0.00095238095 | Q14: Sum | R14: =SUM($C$6:$C$1055) -> 128935
A15: 14550 | B15: 31470 | C15: 59 | H15: =$R$12+($R$11/12)*(ROW()-12) -> -14194 | I15: =COUNTIFS($C$6:$C$1055,">"&H14,$C$6:$C$1055,"<="&H15) -> 0 | J15: =TEXT(H14,"0.00")&" to "&TEXT(H15,"0.00") -> -16285.67 to -14194.00 | K15: =I15/$R$15 -> 0 | L15: =SUM($K$13:K15) -> 0.00095238095 | Q15: Count | R15: =COUNT($C$6:$C$1055) -> 1050 | S15: observations of Chg MoM (k)
A16: 14580 | B16: 31542 | C16: 72 | H16: =$R$12+($R$11/12)*(ROW()-12) -> -12102.333 | I16: =COUNTIFS($C$6:$C$1055,">"&H15,$C$6:$C$1055,"<="&H16) -> 0 | J16: =TEXT(H15,"0.00")&" to "&TEXT(H16,"0.00") -> -14194.00 to -12102.33 | K16: =I16/$R$15 -> 0 | L16: =SUM($K$13:K16) -> 0.00095238095
A17: 14611 | B17: 31603 | C17: 61 | H17: =$R$12+($R$11/12)*(ROW()-12) -> -10010.667 | I17: =COUNTIFS($C$6:$C$1055,">"&H16,$C$6:$C$1055,"<="&H17) -> 0 | J17: =TEXT(H16,"0.00")&" to "&TEXT(H17,"0.00") -> -12102.33 to -10010.67 | K17: =I17/$R$15 -> 0 | L17: =SUM($K$13:K17) -> 0.00095238095
A18: 14642 | B18: 31715 | C18: 112 | H18: =$R$12+($R$11/12)*(ROW()-12) -> -7919 | I18: =COUNTIFS($C$6:$C$1055,">"&H17,$C$6:$C$1055,"<="&H18) -> 0 | J18: =TEXT(H17,"0.00")&" to "&TEXT(H18,"0.00") -> -10010.67 to -7919.00 | K18: =I18/$R$15 -> 0 | L18: =SUM($K$13:K18) -> 0.00095238095
A19: 14671 | B19: 31825 | C19: 110 | H19: =$R$12+($R$11/12)*(ROW()-12) -> -5827.3333 | I19: =COUNTIFS($C$6:$C$1055,">"&H18,$C$6:$C$1055,"<="&H19) -> 0 | J19: =TEXT(H18,"0.00")&" to "&TEXT(H19,"0.00") -> -7919.00 to -5827.33 | K19: =I19/$R$15 -> 0 | L19: =SUM($K$13:K19) -> 0.00095238095
A20: 14702 | B20: 31701 | C20: -124 | H20: =$R$12+($R$11/12)*(ROW()-12) -> -3735.6667 | I20: =COUNTIFS($C$6:$C$1055,">"&H19,$C$6:$C$1055,"<="&H20) -> 0 | J20: =TEXT(H19,"0.00")&" to "&TEXT(H20,"0.00") -> -5827.33 to -3735.67 | K20: =I20/$R$15 -> 0 | L20: =SUM($K$13:K20) -> 0.00095238095
A21: 14732 | B21: 31879 | C21: 178 | H21: =$R$12+($R$11/12)*(ROW()-12) -> -1644 | I21: =COUNTIFS($C$6:$C$1055,">"&H20,$C$6:$C$1055,"<="&H21) -> 1 | J21: =TEXT(H20,"0.00")&" to "&TEXT(H21,"0.00") -> -3735.67 to -1644.00 | K21: =I21/$R$15 -> 0.00095238095 | L21: =SUM($K$13:K21) -> 0.0019047619
A22: 14763 | B22: 31977 | C22: 98 | H22: =$R$12+($R$11/12)*(ROW()-12) -> 447.66667 | I22: =COUNTIFS($C$6:$C$1055,">"&H21,$C$6:$C$1055,"<="&H22) -> 999 | J22: =TEXT(H21,"0.00")&" to "&TEXT(H22,"0.00") -> -1644.00 to 447.67 | K22: =I22/$R$15 -> 0.95142857 | L22: =SUM($K$13:K22) -> 0.95333333
A23: 14793 | B23: 31942 | C23: -35 | H23: =$R$12+($R$11/12)*(ROW()-12) -> 2539.3333 | I23: =COUNTIFS($C$6:$C$1055,">"&H22,$C$6:$C$1055,"<="&H23) -> 47 | J23: =TEXT(H22,"0.00")&" to "&TEXT(H23,"0.00") -> 447.67 to 2539.33 | K23: =I23/$R$15 -> 0.044761905 | L23: =SUM($K$13:K23) -> 0.99809524
A24: 14824 | B24: 32352 | C24: 410 | H24: =$R$12+($R$11/12)*(ROW()-12) -> 4631 | I24: =COUNTIFS($C$6:$C$1055,">"&H23,$C$6:$C$1055,"<="&H24) -> 2 | J24: =TEXT(H23,"0.00")&" to "&TEXT(H24,"0.00") -> 2539.33 to 4631.00 | K24: =I24/$R$15 -> 0.0019047619 | L24: =SUM($K$13:K24) -> 1
A25: 14855 | B25: 32810 | C25: 458
A26: 14885 | B26: 33267 | C26: 457
A27: 14916 | B27: 33669 | C27: 402
A28: 14946 | B28: 34174 | C28: 505
A29: 14977 | B29: 34481 | C29: 307
A30: 15008 | B30: 34843 | C30: 362
A31: 15036 | B31: 35092 | C31: 249
A32: 15067 | B32: 35468 | C32: 376
A33: 15097 | B33: 36182 | C33: 714
A34: 15128 | B34: 36650 | C34: 468
A35: 15158 | B35: 37137 | C35: 487
A36: 15189 | B36: 37544 | C36: 407
... A1052: 46113 | B1052: 158798 | C1052: 148
A1053: 46143 | B1053: 158861 | C1053: =B1053-B1052 -> 63
A1054: 46174 | B1054: 158881 | C1054: =B1054-B1053 -> 20
A1055: 46204 | B1055: 158858 | C1055: =B1055-B1054 -> -23

Sheet UNEMP
A1: Unemployment rate · UNEMP · FRED UNRATE
A2: Source: https://fred.stlouisfed.org/series/UNRATE · refreshed 2026-08-10 · monthly | F2: Z-ANALYSIS — latest level vs full history | Q2: UNEMP Stats — Chg MoM (pp) | U2: Std Dev bands
F3: Latest | G3: =B$946 -> 4.1 | Q3: Mean | R3: =AVERAGE($C$6:$C$946) -> 0.00074388948 | U3: k | V3: 1 | W3: 2 | X3: 3
A4: Date | B4: Value | C4: Chg MoM (pp) | F4: Hist mean | G4: =AVERAGE($B$5:$B$946) -> 5.6561571 | Q4: Standard Error | R4: =_xlfn.STDEV.S($C$6:$C$946)/SQRT(COUNT($C$6:$C$946)) -> 0.013466548 | U4: Upper | V4: =$R$3+V$3*$R$7 -> 0.41383998 | W4: =$R$3+W$3*$R$7 -> 0.82693608 | X4: =$R$3+X$3*$R$7 -> 1.2400322
A5: 17533 | B5: 3.4 | F5: Hist std dev | G5: =_xlfn.STDEV.S($B$5:$B$946) -> 1.7039303 | Q5: Median | R5: =MEDIAN($C$6:$C$946) -> 0 | U5: Lower | V5: =$R$3-V$3*$R$7 -> -0.4123522 | W5: =$R$3-W$3*$R$7 -> -0.8254483 | X5: =$R$3-X$3*$R$7 -> -1.2385444
A6: 17564 | B6: 3.8 | C6: 0.4 | F6: Z-score | G6: =(G3-G4)/G5 -> -0.91327507 | Q6: Mode | R6: =_xlfn.MODE.SNGL($C$6:$C$946) -> 0
A7: 17593 | B7: 4 | C7: 0.2 | F7: Percentile | G7: =_xlfn.PERCENTRANK.INC($B$5:$B$946,G3) -> 0.183 | Q7: Standard Deviation | R7: =_xlfn.STDEV.S($C$6:$C$946) -> 0.41309609 | U7: Actual vs Normal distribution
A8: 17624 | B8: 3.9 | C8: -0.1 | F8: Read | G8: =IF(G6>=2,"EXTREME HIGH",IF(G6>=1,"HIGH (+1 to +2σ)",IF(G6<=-2,"EXTREME LOW",IF(G6<=-1,"LOW (-1 to -2σ)","NORMAL (±1σ)")))) -> NORMAL (±1σ) | Q8: Sample Variance | R8: =_xlfn.VAR.S($C$6:$C$946) -> 0.17064838 | U8: ±kσ | V8: Actual % | W8: Normal % | X8: Verdict
A9: 17654 | B9: 3.5 | C9: -0.4 | F9: Economy read | G9: =IF(G6>=1,"WEAK vs history",IF(G6<=-1,"STRONG vs history","NEUTRAL vs history (inverted: high = weakness)")) -> NEUTRAL vs history (inverted: high = weakness) | Q9: Kurtosis | R9: =KURT($C$6:$C$946) -> 429.06638 | S9: =IF(R9>0,"More peaked than normal — fat tails (excess kurtosis > 0)",IF(R9<0,"Flatter than normal — thin tails (excess kurtosis < 0)","Approximately normal kurtosis")) -> More peaked than normal — fat tails (excess kurtosis > 0) | U9: 1 | V9: =COUNTIFS($C$6:$C$946,">="&($R$3-$R$7*$U9),$C$6:$C$946,"<="&($R$3+$R$7*$U9))/$R$15 -> 0.95749203 | W9: 0.682 | X9: =IF(V9>W9+0.02,"fat tails",IF(V9<W9-0.02,"thin tails","≈ normal")) -> fat tails
A10: 17685 | B10: 3.6 | C10: 0.1 | Q10: Skewness | R10: =SKEW($C$6:$C$946) -> 16.719984 | S10: =IF(R10>0,"Positive skew — bigger fat tail on the upside",IF(R10<0,"Negative skew — bigger fat tail on the downside","Approximately symmetric")) -> Positive skew — bigger fat tail on the upside | U10: 2 | V10: =COUNTIFS($C$6:$C$946,">="&($R$3-$R$7*$U10),$C$6:$C$946,"<="&($R$3+$R$7*$U10))/$R$15 -> 0.98937301 | W10: 0.954 | X10: =IF(V10>W10+0.02,"fat tails",IF(V10<W10-0.02,"thin tails","≈ normal")) -> fat tails
A11: 17715 | B11: 3.6 | C11: 0 | H11: Histogram — Chg MoM (pp) | Q11: Range | R11: =MAX($C$6:$C$946)-MIN($C$6:$C$946) -> 12.6 | U11: 3 | V11: =COUNTIFS($C$6:$C$946,">="&($R$3-$R$7*$U11),$C$6:$C$946,"<="&($R$3+$R$7*$U11))/$R$15 -> 0.9936238 | W11: 0.997 | X11: =IF(V11>W11+0.02,"fat tails",IF(V11<W11-0.02,"thin tails","≈ normal")) -> ≈ normal
A12: 17746 | B12: 3.9 | C12: 0.3 | H12: Bin | I12: Frequency | J12: Range | K12: Probability | L12: Cumulative | Q12: Minimum | R12: =MIN($C$6:$C$946) -> -2.2
A13: 17777 | B13: 3.8 | C13: -0.1 | H13: =$R$12+($R$11/12)*(ROW()-12) -> -1.15 | I13: =COUNTIFS($C$6:$C$946,">="&$R$12,$C$6:$C$946,"<="&H13) -> 4 | J13: =TEXT($R$12,"0.00")&" to "&TEXT(H13,"0.00") -> -2.20 to -1.15 | K13: =I13/$R$15 -> 0.004250797 | L13: =SUM($K$13:K13) -> 0.004250797 | Q13: Maximum | R13: =MAX($C$6:$C$946) -> 10.4
A14: 17807 | B14: 3.7 | C14: -0.1 | H14: =$R$12+($R$11/12)*(ROW()-12) -> -0.1 | I14: =COUNTIFS($C$6:$C$946,">"&H13,$C$6:$C$946,"<="&H14) -> 382 | J14: =TEXT(H13,"0.00")&" to "&TEXT(H14,"0.00") -> -1.15 to -0.10 | K14: =I14/$R$15 -> 0.40595112 | L14: =SUM($K$13:K14) -> 0.41020191 | Q14: Sum | R14: =SUM($C$6:$C$946) -> 0.7
A15: 17838 | B15: 3.8 | C15: 0.1 | H15: =$R$12+($R$11/12)*(ROW()-12) -> 0.95 | I15: =COUNTIFS($C$6:$C$946,">"&H14,$C$6:$C$946,"<="&H15) -> 552 | J15: =TEXT(H14,"0.00")&" to "&TEXT(H15,"0.00") -> -0.10 to 0.95 | K15: =I15/$R$15 -> 0.58660999 | L15: =SUM($K$13:K15) -> 0.9968119 | Q15: Count | R15: =COUNT($C$6:$C$946) -> 941 | S15: observations of Chg MoM (pp)
A16: 17868 | B16: 4 | C16: 0.2 | H16: =$R$12+($R$11/12)*(ROW()-12) -> 2 | I16: =COUNTIFS($C$6:$C$946,">"&H15,$C$6:$C$946,"<="&H16) -> 2 | J16: =TEXT(H15,"0.00")&" to "&TEXT(H16,"0.00") -> 0.95 to 2.00 | K16: =I16/$R$15 -> 0.0021253985 | L16: =SUM($K$13:K16) -> 0.9989373
A17: 17899 | B17: 4.3 | C17: 0.3 | H17: =$R$12+($R$11/12)*(ROW()-12) -> 3.05 | I17: =COUNTIFS($C$6:$C$946,">"&H16,$C$6:$C$946,"<="&H17) -> 0 | J17: =TEXT(H16,"0.00")&" to "&TEXT(H17,"0.00") -> 2.00 to 3.05 | K17: =I17/$R$15 -> 0 | L17: =SUM($K$13:K17) -> 0.9989373
A18: 17930 | B18: 4.7 | C18: 0.4 | H18: =$R$12+($R$11/12)*(ROW()-12) -> 4.1 | I18: =COUNTIFS($C$6:$C$946,">"&H17,$C$6:$C$946,"<="&H18) -> 0 | J18: =TEXT(H17,"0.00")&" to "&TEXT(H18,"0.00") -> 3.05 to 4.10 | K18: =I18/$R$15 -> 0 | L18: =SUM($K$13:K18) -> 0.9989373
A19: 17958 | B19: 5 | C19: 0.3 | H19: =$R$12+($R$11/12)*(ROW()-12) -> 5.15 | I19: =COUNTIFS($C$6:$C$946,">"&H18,$C$6:$C$946,"<="&H19) -> 0 | J19: =TEXT(H18,"0.00")&" to "&TEXT(H19,"0.00") -> 4.10 to 5.15 | K19: =I19/$R$15 -> 0 | L19: =SUM($K$13:K19) -> 0.9989373
A20: 17989 | B20: 5.3 | C20: 0.3 | H20: =$R$12+($R$11/12)*(ROW()-12) -> 6.2 | I20: =COUNTIFS($C$6:$C$946,">"&H19,$C$6:$C$946,"<="&H20) -> 0 | J20: =TEXT(H19,"0.00")&" to "&TEXT(H20,"0.00") -> 5.15 to 6.20 | K20: =I20/$R$15 -> 0 | L20: =SUM($K$13:K20) -> 0.9989373
A21: 18019 | B21: 6.1 | C21: 0.8 | H21: =$R$12+($R$11/12)*(ROW()-12) -> 7.25 | I21: =COUNTIFS($C$6:$C$946,">"&H20,$C$6:$C$946,"<="&H21) -> 0 | J21: =TEXT(H20,"0.00")&" to "&TEXT(H21,"0.00") -> 6.20 to 7.25 | K21: =I21/$R$15 -> 0 | L21: =SUM($K$13:K21) -> 0.9989373
A22: 18050 | B22: 6.2 | C22: 0.1 | H22: =$R$12+($R$11/12)*(ROW()-12) -> 8.3 | I22: =COUNTIFS($C$6:$C$946,">"&H21,$C$6:$C$946,"<="&H22) -> 0 | J22: =TEXT(H21,"0.00")&" to "&TEXT(H22,"0.00") -> 7.25 to 8.30 | K22: =I22/$R$15 -> 0 | L22: =SUM($K$13:K22) -> 0.9989373
A23: 18080 | B23: 6.7 | C23: 0.5 | H23: =$R$12+($R$11/12)*(ROW()-12) -> 9.35 | I23: =COUNTIFS($C$6:$C$946,">"&H22,$C$6:$C$946,"<="&H23) -> 0 | J23: =TEXT(H22,"0.00")&" to "&TEXT(H23,"0.00") -> 8.30 to 9.35 | K23: =I23/$R$15 -> 0 | L23: =SUM($K$13:K23) -> 0.9989373
A24: 18111 | B24: 6.8 | C24: 0.1 | H24: =$R$12+($R$11/12)*(ROW()-12) -> 10.4 | I24: =COUNTIFS($C$6:$C$946,">"&H23,$C$6:$C$946,"<="&H24) -> 1 | J24: =TEXT(H23,"0.00")&" to "&TEXT(H24,"0.00") -> 9.35 to 10.40 | K24: =I24/$R$15 -> 0.0010626993 | L24: =SUM($K$13:K24) -> 1
A25: 18142 | B25: 6.6 | C25: -0.2
A26: 18172 | B26: 7.9 | C26: 1.3
A27: 18203 | B27: 6.4 | C27: -1.5
A28: 18233 | B28: 6.6 | C28: 0.2
A29: 18264 | B29: 6.5 | C29: -0.1
A30: 18295 | B30: 6.4 | C30: -0.1
A31: 18323 | B31: 6.3 | C31: -0.1
A32: 18354 | B32: 5.8 | C32: -0.5
A33: 18384 | B33: 5.5 | C33: -0.3
A34: 18415 | B34: 5.4 | C34: -0.1
A35: 18445 | B35: 5 | C35: -0.4
A36: 18476 | B36: 4.5 | C36: -0.5
... A945: 46174 | B945: 4.2 | C945: -0.1
A946: 46204 | B946: 4.1 | C946: =B946-B945 -> -0.1

Sheet CAPU
A1: Capacity utilization (total) · CAPU · FRED TCU
A2: Source: Federal Reserve G.17 release / FRED TCU history · refreshed 2026-08-10 · monthly (latest available: June 2026) | F2: Z-ANALYSIS — latest level vs full history | Q2: CAPU Stats — Chg MoM (pp) | U2: Std Dev bands
F3: Latest | G3: =B$718 -> 76.1 | Q3: Mean | R3: =AVERAGE($C$6:$C$718) -> -0.018639832 | U3: k | V3: 1 | W3: 2 | X3: 3
A4: Date | B4: Value | C4: Chg MoM (pp) | F4: Hist mean | G4: =AVERAGE($B$5:$B$718) -> 79.814991 | Q4: Standard Error | R4: =_xlfn.STDEV.S($C$6:$C$718)/SQRT(COUNT($C$6:$C$718)) -> 0.0269073 | U4: Upper | V4: =$R$3+V$3*$R$7 -> 0.69984051 | W4: =$R$3+W$3*$R$7 -> 1.4183208 | X4: =$R$3+X$3*$R$7 -> 2.1368012
A5: 24473 | B5: 89.3902 | F5: Hist std dev | G5: =_xlfn.STDEV.S($B$5:$B$718) -> 4.2171219 | Q5: Median | R5: =MEDIAN($C$6:$C$718) -> 0.0213 | U5: Lower | V5: =$R$3-V$3*$R$7 -> -0.73712017 | W5: =$R$3-W$3*$R$7 -> -1.4556005 | X5: =$R$3-X$3*$R$7 -> -2.1740809
A6: 24504 | B6: 87.975 | C6: -1.4152 | F6: Z-score | G6: =(G3-G4)/G5 -> -0.88093047 | Q6: Mode | R6: =_xlfn.MODE.SNGL($C$6:$C$718) -> 0.1524
A7: 24532 | B7: 87.0835 | C7: -0.8915 | F7: Percentile | G7: =_xlfn.PERCENTRANK.INC($B$5:$B$718,G3) -> 0.179 | Q7: Standard Deviation | R7: =_xlfn.STDEV.S($C$6:$C$718) -> 0.71848034 | U7: Actual vs Normal distribution
A8: 24563 | B8: 87.5089 | C8: 0.4254 | F8: Read | G8: =IF(G6>=2,"EXTREME HIGH",IF(G6>=1,"HIGH (+1 to +2σ)",IF(G6<=-2,"EXTREME LOW",IF(G6<=-1,"LOW (-1 to -2σ)","NORMAL (±1σ)")))) -> NORMAL (±1σ) | Q8: Sample Variance | R8: =_xlfn.VAR.S($C$6:$C$718) -> 0.516214 | U8: ±kσ | V8: Actual % | W8: Normal % | X8: Verdict
A9: 24593 | B9: 86.3566 | C9: -1.1523 | F9: Economy read | G9: =IF(G6>=1,"STRONG vs history",IF(G6<=-1,"WEAK vs history","NEUTRAL vs history")) -> NEUTRAL vs history | Q9: Kurtosis | R9: =KURT($C$6:$C$718) -> 49.648748 | S9: =IF(R9>0,"More peaked than normal — fat tails (excess kurtosis > 0)",IF(R9<0,"Flatter than normal — thin tails (excess kurtosis < 0)","Approximately normal kurtosis")) -> More peaked than normal — fat tails (excess kurtosis > 0) | U9: 1 | V9: =COUNTIFS($C$6:$C$718,">="&($R$3-$R$7*$U9),$C$6:$C$718,"<="&($R$3+$R$7*$U9))/$R$15 -> 0.85413745 | W9: 0.682 | X9: =IF(V9>W9+0.02,"fat tails",IF(V9<W9-0.02,"thin tails","≈ normal")) -> fat tails
A10: 24624 | B10: 85.9603 | C10: -0.3963 | Q10: Skewness | R10: =SKEW($C$6:$C$718) -> -3.6435309 | S10: =IF(R10>0,"Positive skew — bigger fat tail on the upside",IF(R10<0,"Negative skew — bigger fat tail on the downside","Approximately symmetric")) -> Negative skew — bigger fat tail on the downside | U10: 2 | V10: =COUNTIFS($C$6:$C$718,">="&($R$3-$R$7*$U10),$C$6:$C$718,"<="&($R$3+$R$7*$U10))/$R$15 -> 0.96774194 | W10: 0.954 | X10: =IF(V10>W10+0.02,"fat tails",IF(V10<W10-0.02,"thin tails","≈ normal")) -> ≈ normal
A11: 24654 | B11: 85.3833 | C11: -0.577 | H11: Histogram — Chg MoM (pp) | Q11: Range | R11: =MAX($C$6:$C$718)-MIN($C$6:$C$718) -> 14.0384 | U11: 3 | V11: =COUNTIFS($C$6:$C$718,">="&($R$3-$R$7*$U11),$C$6:$C$718,"<="&($R$3+$R$7*$U11))/$R$15 -> 0.98597475 | W11: 0.997 | X11: =IF(V11>W11+0.02,"fat tails",IF(V11<W11-0.02,"thin tails","≈ normal")) -> ≈ normal
A12: 24685 | B12: 86.6339 | C12: 1.2506 | H12: Bin | I12: Frequency | J12: Range | K12: Probability | L12: Cumulative | Q12: Minimum | R12: =MIN($C$6:$C$718) -> -9.704
A13: 24716 | B13: 86.1122 | C13: -0.5217 | H13: =$R$12+($R$11/12)*(ROW()-12) -> -8.5341333 | I13: =COUNTIFS($C$6:$C$718,">="&$R$12,$C$6:$C$718,"<="&H13) -> 1 | J13: =TEXT($R$12,"0.00")&" to "&TEXT(H13,"0.00") -> -9.70 to -8.53 | K13: =I13/$R$15 -> 0.0014025245 | L13: =SUM($K$13:K13) -> 0.0014025245 | Q13: Maximum | R13: =MAX($C$6:$C$718) -> 4.3344
A14: 24746 | B14: 86.4325 | C14: 0.3203 | H14: =$R$12+($R$11/12)*(ROW()-12) -> -7.3642667 | I14: =COUNTIFS($C$6:$C$718,">"&H13,$C$6:$C$718,"<="&H14) -> 0 | J14: =TEXT(H13,"0.00")&" to "&TEXT(H14,"0.00") -> -8.53 to -7.36 | K14: =I14/$R$15 -> 0 | L14: =SUM($K$13:K14) -> 0.0014025245 | Q14: Sum | R14: =SUM($C$6:$C$718) -> -13.2902
A15: 24777 | B15: 87.2856 | C15: 0.8531 | H15: =$R$12+($R$11/12)*(ROW()-12) -> -6.1944 | I15: =COUNTIFS($C$6:$C$718,">"&H14,$C$6:$C$718,"<="&H15) -> 0 | J15: =TEXT(H14,"0.00")&" to "&TEXT(H15,"0.00") -> -7.36 to -6.19 | K15: =I15/$R$15 -> 0 | L15: =SUM($K$13:K15) -> 0.0014025245 | Q15: Count | R15: =COUNT($C$6:$C$718) -> 713 | S15: observations of Chg MoM (pp)
A16: 24807 | B16: 87.8417 | C16: 0.5561 | H16: =$R$12+($R$11/12)*(ROW()-12) -> -5.0245333 | I16: =COUNTIFS($C$6:$C$718,">"&H15,$C$6:$C$718,"<="&H16) -> 0 | J16: =TEXT(H15,"0.00")&" to "&TEXT(H16,"0.00") -> -6.19 to -5.02 | K16: =I16/$R$15 -> 0 | L16: =SUM($K$13:K16) -> 0.0014025245
A17: 24838 | B17: 87.3856 | C17: -0.4561 | H17: =$R$12+($R$11/12)*(ROW()-12) -> -3.8546667 | I17: =COUNTIFS($C$6:$C$718,">"&H16,$C$6:$C$718,"<="&H17) -> 0 | J17: =TEXT(H16,"0.00")&" to "&TEXT(H17,"0.00") -> -5.02 to -3.85 | K17: =I17/$R$15 -> 0 | L17: =SUM($K$13:K17) -> 0.0014025245
A18: 24869 | B18: 87.352 | C18: -0.0336 | H18: =$R$12+($R$11/12)*(ROW()-12) -> -2.6848 | I18: =COUNTIFS($C$6:$C$718,">"&H17,$C$6:$C$718,"<="&H18) -> 4 | J18: =TEXT(H17,"0.00")&" to "&TEXT(H18,"0.00") -> -3.85 to -2.68 | K18: =I18/$R$15 -> 0.0056100982 | L18: =SUM($K$13:K18) -> 0.0070126227
A19: 24898 | B19: 87.2794 | C19: -0.0726 | H19: =$R$12+($R$11/12)*(ROW()-12) -> -1.5149333 | I19: =COUNTIFS($C$6:$C$718,">"&H18,$C$6:$C$718,"<="&H19) -> 10 | J19: =TEXT(H18,"0.00")&" to "&TEXT(H19,"0.00") -> -2.68 to -1.51 | K19: =I19/$R$15 -> 0.014025245 | L19: =SUM($K$13:K19) -> 0.021037868
A20: 24929 | B20: 87.0627 | C20: -0.2167 | H20: =$R$12+($R$11/12)*(ROW()-12) -> -0.34506667 | I20: =COUNTIFS($C$6:$C$718,">"&H19,$C$6:$C$718,"<="&H20) -> 150 | J20: =TEXT(H19,"0.00")&" to "&TEXT(H20,"0.00") -> -1.51 to -0.35 | K20: =I20/$R$15 -> 0.21037868 | L20: =SUM($K$13:K20) -> 0.23141655
A21: 24959 | B21: 87.6951 | C21: 0.6324 | H21: =$R$12+($R$11/12)*(ROW()-12) -> 0.8248 | I21: =COUNTIFS($C$6:$C$718,">"&H20,$C$6:$C$718,"<="&H21) -> 507 | J21: =TEXT(H20,"0.00")&" to "&TEXT(H21,"0.00") -> -0.35 to 0.82 | K21: =I21/$R$15 -> 0.71107994 | L21: =SUM($K$13:K21) -> 0.94249649
A22: 24990 | B22: 87.6744 | C22: -0.0207 | H22: =$R$12+($R$11/12)*(ROW()-12) -> 1.9946667 | I22: =COUNTIFS($C$6:$C$718,">"&H21,$C$6:$C$718,"<="&H22) -> 38 | J22: =TEXT(H21,"0.00")&" to "&TEXT(H22,"0.00") -> 0.82 to 1.99 | K22: =I22/$R$15 -> 0.053295933 | L22: =SUM($K$13:K22) -> 0.99579243
A23: 25020 | B23: 87.2002 | C23: -0.4742 | H23: =$R$12+($R$11/12)*(ROW()-12) -> 3.1645333 | I23: =COUNTIFS($C$6:$C$718,">"&H22,$C$6:$C$718,"<="&H23) -> 2 | J23: =TEXT(H22,"0.00")&" to "&TEXT(H23,"0.00") -> 1.99 to 3.16 | K23: =I23/$R$15 -> 0.0028050491 | L23: =SUM($K$13:K23) -> 0.99859748
A24: 25051 | B24: 87.1055 | C24: -0.0947 | H24: =$R$12+($R$11/12)*(ROW()-12) -> 4.3344 | I24: =COUNTIFS($C$6:$C$718,">"&H23,$C$6:$C$718,"<="&H24) -> 1 | J24: =TEXT(H23,"0.00")&" to "&TEXT(H24,"0.00") -> 3.16 to 4.33 | K24: =I24/$R$15 -> 0.0014025245 | L24: =SUM($K$13:K24) -> 1
A25: 25082 | B25: 87.0988 | C25: -0.0067
A26: 25112 | B26: 86.9369 | C26: -0.1619
A27: 25143 | B27: 87.7249 | C27: 0.788
A28: 25173 | B28: 87.6668 | C28: -0.0581
A29: 25204 | B29: 87.8712 | C29: 0.2044
A30: 25235 | B30: 88.1166 | C30: 0.2454
A31: 25263 | B31: 88.4902 | C31: 0.3736
A32: 25294 | B32: 87.8507 | C32: -0.6395
A33: 25324 | B33: 87.2081 | C33: -0.6426
A34: 25355 | B34: 87.7487 | C34: 0.5406
A35: 25385 | B35: 87.9011 | C35: 0.1524
A36: 25416 | B36: 87.7936 | C36: -0.1075
... A718: 46174 | B718: 76.1 | C718: -0.0663

Sheet ISM
A1: ISM Manufacturing PMI (local full-history file) · ISM · ISM Manufacturing PMI — local full-history file (FRED's NAPM is discontinued/proprietary)
A2: Source: Institute for Supply Management July 2026 release / local full-history file · refreshed 2026-08-10 · monthly | F2: Z-ANALYSIS — latest level vs full history | Q2: ISM Stats — Chg MoM (pts) | U2: Std Dev bands
F3: Latest | G3: =B$947 -> 55.6 | Q3: Mean | R3: =AVERAGE($C$6:$C$947) -> 0.0041401274 | U3: k | V3: 1 | W3: 2 | X3: 3
A4: Date | B4: Value | C4: Chg MoM (pts) | F4: Hist mean | G4: =AVERAGE($B$5:$B$947) -> 52.818431 | Q4: Standard Error | R4: =_xlfn.STDEV.S($C$6:$C$947)/SQRT(COUNT($C$6:$C$947)) -> 0.084311749 | U4: Upper | V4: =$R$3+V$3*$R$7 -> 2.5918379 | W4: =$R$3+W$3*$R$7 -> 5.1795356 | X4: =$R$3+X$3*$R$7 -> 7.7672334
A5: 17533 | B5: 51.7 | F5: Hist std dev | G5: =_xlfn.STDEV.S($B$5:$B$947) -> 7.1529853 | Q5: Median | R5: =MEDIAN($C$6:$C$947) -> -0.02 | U5: Lower | V5: =$R$3-V$3*$R$7 -> -2.5835576 | W5: =$R$3-W$3*$R$7 -> -5.1712554 | X5: =$R$3-X$3*$R$7 -> -7.7589531
A6: 17564 | B6: 50.2 | C6: -1.5 | F6: Z-score | G6: =(G3-G4)/G5 -> 0.38886833 | Q6: Mode | R6: =_xlfn.MODE.SNGL($C$6:$C$947) -> -0.5
A7: 17593 | B7: 43.3 | C7: -6.9 | F7: Percentile | G7: =_xlfn.PERCENTRANK.INC($B$5:$B$947,G3) -> 0.658 | Q7: Standard Deviation | R7: =_xlfn.STDEV.S($C$6:$C$947) -> 2.5876978 | U7: Actual vs Normal distribution
A8: 17624 | B8: 45.4 | C8: 2.1 | F8: Read | G8: =IF(G6>=2,"EXTREME HIGH",IF(G6>=1,"HIGH (+1 to +2σ)",IF(G6<=-2,"EXTREME LOW",IF(G6<=-1,"LOW (-1 to -2σ)","NORMAL (±1σ)")))) -> NORMAL (±1σ) | Q8: Sample Variance | R8: =_xlfn.VAR.S($C$6:$C$947) -> 6.6961797 | U8: ±kσ | V8: Actual % | W8: Normal % | X8: Verdict
