Workbook

Sheet Names
A5: Country Name | B5: % World GDP | C5: GDP y/y | D5: GDP q/q | E5: Key Rate | F5: Inflation | G5: PMI | H5: Summary | K5: Country Name | L5: % World GDP | M5: Jun-26 | N5: May-26 | O5: Change | P5: Trend | Q5: Summary
A6: United States | B6: =VLOOKUP(A6,Data!$A$51:$L$275,2,FALSE)/SUM(Data!$B$53:$B$275) -> 0.19182681 | C6: =VLOOKUP($A6,Data!$A$51:$L$275,COLUMN(C5),FALSE) -> 0.022 | D6: =VLOOKUP($A6,Data!$A$51:$L$275,COLUMN(D5),FALSE) -> 0 | E6: =VLOOKUP($A6,Data!$A$51:$L$275,COLUMN(E5),FALSE) -> 0.0363 | F6: =VLOOKUP($A6,Data!$A$51:$L$275,COLUMN(F5),FALSE) -> 0.043 | G6: =Tabs!F27 -> 53.9 | H6: =VLOOKUP(A6,$K$6:$Q$28,7,FALSE) -> Growing, slower | K6: Ireland | L6: =VLOOKUP(K6,$A$6:$B$28,2,FALSE) -> 0.0024891812 | M6: =Tabs!AP27 -> 54.9 | N6: =Tabs!AP26 -> 55.9 | O6: =M6-N6 -> -1 | P6: 18 | Q6: Growing, slower
A7: Euro Area | B7: =VLOOKUP(A7,Data!$A$51:$L$275,2,FALSE)/SUM(Data!$B$53:$B$275) -> 0.14558285 | C7: =VLOOKUP($A7,Data!$A$51:$L$275,COLUMN(C6),FALSE) -> 0.003 | D7: =VLOOKUP($A7,Data!$A$51:$L$275,COLUMN(D6),FALSE) -> 0 | E7: =VLOOKUP($A7,Data!$A$51:$L$275,COLUMN(E6),FALSE) -> 0.0193 | F7: =VLOOKUP($A7,Data!$A$51:$L$275,COLUMN(F6),FALSE) -> 0.0314 | G7: =Tabs!N27 -> 51.4 | H7: =VLOOKUP(A7,$K$6:$Q$28,7,FALSE) -> Growing, slower | K7: Czech Republic | L7: =VLOOKUP(K7,$A$6:$B$28,2,FALSE) -> 0.0022608159 | M7: =Tabs!CL27 -> 53.9 | N7: =Tabs!CL26 -> 52.2 | O7: =M7-N7 -> 1.7 | P7: 19 | Q7: Growing, faster
A8: China | B8: =VLOOKUP(A8,Data!$A$51:$L$275,2,FALSE)/SUM(Data!$B$53:$B$275) -> 0.10550474 | C8: =VLOOKUP($A8,Data!$A$51:$L$275,COLUMN(C7),FALSE) -> 0.0446 | D8: =VLOOKUP($A8,Data!$A$51:$L$275,COLUMN(D7),FALSE) -> 0 | E8: =VLOOKUP($A8,Data!$A$51:$L$275,COLUMN(E7),FALSE) -> 0.03 | F8: =VLOOKUP($A8,Data!$A$51:$L$275,COLUMN(F7),FALSE) -> -0.001 | G8: =Tabs!AT27 -> 51.7 | H8: =VLOOKUP(A8,$K$6:$Q$28,7,FALSE) -> Growing, slower | K8: Canada | L8: =VLOOKUP(K8,$A$6:$B$28,2,FALSE) -> 0.020838329 | M8: =Tabs!J27 -> 53 | N8: =Tabs!J26 -> 52.9 | O8: =M8-N8 -> 0.1 | P8: 19 | Q8: Growing, at same rate
A9: Japan | B9: =VLOOKUP(A9,Data!$A$51:$L$275,2,FALSE)/SUM(Data!$B$53:$B$275) -> 0.055960904 | C9: =VLOOKUP($A9,Data!$A$51:$L$275,COLUMN(C8),FALSE) -> 0.0143 | D9: =VLOOKUP($A9,Data!$A$51:$L$275,COLUMN(D8),FALSE) -> 0 | E9: =VLOOKUP($A9,Data!$A$51:$L$275,COLUMN(E8),FALSE) -> 0.0075 | F9: =VLOOKUP($A9,Data!$A$51:$L$275,COLUMN(F8),FALSE) -> 0.0192 | G9: =Tabs!AX27 -> 54.8 | H9: =VLOOKUP(A9,$K$6:$Q$28,7,FALSE) -> Growing, slower | K9: United States | L9: =VLOOKUP(K9,$A$6:$B$28,2,FALSE) -> 0.19182681 | M9: =Tabs!F27 -> 53.9 | N9: =Tabs!F26 -> 55.1 | O9: =M9-N9 -> -1.2 | P9: 49 | Q9: Growing, slower
A10: Germany | B10: =VLOOKUP(A10,Data!$A$51:$L$275,2,FALSE)/SUM(Data!$B$53:$B$275) -> 0.041505384 | C10: =VLOOKUP($A10,Data!$A$51:$L$275,COLUMN(C9),FALSE) -> 0.0072 | D10: =VLOOKUP($A10,Data!$A$51:$L$275,COLUMN(D9),FALSE) -> 0 | E10: =VLOOKUP($A10,Data!$A$51:$L$275,COLUMN(E9),FALSE) -> 0.0238 | F10: =VLOOKUP($A10,Data!$A$51:$L$275,COLUMN(F9),FALSE) -> 0.0202 | G10: =Tabs!V27 -> 50.3 | H10: =VLOOKUP(A10,$K$6:$Q$28,7,FALSE) -> Contracting, from Growing | K10: Spain | L10: =VLOOKUP(K10,$A$6:$B$28,2,FALSE) -> 0.015506 | M10: =Tabs!AH27 -> 49.7 | N10: =Tabs!AH26 -> 51.2 | O10: =M10-N10 -> -1.5 | P10: 12 | Q10: Growing, faster
A11: France | B11: =VLOOKUP(A11,Data!$A$51:$L$275,2,FALSE)/SUM(Data!$B$53:$B$275) -> 0.031228948 | C11: =VLOOKUP($A11,Data!$A$51:$L$275,COLUMN(C10),FALSE) -> 0.009 | D11: =VLOOKUP($A11,Data!$A$51:$L$275,COLUMN(D10),FALSE) -> 0 | E11: =VLOOKUP($A11,Data!$A$51:$L$275,COLUMN(E10),FALSE) -> 0.0238 | F11: =VLOOKUP($A11,Data!$A$51:$L$275,COLUMN(F10),FALSE) -> 0.016 | G11: =Tabs!Z27 -> 51.2 | H11: =VLOOKUP(A11,$K$6:$Q$28,7,FALSE) -> Contracting, faster | K11: Mexico | L11: =VLOOKUP(K11,$A$6:$B$28,2,FALSE) -> 0.014398429 | M11: =Tabs!BN27 -> 51.3 | N11: =Tabs!BN26 -> 49.6 | O11: =M11-N11 -> 1.7 | P11: 15 | Q11: Growing, faster
A12: United Kingdom | B12: =VLOOKUP(A12,Data!$A$51:$L$275,2,FALSE)/SUM(Data!$B$53:$B$275) -> 0.028796858 | C12: =VLOOKUP($A12,Data!$A$51:$L$275,COLUMN(C11),FALSE) -> 0.0169 | D12: =VLOOKUP($A12,Data!$A$51:$L$275,COLUMN(D11),FALSE) -> 0 | E12: =VLOOKUP($A12,Data!$A$51:$L$275,COLUMN(E11),FALSE) -> 0.0373 | F12: =VLOOKUP($A12,Data!$A$51:$L$275,COLUMN(F11),FALSE) -> 0.028 | G12: =Tabs!R27 -> 52.5 | H12: =VLOOKUP(A12,$K$6:$Q$28,7,FALSE) -> Growing, faster | K12: United Kingdom | L12: =VLOOKUP(K12,$A$6:$B$28,2,FALSE) -> 0.028796858 | M12: =Tabs!R27 -> 52.5 | N12: =Tabs!R26 -> 53.9 | O12: =M12-N12 -> -1.4 | P12: 20 | Q12: Growing, faster
A13: Brazil | B13: =VLOOKUP(A13,Data!$A$51:$L$275,2,FALSE)/SUM(Data!$B$53:$B$275) -> 0.025645417 | C13: =VLOOKUP($A13,Data!$A$51:$L$275,COLUMN(C12),FALSE) -> 0.0233 | D13: =VLOOKUP($A13,Data!$A$51:$L$275,COLUMN(D12),FALSE) -> 0 | E13: =VLOOKUP($A13,Data!$A$51:$L$275,COLUMN(E12),FALSE) -> 0.15 | F13: =VLOOKUP($A13,Data!$A$51:$L$275,COLUMN(F12),FALSE) -> 0.0424 | G13: =Tabs!BB27 -> 50.8 | H13: =VLOOKUP(A13,$K$6:$Q$28,7,FALSE) -> Contracting, faster | K13: India | L13: =VLOOKUP(K13,$A$6:$B$28,2,FALSE) -> 0.021432078 | M13: =Tabs!BF27 -> 54.2 | N13: =Tabs!BF26 -> 55 | O13: =M13-N13 -> -0.8 | P13: 13 | Q13: Growing, faster
A14: Russia | B14: =VLOOKUP(A14,Data!$A$51:$L$275,2,FALSE)/SUM(Data!$B$53:$B$275) -> 0.023944096 | C14: =VLOOKUP($A14,Data!$A$51:$L$275,COLUMN(C13),FALSE) -> 0.0113 | D14: =VLOOKUP($A14,Data!$A$51:$L$275,COLUMN(D13),FALSE) -> 0 | E14: =VLOOKUP($A14,Data!$A$51:$L$275,COLUMN(E13),FALSE) -> 0.16 | F14: =VLOOKUP($A14,Data!$A$51:$L$275,COLUMN(F13),FALSE) -> 0.0704 | G14: =Tabs!BJ27 -> 50.3 | H14: =VLOOKUP(A14,$K$6:$Q$28,7,FALSE) -> Growing, faster | K14: Poland | L14: =VLOOKUP(K14,$A$6:$B$28,2,FALSE) -> 0.0059146599 | M14: =Tabs!CP27 -> 46.1 | N14: =Tabs!CP26 -> 49.4 | O14: =M14-N14 -> -3.3 | P14: 2 | Q14: Growing, faster
A15: Italy | B15: =VLOOKUP(A15,Data!$A$51:$L$275,2,FALSE)/SUM(Data!$B$53:$B$275) -> 0.023647221 | C15: =VLOOKUP($A15,Data!$A$51:$L$275,COLUMN(C14),FALSE) -> 0.009 | D15: =VLOOKUP($A15,Data!$A$51:$L$275,COLUMN(D14),FALSE) -> 0 | E15: =VLOOKUP($A15,Data!$A$51:$L$275,COLUMN(E14),FALSE) -> 0.0238 | F15: =VLOOKUP($A15,Data!$A$51:$L$275,COLUMN(F14),FALSE) -> 0.0206 | G15: =Tabs!AD27 -> 52.2 | H15: =VLOOKUP(A15,$K$6:$Q$28,7,FALSE) -> Contracting, at same rate | K15: Turkey | L15: =VLOOKUP(K15,$A$6:$B$28,2,FALSE) -> 0.0093629751 | M15: =Tabs!CH27 -> 47.1 | N15: =Tabs!CH26 -> 49.8 | O15: =M15-N15 -> -2.7 | P15: 4 | Q15: Growing, faster
A16: India | B16: =VLOOKUP(A16,Data!$A$51:$L$275,2,FALSE)/SUM(Data!$B$53:$B$275) -> 0.021432078 | C16: =VLOOKUP($A16,Data!$A$51:$L$275,COLUMN(C15),FALSE) -> 0.0667 | D16: =VLOOKUP($A16,Data!$A$51:$L$275,COLUMN(D15),FALSE) -> 0 | E16: =VLOOKUP($A16,Data!$A$51:$L$275,COLUMN(E15),FALSE) -> 0.0525 | F16: =VLOOKUP($A16,Data!$A$51:$L$275,COLUMN(F15),FALSE) -> 0.042 | G16: =Tabs!BF27 -> 54.2 | H16: =VLOOKUP(A16,$K$6:$Q$28,7,FALSE) -> Growing, faster | K16: Japan | L16: =VLOOKUP(K16,$A$6:$B$28,2,FALSE) -> 0.055960904 | M16: =Tabs!AX27 -> 54.8 | N16: =Tabs!AX26 -> 54.5 | O16: =M16-N16 -> 0.3 | P16: 6 | Q16: Growing, slower
A17: Canada | B17: =VLOOKUP(A17,Data!$A$51:$L$275,2,FALSE)/SUM(Data!$B$53:$B$275) -> 0.020838329 | C17: =VLOOKUP($A17,Data!$A$51:$L$275,COLUMN(C16),FALSE) -> 0.0195 | D17: =VLOOKUP($A17,Data!$A$51:$L$275,COLUMN(D16),FALSE) -> 0 | E17: =VLOOKUP($A17,Data!$A$51:$L$275,COLUMN(E16),FALSE) -> 0.0225 | F17: =VLOOKUP($A17,Data!$A$51:$L$275,COLUMN(F16),FALSE) -> 0.0199 | G17: =Tabs!J27 -> 53 | H17: =VLOOKUP(A17,$K$6:$Q$28,7,FALSE) -> Growing, at same rate | K17: Russia | L17: =VLOOKUP(K17,$A$6:$B$28,2,FALSE) -> 0.023944096 | M17: =Tabs!BJ27 -> 50.3 | N17: =Tabs!BJ26 -> 48.8 | O17: =M17-N17 -> 1.5 | P17: 5 | Q17: Growing, faster
A18: Australia | B18: =VLOOKUP(A18,Data!$A$51:$L$275,2,FALSE)/SUM(Data!$B$53:$B$275) -> 0.017823908 | C18: =VLOOKUP($A18,Data!$A$51:$L$275,COLUMN(C17),FALSE) -> 0.0189 | D18: =VLOOKUP($A18,Data!$A$51:$L$275,COLUMN(D17),FALSE) -> 0 | E18: =VLOOKUP($A18,Data!$A$51:$L$275,COLUMN(E17),FALSE) -> 0.0431 | F18: =VLOOKUP($A18,Data!$A$51:$L$275,COLUMN(F17),FALSE) -> 0.024 | G18: =Tabs!BR27 -> 51.5 | H18: =VLOOKUP(A18,$K$6:$Q$28,7,FALSE) -> Growing, from Contracting | K18: Taiwan | L18: =VLOOKUP(K18,$A$6:$B$28,2,FALSE) -> 0.0055835303 | M18: =Tabs!CD27 -> 55.2 | N18: =Tabs!CD26 -> 56.1 | O18: =M18-N18 -> -0.9 | P18: 15 | Q18: Growing, slower
A19: Spain | B19: =VLOOKUP(A19,Data!$A$51:$L$275,2,FALSE)/SUM(Data!$B$53:$B$275) -> 0.015506 | C19: =VLOOKUP($A19,Data!$A$51:$L$275,COLUMN(C18),FALSE) -> 0.0228 | D19: =VLOOKUP($A19,Data!$A$51:$L$275,COLUMN(D18),FALSE) -> 0 | E19: =VLOOKUP($A19,Data!$A$51:$L$275,COLUMN(E18),FALSE) -> 0.0238 | F19: =VLOOKUP($A19,Data!$A$51:$L$275,COLUMN(F18),FALSE) -> 0.0206 | G19: =Tabs!AH27 -> 49.7 | H19: =VLOOKUP(A19,$K$6:$Q$28,7,FALSE) -> Growing, faster | K19: China | L19: =VLOOKUP(K19,$A$6:$B$28,2,FALSE) -> 0.10550474 | M19: =Tabs!AT27 -> 51.7 | N19: =Tabs!AT26 -> 51.8 | O19: =M19-N19 -> -0.1 | P19: 6 | Q19: Growing, slower
A20: South Korea | B20: =VLOOKUP(A20,Data!$A$51:$L$275,2,FALSE)/SUM(Data!$B$53:$B$275) -> 0.014900832 | C20: =VLOOKUP($A20,Data!$A$51:$L$275,COLUMN(C19),FALSE) -> 0.023 | D20: =VLOOKUP($A20,Data!$A$51:$L$275,COLUMN(D19),FALSE) -> 0 | E20: =VLOOKUP($A20,Data!$A$51:$L$275,COLUMN(E19),FALSE) -> 0.025 | F20: =VLOOKUP($A20,Data!$A$51:$L$275,COLUMN(F19),FALSE) -> 0.0184 | G20: =Tabs!BV27 -> 52.1 | H20: =VLOOKUP(A20,$K$6:$Q$28,7,FALSE) -> Contracting, slower | K20: Australia | L20: =VLOOKUP(K20,$A$6:$B$28,2,FALSE) -> 0.017823908 | M20: =Tabs!BR27 -> 51.5 | N20: =Tabs!BR26 -> 50.7 | O20: =M20-N20 -> 0.8 | P20: 1 | Q20: Growing, from Contracting
A21: Mexico | B21: =VLOOKUP(A21,Data!$A$51:$L$275,2,FALSE)/SUM(Data!$B$53:$B$275) -> 0.014398429 | C21: =VLOOKUP($A21,Data!$A$51:$L$275,COLUMN(C20),FALSE) -> 0.0141 | D21: =VLOOKUP($A21,Data!$A$51:$L$275,COLUMN(D20),FALSE) -> 0 | E21: =VLOOKUP($A21,Data!$A$51:$L$275,COLUMN(E20),FALSE) -> 0.07 | F21: =VLOOKUP($A21,Data!$A$51:$L$275,COLUMN(F20),FALSE) -> 0.0334 | G21: =Tabs!BN27 -> 51.3 | H21: =VLOOKUP(A21,$K$6:$Q$28,7,FALSE) -> Growing, faster | K21: Euro Area | L21: =VLOOKUP(K21,$A$6:$B$28,2,FALSE) -> 0.14558285 | M21: =Tabs!N27 -> 51.4 | N21: =Tabs!N26 -> 51.6 | O21: =M21-N21 -> -0.2 | P21: 17 | Q21: Growing, slower
A22: Indonesia | B22: =VLOOKUP(A22,Data!$A$51:$L$275,2,FALSE)/SUM(Data!$B$53:$B$275) -> 0.0099110517 | C22: =VLOOKUP($A22,Data!$A$51:$L$275,COLUMN(C21),FALSE) -> 0.0482 | D22: =VLOOKUP($A22,Data!$A$51:$L$275,COLUMN(D21),FALSE) -> 0 | E22: =VLOOKUP($A22,Data!$A$51:$L$275,COLUMN(E21),FALSE) -> 0.0475 | F22: =VLOOKUP($A22,Data!$A$51:$L$275,COLUMN(F21),FALSE) -> 0.0224 | G22: =Tabs!BZ27 -> 46.9 | H22: =VLOOKUP(A22,$K$6:$Q$28,7,FALSE) -> Contracting, faster | K22: Germany | L22: =VLOOKUP(K22,$A$6:$B$28,2,FALSE) -> 0.041505384 | M22: =Tabs!V27 -> 50.3 | N22: =Tabs!V26 -> 50.1 | O22: =M22-N22 -> 0.2 | P22: 1 | Q22: Contracting, from Growing
A23: Turkey | B23: =VLOOKUP(A23,Data!$A$51:$L$275,2,FALSE)/SUM(Data!$B$53:$B$275) -> 0.0093629751 | C23: =VLOOKUP($A23,Data!$A$51:$L$275,COLUMN(C22),FALSE) -> 0.0259 | D23: =VLOOKUP($A23,Data!$A$51:$L$275,COLUMN(D22),FALSE) -> 0 | E23: =VLOOKUP($A23,Data!$A$51:$L$275,COLUMN(E22),FALSE) -> 0.38 | F23: =VLOOKUP($A23,Data!$A$51:$L$275,COLUMN(F22),FALSE) -> 0.3067 | G23: =Tabs!CH27 -> 47.1 | H23: =VLOOKUP(A23,$K$6:$Q$28,7,FALSE) -> Growing, faster | K23: Greece | L23: =VLOOKUP(K23,$A$6:$B$28,2,FALSE) -> 0.0027632195 | M23: =Tabs!AL27 -> 53.8 | N23: =Tabs!AL26 -> 53.3 | O23: =M23-N23 -> 0.5 | P23: 3 | Q23: Contracting, slower
A24: Poland | B24: =VLOOKUP(A24,Data!$A$51:$L$275,2,FALSE)/SUM(Data!$B$53:$B$275) -> 0.0059146599 | C24: =VLOOKUP($A24,Data!$A$51:$L$275,COLUMN(C23),FALSE) -> 0.0336 | D24: =VLOOKUP($A24,Data!$A$51:$L$275,COLUMN(D23),FALSE) -> 0 | E24: =VLOOKUP($A24,Data!$A$51:$L$275,COLUMN(E23),FALSE) -> 0.04 | F24: =VLOOKUP($A24,Data!$A$51:$L$275,COLUMN(F23),FALSE) -> 0.0503 | G24: =Tabs!CP27 -> 46.1 | H24: =VLOOKUP(A24,$K$6:$Q$28,7,FALSE) -> Growing, faster | K24: South Korea | L24: =VLOOKUP(K24,$A$6:$B$28,2,FALSE) -> 0.014900832 | M24: =Tabs!BV27 -> 52.1 | N24: =Tabs!BV26 -> 54.8 | O24: =M24-N24 -> -2.7 | P24: 3 | Q24: Contracting, slower
A25: Taiwan | B25: =VLOOKUP(A25,Data!$A$51:$L$275,2,FALSE)/SUM(Data!$B$53:$B$275) -> 0.0055835303 | C25: =VLOOKUP($A25,Data!$A$51:$L$275,COLUMN(C24),FALSE) -> 0.087 | D25: =VLOOKUP($A25,Data!$A$51:$L$275,COLUMN(D24),FALSE) -> 0 | E25: =VLOOKUP($A25,Data!$A$51:$L$275,COLUMN(E24),FALSE) -> 0.0111 | F25: =VLOOKUP($A25,Data!$A$51:$L$275,COLUMN(F24),FALSE) -> 0.0166 | G25: =Tabs!CD27 -> 55.2 | H25: =VLOOKUP(A25,$K$6:$Q$28,7,FALSE) -> Growing, slower | K25: Italy | L25: =VLOOKUP(K25,$A$6:$B$28,2,FALSE) -> 0.023647221 | M25: =Tabs!AD27 -> 52.2 | N25: =Tabs!AD26 -> 52.9 | O25: =M25-N25 -> -0.7 | P25: 2 | Q25: Contracting, at same rate
A26: Greece | B26: =VLOOKUP(A26,Data!$A$51:$L$275,2,FALSE)/SUM(Data!$B$53:$B$275) -> 0.0027632195 | C26: =VLOOKUP($A26,Data!$A$51:$L$275,COLUMN(C25),FALSE) -> 0.0217 | D26: =VLOOKUP($A26,Data!$A$51:$L$275,COLUMN(D25),FALSE) -> 0 | E26: =VLOOKUP($A26,Data!$A$51:$L$275,COLUMN(E25),FALSE) -> 0.0238 | F26: =VLOOKUP($A26,Data!$A$51:$L$275,COLUMN(F25),FALSE) -> 0.0274 | G26: =Tabs!AL27 -> 53.8 | H26: =VLOOKUP(A26,$K$6:$Q$28,7,FALSE) -> Contracting, slower | K26: Brazil | L26: =VLOOKUP(K26,$A$6:$B$28,2,FALSE) -> 0.025645417 | M26: =Tabs!BB27 -> 50.8 | N26: =Tabs!BB26 -> 49.1 | O26: =M26-N26 -> 1.7 | P26: 3 | Q26: Contracting, faster
A27: Ireland | B27: =VLOOKUP(A27,Data!$A$51:$L$275,2,FALSE)/SUM(Data!$B$53:$B$275) -> 0.0024891812 | C27: =VLOOKUP($A27,Data!$A$51:$L$275,COLUMN(C26),FALSE) -> 0.0366 | D27: =VLOOKUP($A27,Data!$A$51:$L$275,COLUMN(D26),FALSE) -> 0 | E27: =VLOOKUP($A27,Data!$A$51:$L$275,COLUMN(E26),FALSE) -> 0.0238 | F27: =VLOOKUP($A27,Data!$A$51:$L$275,COLUMN(F26),FALSE) -> 0.0186 | G27: =Tabs!AP27 -> 54.9 | H27: =VLOOKUP(A27,$K$6:$Q$28,7,FALSE) -> Growing, slower | K27: France | L27: =VLOOKUP(K27,$A$6:$B$28,2,FALSE) -> 0.031228948 | M27: =Tabs!Z27 -> 51.2 | N27: =Tabs!Z26 -> 49.7 | O27: =M27-N27 -> 1.5 | P27: 7 | Q27: Contracting, faster
A28: Czech Republic | B28: =VLOOKUP(A28,Data!$A$51:$L$275,2,FALSE)/SUM(Data!$B$53:$B$275) -> 0.0022608159 | C28: =VLOOKUP($A28,Data!$A$51:$L$275,COLUMN(C27),FALSE) -> 0.0236 | D28: =VLOOKUP($A28,Data!$A$51:$L$275,COLUMN(D27),FALSE) -> 0 | E28: =VLOOKUP($A28,Data!$A$51:$L$275,COLUMN(E27),FALSE) -> 0.035 | F28: =VLOOKUP($A28,Data!$A$51:$L$275,COLUMN(F27),FALSE) -> 0.0233 | G28: =Tabs!CL27 -> 53.9 | H28: =VLOOKUP(A28,$K$6:$Q$28,7,FALSE) -> Growing, faster | K28: Indonesia | L28: =VLOOKUP(K28,$A$6:$B$28,2,FALSE) -> 0.0099110517 | M28: =Tabs!BZ27 -> 46.9 | N28: =Tabs!BZ26 -> 50 | O28: =M28-N28 -> -3.1 | P28: 2 | Q28: Contracting, faster

Sheet Tabs
A1: Rows 26-27 REFRESHED to May/Jun-2026 (S&P Global press releases via web, fetched 2026-07-03; China block = Caixin/RatingDog, HSBC lineage). Rows 4-25 remain the 2012-14 teaching corpus. May row Change left blank (Apr-2026 not tracked). Cross-checks: US ISM Jun 53.3 (May 54.0); China NBS official Jun 50.3 (May 50.0).
A2: Global | E2: US | I2: CA | M2: EZ | Q2: UK | U2: DE | Y2: FR | AC2: IT | AG2: ES | AK2: EL | AO2: IR | AS2: CH | AW2: JP | BA2: BRL | BE2: IND | BI2: RS | BM2: MX | BQ2: AU | BU2: SK | BY2: INS | CC2: TW | CG2: TUR | CK2: CZ | CO2: PL
A3: Date | B3: Index | C3: Change | E3: Date | F3: Index | G3: Change | I3: Date | J3: Index | K3: Change | M3: Date | N3: Index | O3: Change | Q3: Date | R3: Index | S3: Change | U3: Date | V3: Index | W3: Change | Y3: Date | Z3: Index | AA3: Change | AC3: Date | AD3: Index | AE3: Change | AG3: Date | AH3: Index | AI3: Change | AK3: Date | AL3: Index | AM3: Change | AO3: Date | AP3: Index | AQ3: Change | AS3: Date | AT3: Index | AU3: Change | AW3: Date | AX3: Index | AY3: Change | BA3: Date | BB3: Index | BC3: Change | BE3: Date | BF3: Index | BG3: Change | BI3: Date | BJ3: Index | BK3: Change | BM3: Date | BN3: Index | BO3: Change | BQ3: Date | BR3: Index | BS3: Change | BU3: Date | BV3: Index | BW3: Change | BY3: Date | BZ3: Index | CA3: Change | CC3: Date | CD3: Index | CE3: Change | CG3: Date | CH3: Index | CI3: Change | CK3: Date | CL3: Index | CM3: Change | CO3: Date | CP3: Index | CQ3: Change
A4: =Global!A98 -> 41244 | B4: =Global!B98 -> 50 | C4: =Global!C98 -> 0.4 | E4: =US!A98 -> 41244 | F4: =US!B98 -> 54 | G4: =US!C98 -> 1.2 | I4: =CA!A98 -> 41244 | J4: =CA!B98 -> 50.4 | K4: =CA!C98 -> 0 | M4: =EZ!A98 -> 41244 | N4: =EZ!B98 -> 46.1 | O4: =EZ!C98 -> -0.1 | Q4: =UK!A98 -> 41244 | R4: =UK!B98 -> 50.7 | S4: =UK!C98 -> 2.3 | U4: =DE!A98 -> 41244 | V4: =DE!B98 -> 46 | W4: =DE!C98 -> -0.8 | Y4: =FR!A98 -> 41244 | Z4: =FR!B98 -> 44.6 | AA4: =FR!C98 -> 0.1 | AC4: =IT!A98 -> 41244 | AD4: =IT!B98 -> 46.7 | AE4: =IT!C98 -> 1.6 | AG4: =ES!A98 -> 41244 | AH4: =ES!B98 -> 44.6 | AI4: =ES!C98 -> -0.7 | AK4: =ES!A98 -> 41244 | AL4: =EL!B98 -> 41.4 | AM4: =EL!C98 -> -0.4 | AO4: =IR!A98 -> 41244 | AP4: =IR!B98 -> 51.4 | AQ4: =IR!C98 -> -1 | AS4: =CH!A98 -> 41252 | AT4: =CH!B98 -> 51.5 | AU4: =CH!C98 -> 1 | AW4: =JP!A98 -> 41244 | AX4: =JP!B98 -> 45 | AY4: =JP!C98 -> -1.5 | BA4: =BRL!A98 -> 41244 | BB4: =BRL!B98 -> 51.1 | BC4: =BRL!C98 -> -1.1 | BE4: =IND!A98 -> 41244 | BF4: =IND!B98 -> 54.7 | BG4: =IND!C98 -> 1 | BI4: =RS!A98 -> 41244 | BJ4: =RS!B98 -> 50 | BK4: =RS!C98 -> -2.2 | BM4: =MX!A98 -> 41244 | BN4: =MX!B98 -> 57.1 | BO4: =MX!C98 -> 1.5 | BQ4: =AU!A98 -> 41244 | BR4: =AU!B98 -> 44.3 | BS4: =AU!C98 -> 0.7 | BU4: =SK!A98 -> 41244 | BV4: =SK!B98 -> 50.1 | BW4: =SK!C98 -> 1.9 | BY4: =INS!A98 -> 41244 | BZ4: =INS!B98 -> 51.5 | CA4: =INS!C98 -> -0.4 | CC4: =TW!A98 -> 41244 | CD4: =TW!B98 -> 47.4 | CE4: =TW!C98 -> -0.4 | CG4: =TUR!A98 -> 41244 | CH4: =TUR!B98 -> 53.1 | CI4: =TUR!C98 -> 1.5 | CK4: =CZ!A98 -> 41244 | CL4: =CZ!B98 -> 46 | CM4: =CZ!C98 -> -2.2 | CO4: =PL!A98 -> 41244 | CP4: =PL!B98 -> 48.3 | CQ4: =PL!C98 -> 0.1
A5: =Global!A99 -> 41275 | B5: =Global!B99 -> 51.5 | C5: =Global!C99 -> 1.5 | E5: =US!A99 -> 41275 | F5: =US!B99 -> 55.8 | G5: =US!C99 -> 1.8 | I5: =CA!A99 -> 41275 | J5: =CA!B99 -> 50.5 | K5: =CA!C99 -> 0.1 | M5: =EZ!A99 -> 41275 | N5: =EZ!B99 -> 47.9 | O5: =EZ!C99 -> 1.8 | Q5: =UK!A99 -> 41275 | R5: =UK!B99 -> 50.9 | S5: =UK!C99 -> 0.2 | U5: =DE!A99 -> 41275 | V5: =DE!B99 -> 49.8 | W5: =DE!C99 -> 3.8 | Y5: =FR!A99 -> 41275 | Z5: =FR!B99 -> 42.9 | AA5: =FR!C99 -> -1.7 | AC5: =IT!A99 -> 41275 | AD5: =IT!B99 -> 47.8 | AE5: =IT!C99 -> 1.1 | AG5: =ES!A99 -> 41275 | AH5: =ES!B99 -> 46.1 | AI5: =ES!C99 -> 1.5 | AK5: =ES!A99 -> 41275 | AL5: =EL!B99 -> 41.7 | AM5: =EL!C99 -> 0.3 | AO5: =IR!A99 -> 41275 | AP5: =IR!B99 -> 50.3 | AQ5: =IR!C99 -> -1.1 | AS5: =CH!A99 -> 41275 | AT5: =CH!B99 -> 52.3 | AU5: =CH!C99 -> 0.8 | AW5: =JP!A99 -> 41275 | AX5: =JP!B99 -> 47.7 | AY5: =JP!C99 -> 2.7 | BA5: =BRL!A99 -> 41275 | BB5: =BRL!B99 -> 53.2 | BC5: =BRL!C99 -> 2.1 | BE5: =IND!A99 -> 41275 | BF5: =IND!B99 -> 53.2 | BG5: =IND!C99 -> -1.5 | BI5: =RS!A99 -> 41275 | BJ5: =RS!B99 -> 52 | BK5: =RS!C99 -> 2 | BM5: =MX!A99 -> 41275 | BN5: =MX!B99 -> 55 | BO5: =MX!C99 -> -2.1 | BQ5: =AU!A99 -> 41275 | BR5: =AU!B99 -> 40.2 | BS5: =AU!C99 -> -4.1 | BU5: =SK!A99 -> 41275 | BV5: =SK!B99 -> 49.9 | BW5: =SK!C99 -> -0.2 | BY5: =INS!A99 -> 41275 | BZ5: =INS!B99 -> 49.7 | CA5: =INS!C99 -> -1.8 | CC5: =TW!A99 -> 41275 | CD5: =TW!B99 -> 51.5 | CE5: =TW!C99 -> 4.1 | CG5: =TUR!A99 -> 41275 | CH5: =TUR!B99 -> 54 | CI5: =TUR!C99 -> 0.9 | CK5: =CZ!A99 -> 41275 | CL5: =CZ!B99 -> 48.3 | CM5: =CZ!C99 -> 2.3 | CO5: =PL!A99 -> 41275 | CP5: =PL!B99 -> 48.6 | CQ5: =PL!C99 -> 0.3
A6: =Global!A100 -> 41306 | B6: =Global!B100 -> 50.9 | C6: =Global!C100 -> -0.6 | E6: =US!A100 -> 41306 | F6: =US!B100 -> 54.3 | G6: =US!C100 -> -1.5 | I6: =CA!A100 -> 41306 | J6: =CA!B100 -> 51.7 | K6: =CA!C100 -> 1.2 | M6: =EZ!A100 -> 41306 | N6: =EZ!B100 -> 47.9 | O6: =EZ!C100 -> 0 | Q6: =UK!A100 -> 41306 | R6: =UK!B100 -> 48.2 | S6: =UK!C100 -> -2.7 | U6: =DE!A100 -> 41306 | V6: =DE!B100 -> 50.3 | W6: =DE!C100 -> 0.5 | Y6: =FR!A100 -> 41306 | Z6: =FR!B100 -> 43.9 | AA6: =FR!C100 -> 1 | AC6: =IT!A100 -> 41306 | AD6: =IT!B100 -> 45.8 | AE6: =IT!C100 -> -2 | AG6: =ES!A100 -> 41306 | AH6: =ES!B100 -> 46.8 | AI6: =ES!C100 -> 0.7 | AK6: =ES!A100 -> 41306 | AL6: =EL!B100 -> 43 | AM6: =EL!C100 -> 1.3 | AO6: =IR!A100 -> 41306 | AP6: =IR!B100 -> 51.5 | AQ6: =IR!C100 -> 1.2 | AS6: =CH!A100 -> 41307 | AT6: =CH!B100 -> 50.4 | AU6: =CH!C100 -> -1.9 | AW6: =JP!A100 -> 41306 | AX6: =JP!B100 -> 48.5 | AY6: =JP!C100 -> 0.8 | BA6: =BRL!A100 -> 41306 | BB6: =BRL!B100 -> 52.5 | BC6: =BRL!C100 -> -0.7 | BE6: =IND!A100 -> 41306 | BF6: =IND!B100 -> 54.2 | BG6: =IND!C100 -> 1 | BI6: =RS!A100 -> 41306 | BJ6: =RS!B100 -> 52 | BK6: =RS!C100 -> 0 | BM6: =MX!A100 -> 41306 | BN6: =MX!B100 -> 53.4 | BO6: =MX!C100 -> -1.6 | BQ6: =AU!A100 -> 41306 | BR6: =AU!B100 -> 45.6 | BS6: =AU!C100 -> 5.4 | BU6: =SK!A100 -> 41306 | BV6: =SK!B100 -> 50.9 | BW6: =SK!C100 -> 1 | BY6: =INS!A100 -> 41306 | BZ6: =INS!B100 -> 50.5 | CA6: =INS!C100 -> 0.8 | CC6: =TW!A100 -> 41306 | CD6: =TW!B100 -> 51.5 | CE6: =TW!C100 -> 0 | CG6: =TUR!A100 -> 41306 | CH6: =TUR!B100 -> 53.5 | CI6: =TUR!C100 -> -0.5 | CK6: =CZ!A100 -> 41306 | CL6: =CZ!B100 -> 49.9 | CM6: =CZ!C100 -> 1.6 | CO6: =PL!A100 -> 41306 | CP6: =PL!B100 -> 48.9 | CQ6: =PL!C100 -> 0.3
A7: =Global!A101 -> 41334 | B7: =Global!B101 -> 51.2 | C7: =Global!C101 -> 0.3 | E7: =US!A101 -> 41334 | F7: =US!B101 -> 54.6 | G7: =US!C101 -> 0.3 | I7: =CA!A101 -> 41334 | J7: =CA!B101 -> 49.3 | K7: =CA!C101 -> -2.4 | M7: =EZ!A101 -> 41334 | N7: =EZ!B101 -> 46.8 | O7: =EZ!C101 -> -1.1 | Q7: =UK!A101 -> 41334 | R7: =UK!B101 -> 49.3 | S7: =UK!C101 -> 1.1 | U7: =DE!A101 -> 41334 | V7: =DE!B101 -> 49 | W7: =DE!C101 -> -1.3 | Y7: =FR!A101 -> 41334 | Z7: =FR!B101 -> 44 | AA7: =FR!C101 -> 0.1 | AC7: =IT!A101 -> 41334 | AD7: =IT!B101 -> 44.5 | AE7: =IT!C101 -> -1.3 | AG7: =ES!A101 -> 41334 | AH7: =ES!B101 -> 44.2 | AI7: =ES!C101 -> -2.6 | AK7: =ES!A101 -> 41334 | AL7: =EL!B101 -> 42.1 | AM7: =EL!C101 -> -0.9 | AO7: =IR!A101 -> 41334 | AP7: =IR!B101 -> 48.6 | AQ7: =IR!C101 -> -2.9 | AS7: =CH!A101 -> 41336 | AT7: =CH!B101 -> 51.6 | AU7: =CH!C101 -> 1.2 | AW7: =JP!A101 -> 41334 | AX7: =JP!B101 -> 50.4 | AY7: =JP!C101 -> 1.9 | BA7: =BRL!A101 -> 41334 | BB7: =BRL!B101 -> 51.8 | BC7: =BRL!C101 -> -0.7 | BE7: =IND!A101 -> 41334 | BF7: =IND!B101 -> 52 | BG7: =IND!C101 -> -2.2 | BI7: =RS!A101 -> 41334 | BJ7: =RS!B101 -> 50.8 | BK7: =RS!C101 -> -1.2 | BM7: =MX!A101 -> 41334 | BN7: =MX!B101 -> 52.2 | BO7: =MX!C101 -> -1.2 | BQ7: =AU!A101 -> 41334 | BR7: =AU!B101 -> 44.4 | BS7: =AU!C101 -> -1.2 | BU7: =SK!A101 -> 41334 | BV7: =SK!B101 -> 52 | BW7: =SK!C101 -> 1.1 | BY7: =INS!A101 -> 41334 | BZ7: =INS!B101 -> 51.3 | CA7: =INS!C101 -> 0.8 | CC7: =TW!A101 -> 41334 | CD7: =TW!B101 -> 50.2 | CE7: =TW!C101 -> -1.3 | CG7: =TUR!A101 -> 41334 | CH7: =TUR!B101 -> 52.3 | CI7: =TUR!C101 -> -1.2 | CK7: =CZ!A101 -> 41334 | CL7: =CZ!B101 -> 49.1 | CM7: =CZ!C101 -> -0.8 | CO7: =PL!A101 -> 41334 | CP7: =PL!B101 -> 48 | CQ7: =PL!C101 -> -0.9
A8: =Global!A102 -> 41365 | B8: =Global!B102 -> 50.4 | C8: =Global!C102 -> -0.8 | E8: =US!A102 -> 41365 | F8: =US!B102 -> 52.1 | G8: =US!C102 -> -2.5 | I8: =CA!A102 -> 41365 | J8: =CA!B102 -> 50.1 | K8: =CA!C102 -> 0.8 | M8: =EZ!A102 -> 41365 | N8: =EZ!B102 -> 46.7 | O8: =EZ!C102 -> -0.1 | Q8: =UK!A102 -> 41365 | R8: =UK!B102 -> 50.6 | S8: =UK!C102 -> 1.3 | U8: =DE!A102 -> 41365 | V8: =DE!B102 -> 48.1 | W8: =DE!C102 -> -0.9 | Y8: =FR!A102 -> 41365 | Z8: =FR!B102 -> 44.4 | AA8: =FR!C102 -> 0.4 | AC8: =IT!A102 -> 41365 | AD8: =IT!B102 -> 45.5 | AE8: =IT!C102 -> 1 | AG8: =ES!A102 -> 41365 | AH8: =ES!B102 -> 44.7 | AI8: =ES!C102 -> 0.5 | AK8: =ES!A102 -> 41365 | AL8: =EL!B102 -> 45 | AM8: =EL!C102 -> 2.9 | AO8: =IR!A102 -> 41365 | AP8: =IR!B102 -> 48 | AQ8: =IR!C102 -> -0.6 | AS8: =CH!A102 -> 41368 | AT8: =CH!B102 -> 50.4 | AU8: =CH!C102 -> -1.2 | AW8: =JP!A102 -> 41365 | AX8: =JP!B102 -> 51.1 | AY8: =JP!C102 -> 0.7 | BA8: =BRL!A102 -> 41365 | BB8: =BRL!B102 -> 50.8 | BC8: =BRL!C102 -> -1 | BE8: =IND!A102 -> 41365 | BF8: =IND!B102 -> 51 | BG8: =IND!C102 -> -1 | BI8: =RS!A102 -> 41365 | BJ8: =RS!B102 -> 50.6 | BK8: =RS!C102 -> -0.2 | BM8: =MX!A102 -> 41365 | BN8: =MX!B102 -> 51.7 | BO8: =MX!C102 -> -0.5 | BQ8: =AU!A102 -> 41365 | BR8: =AU!B102 -> 36.7 | BS8: =AU!C102 -> -7.7 | BU8: =SK!A102 -> 41365 | BV8: =SK!B102 -> 52.6 | BW8: =SK!C102 -> 0.6 | BY8: =INS!A102 -> 41365 | BZ8: =INS!B102 -> 51.7 | CA8: =INS!C102 -> 0.4 | CC8: =TW!A102 -> 41365 | CD8: =TW!B102 -> 51.2 | CE8: =TW!C102 -> 1 | CG8: =TUR!A102 -> 41365 | CH8: =TUR!B102 -> 51.3 | CI8: =TUR!C102 -> -1 | CK8: =CZ!A102 -> 41365 | CL8: =CZ!B102 -> 49.5 | CM8: =CZ!C102 -> 0.4 | CO8: =PL!A102 -> 41365 | CP8: =PL!B102 -> 48 | CQ8: =PL!C102 -> 0
A9: =Global!A103 -> 41395 | B9: =Global!B103 -> 50.6 | C9: =Global!C103 -> 0.2 | E9: =US!A103 -> 41395 | F9: =US!B103 -> 52.3 | G9: =US!C103 -> 0.2 | I9: =CA!A103 -> 41395 | J9: =CA!B103 -> 53.2 | K9: =CA!C103 -> 3.1 | M9: =EZ!A103 -> 41395 | N9: =EZ!B103 -> 48.3 | O9: =EZ!C103 -> 1.6 | Q9: =UK!A103 -> 41395 | R9: =UK!B103 -> 52.1 | S9: =UK!C103 -> 1.5 | U9: =DE!A103 -> 41395 | V9: =DE!B103 -> 49.4 | W9: =DE!C103 -> 1.3 | Y9: =FR!A103 -> 41395 | Z9: =FR!B103 -> 46.4 | AA9: =FR!C103 -> 2 | AC9: =IT!A103 -> 41395 | AD9: =IT!B103 -> 47.3 | AE9: =IT!C103 -> 1.8 | AG9: =ES!A103 -> 41395 | AH9: =ES!B103 -> 48.1 | AI9: =ES!C103 -> 3.4 | AK9: =ES!A103 -> 41395 | AL9: =EL!B103 -> 45.3 | AM9: =EL!C103 -> 0.3 | AO9: =IR!A103 -> 41395 | AP9: =IR!B103 -> 49.7 | AQ9: =IR!C103 -> 1.7 | AS9: =CH!A103 -> 41399 | AT9: =CH!B103 -> 49.2 | AU9: =CH!C103 -> -1.2 | AW9: =JP!A103 -> 41395 | AX9: =JP!B103 -> 51.5 | AY9: =JP!C103 -> 0.4 | BA9: =BRL!A103 -> 41395 | BB9: =BRL!B103 -> 50.4 | BC9: =BRL!C103 -> -0.4 | BE9: =IND!A103 -> 41395 | BF9: =IND!B103 -> 50.1 | BG9: =IND!C103 -> -0.9 | BI9: =RS!A103 -> 41395 | BJ9: =RS!B103 -> 50.4 | BK9: =RS!C103 -> -0.2 | BM9: =MX!A103 -> 41395 | BN9: =MX!B103 -> 51.8 | BO9: =MX!C103 -> 0.1 | BQ9: =AU!A103 -> 41395 | BR9: =AU!B103 -> 43.8 | BS9: =AU!C103 -> 7.1 | BU9: =SK!A103 -> 41395 | BV9: =SK!B103 -> 51.1 | BW9: =SK!C103 -> -1.5 | BY9: =INS!A103 -> 41395 | BZ9: =INS!B103 -> 51.6 | CA9: =INS!C103 -> -0.1 | CC9: =TW!A103 -> 41395 | CD9: =TW!B103 -> 50.7 | CE9: =TW!C103 -> -0.5 | CG9: =TUR!A103 -> 41395 | CH9: =TUR!B103 -> 51.1 | CI9: =TUR!C103 -> -0.2 | CK9: =CZ!A103 -> 41395 | CL9: =CZ!B103 -> 50.1 | CM9: =CZ!C103 -> 0.6 | CO9: =PL!A103 -> 41395 | CP9: =PL!B103 -> 46.9 | CQ9: =PL!C103 -> -1.1
A10: =Global!A104 -> 41426 | B10: =Global!B104 -> 50.6 | C10: =Global!C104 -> 0 | E10: =US!A104 -> 41426 | F10: =US!B104 -> 51.9 | G10: =US!C104 -> -0.4 | I10: =CA!A104 -> 41426 | J10: =CA!B104 -> 52.4 | K10: =CA!C104 -> -0.8 | M10: =EZ!A104 -> 41426 | N10: =EZ!B104 -> 48.8 | O10: =EZ!C104 -> 0.5 | Q10: =UK!A104 -> 41426 | R10: =UK!B104 -> 53 | S10: =UK!C104 -> 0.9 | U10: =DE!A104 -> 41426 | V10: =DE!B104 -> 48.6 | W10: =DE!C104 -> -0.8 | Y10: =FR!A104 -> 41426 | Z10: =FR!B104 -> 48.4 | AA10: =FR!C104 -> 2 | AC10: =IT!A104 -> 41426 | AD10: =IT!B104 -> 49.1 | AE10: =IT!C104 -> 1.8 | AG10: =ES!A104 -> 41426 | AH10: =ES!B104 -> 50 | AI10: =ES!C104 -> 1.9 | AK10: =ES!A104 -> 41426 | AL10: =EL!B104 -> 45.4 | AM10: =EL!C104 -> 0.1 | AO10: =IR!A104 -> 41426 | AP10: =IR!B104 -> 50.3 | AQ10: =IR!C104 -> 0.6 | AS10: =CH!A104 -> 41431 | AT10: =CH!B104 -> 48.2 | AU10: =CH!C104 -> -1 | AW10: =JP!A104 -> 41426 | AX10: =JP!B104 -> 52.3 | AY10: =JP!C104 -> 0.8 | BA10: =BRL!A104 -> 41426 | BB10: =BRL!B104 -> 50.4 | BC10: =BRL!C104 -> 0 | BE10: =IND!A104 -> 41426 | BF10: =IND!B104 -> 50.3 | BG10: =IND!C104 -> 0.2 | BI10: =RS!A104 -> 41426 | BJ10: =RS!B104 -> 51.7 | BK10: =RS!C104 -> 1.3 | BM10: =MX!A104 -> 41426 | BN10: =MX!B104 -> 51.3 | BO10: =MX!C104 -> -0.5 | BQ10: =AU!A104 -> 41426 | BR10: =AU!B104 -> 49.6 | BS10: =AU!C104 -> 5.8 | BU10: =SK!A104 -> 41426 | BV10: =SK!B104 -> 49.4 | BW10: =SK!C104 -> -1.7 | BY10: =INS!A104 -> 41426 | BZ10: =INS!B104 -> 51 | CA10: =INS!C104 -> -0.6 | CC10: =TW!A104 -> 41426 | CD10: =TW!B104 -> 47.1 | CE10: =TW!C104 -> -3.6 | CG10: =TUR!A104 -> 41426 | CH10: =TUR!B104 -> 51.2 | CI10: =TUR!C104 -> 0.1 | CK10: =CZ!A104 -> 41426 | CL10: =CZ!B104 -> 51 | CM10: =CZ!C104 -> 0.9 | CO10: =PL!A104 -> 41426 | CP10: =PL!B104 -> 48 | CQ10: =PL!C104 -> 1.1
A11: =Global!A105 -> 41456 | B11: =Global!B105 -> 50.8 | C11: =Global!C105 -> 0.2 | E11: =US!A105 -> 41456 | F11: =US!B105 -> 53.7 | G11: =US!C105 -> 1.8 | I11: =CA!A105 -> 41456 | J11: =CA!B105 -> 52 | K11: =CA!C105 -> -0.4 | M11: =EZ!A105 -> 41456 | N11: =EZ!B105 -> 50.3 | O11: =EZ!C105 -> 1.5 | Q11: =UK!A105 -> 41456 | R11: =UK!B105 -> 54.7 | S11: =UK!C105 -> 1.7 | U11: =DE!A105 -> 41456 | V11: =DE!B105 -> 50.7 | W11: =DE!C105 -> 2.1 | Y11: =FR!A105 -> 41456 | Z11: =FR!B105 -> 49.7 | AA11: =FR!C105 -> 1.3 | AC11: =IT!A105 -> 41456 | AD11: =IT!B105 -> 50.4 | AE11: =IT!C105 -> 1.3 | AG11: =ES!A105 -> 41456 | AH11: =ES!B105 -> 49.8 | AI11: =ES!C105 -> -0.2 | AK11: =ES!A105 -> 41456 | AL11: =EL!B105 -> 47 | AM11: =EL!C105 -> 1.6 | AO11: =IR!A105 -> 41456 | AP11: =IR!B105 -> 51 | AQ11: =IR!C105 -> 0.7 | AS11: =CH!A105 -> 41462 | AT11: =CH!B105 -> 47.7 | AU11: =CH!C105 -> -0.5 | AW11: =JP!A105 -> 41456 | AX11: =JP!B105 -> 50.7 | AY11: =JP!C105 -> -1.6 | BA11: =BRL!A105 -> 41456 | BB11: =BRL!B105 -> 48.5 | BC11: =BRL!C105 -> -1.9 | BE11: =IND!A105 -> 41456 | BF11: =IND!B105 -> 50.1 | BG11: =IND!C105 -> -0.2 | BI11: =RS!A105 -> 41456 | BJ11: =RS!B105 -> 49.2 | BK11: =RS!C105 -> -2.5 | BM11: =MX!A105 -> 41456 | BN11: =MX!B105 -> 49.7 | BO11: =MX!C105 -> -1.6 | BQ11: =AU!A105 -> 41456 | BR11: =AU!B105 -> 42 | BS11: =AU!C105 -> -7.6 | BU11: =SK!A105 -> 41456 | BV11: =SK!B105 -> 47.2 | BW11: =SK!C105 -> -2.2 | BY11: =INS!A105 -> 41456 | BZ11: =INS!B105 -> 50.7 | CA11: =INS!C105 -> -0.3 | CC11: =TW!A105 -> 41456 | CD11: =TW!B105 -> 49.5 | CE11: =TW!C105 -> 2.4 | CG11: =TUR!A105 -> 41456 | CH11: =TUR!B105 -> 49.8 | CI11: =TUR!C105 -> -1.4 | CK11: =CZ!A105 -> 41456 | CL11: =CZ!B105 -> 52 | CM11: =CZ!C105 -> 1 | CO11: =PL!A105 -> 41456 | CP11: =PL!B105 -> 49.3 | CQ11: =PL!C105 -> 1.3
A12: =Global!A106 -> 41487 | B12: =Global!B106 -> 51.6 | C12: =Global!C106 -> 0.8 | E12: =US!A106 -> 41487 | F12: =US!B106 -> 53.7 | G12: =US!C106 -> 0 | I12: =CA!A106 -> 41487 | J12: =CA!B106 -> 52.1 | K12: =CA!C106 -> 0.1 | M12: =EZ!A106 -> 41487 | N12: =EZ!B106 -> 51.4 | O12: =EZ!C106 -> 1.1 | Q12: =UK!A106 -> 41487 | R12: =UK!B106 -> 57.3 | S12: =UK!C106 -> 2.6 | U12: =DE!A106 -> 41487 | V12: =DE!B106 -> 51.8 | W12: =DE!C106 -> 1.1 | Y12: =FR!A106 -> 41487 | Z12: =FR!B106 -> 49.7 | AA12: =FR!C106 -> 0 | AC12: =IT!A106 -> 41487 | AD12: =IT!B106 -> 51.3 | AE12: =IT!C106 -> 0.9 | AG12: =ES!A106 -> 41487 | AH12: =ES!B106 -> 51.1 | AI12: =ES!C106 -> 1.3 | AK12: =ES!A106 -> 41487 | AL12: =EL!B106 -> 48.7 | AM12: =EL!C106 -> 1.7 | AO12: =IR!A106 -> 41487 | AP12: =IR!B106 -> 52 | AQ12: =IR!C106 -> 1 | AS12: =CH!A106 -> 41493 | AT12: =CH!B106 -> 50.1 | AU12: =CH!C106 -> 2.4 | AW12: =JP!A106 -> 41487 | AX12: =JP!B106 -> 52.2 | AY12: =JP!C106 -> 1.5 | BA12: =BRL!A106 -> 41487 | BB12: =BRL!B106 -> 49.4 | BC12: =BRL!C106 -> 0.9 | BE12: =IND!A106 -> 41487 | BF12: =IND!B106 -> 48.5 | BG12: =IND!C106 -> -1.6 | BI12: =RS!A106 -> 41487 | BJ12: =RS!B106 -> 49.4 | BK12: =RS!C106 -> 0.2 | BM12: =MX!A106 -> 41487 | BN12: =MX!B106 -> 50.8 | BO12: =MX!C106 -> 1.1 | BQ12: =AU!A106 -> 41487 | BR12: =AU!B106 -> 46.4 | BS12: =AU!C106 -> 4.4 | BU12: =SK!A106 -> 41487 | BV12: =SK!B106 -> 47.5 | BW12: =SK!C106 -> 0.3 | BY12: =INS!A106 -> 41487 | BZ12: =INS!B106 -> 48.5 | CA12: =INS!C106 -> -2.2 | CC12: =TW!A106 -> 41487 | CD12: =TW!B106 -> 48.6 | CE12: =TW!C106 -> -0.9 | CG12: =TUR!A106 -> 41487 | CH12: =TUR!B106 -> 50.9 | CI12: =TUR!C106 -> 1.1 | CK12: =CZ!A106 -> 41487 | CL12: =CZ!B106 -> 53.9 | CM12: =CZ!C106 -> 1.9 | CO12: =PL!A106 -> 41487 | CP12: =PL!B106 -> 51.1 | CQ12: =PL!C106 -> 1.8
A13: =Global!A107 -> 41518 | B13: =Global!B107 -> 51.8 | C13: =Global!C107 -> 0.2 | E13: =US!A107 -> 41518 | F13: =US!B107 -> 52.8 | G13: =US!C107 -> -0.9 | I13: =CA!A107 -> 41518 | J13: =CA!B107 -> 54.2 | K13: =CA!C107 -> 2.1 | M13: =EZ!A107 -> 41518 | N13: =EZ!B107 -> 51.1 | O13: =EZ!C107 -> -0.3 | Q13: =UK!A107 -> 41518 | R13: =UK!B107 -> 56.7 | S13: =UK!C107 -> -0.6 | U13: =DE!A107 -> 41518 | V13: =DE!B107 -> 51.1 | W13: =DE!C107 -> -0.7 | Y13: =FR!A107 -> 41518 | Z13: =FR!B107 -> 49.8 | AA13: =FR!C107 -> 0.1 | AC13: =IT!A107 -> 41518 | AD13: =IT!B107 -> 50.8 | AE13: =IT!C107 -> -0.5 | AG13: =ES!A107 -> 41518 | AH13: =ES!B107 -> 50.7 | AI13: =ES!C107 -> -0.4 | AK13: =ES!A107 -> 41518 | AL13: =EL!B107 -> 47.5 | AM13: =EL!C107 -> -1.2 | AO13: =IR!A107 -> 41518 | AP13: =IR!B107 -> 52.7 | AQ13: =IR!C107 -> 0.7 | AS13: =CH!A107 -> 41524 | AT13: =CH!B107 -> 50.2 | AU13: =CH!C107 -> 0.1 | AW13: =JP!A107 -> 41518 | AX13: =JP!B107 -> 52.5 | AY13: =JP!C107 -> 0.3 | BA13: =BRL!A107 -> 41518 | BB13: =BRL!B107 -> 49.9 | BC13: =BRL!C107 -> 0.5 | BE13: =IND!A107 -> 41518 | BF13: =IND!B107 -> 49.6 | BG13: =IND!C107 -> 1.1 | BI13: =RS!A107 -> 41518 | BJ13: =RS!B107 -> 49.4 | BK13: =RS!C107 -> 0 | BM13: =MX!A107 -> 41518 | BN13: =MX!B107 -> 50 | BO13: =MX!C107 -> -0.8 | BQ13: =AU!A107 -> 41518 | BR13: =AU!B107 -> 51.7 | BS13: =AU!C107 -> 5.3 | BU13: =SK!A107 -> 41518 | BV13: =SK!B107 -> 49.7 | BW13: =SK!C107 -> 2.2 | BY13: =INS!A107 -> 41518 | BZ13: =INS!B107 -> 50.2 | CA13: =INS!C107 -> 1.7 | CC13: =TW!A107 -> 41518 | CD13: =TW!B107 -> 50 | CE13: =TW!C107 -> 1.4 | CG13: =TUR!A107 -> 41518 | CH13: =TUR!B107 -> 54 | CI13: =TUR!C107 -> 3.1 | CK13: =CZ!A107 -> 41518 | CL13: =CZ!B107 -> 53.4 | CM13: =CZ!C107 -> -0.5 | CO13: =PL!A107 -> 41518 | CP13: =PL!B107 -> 52.6 | CQ13: =PL!C107 -> 1.5
A14: =Global!A108 -> 41548 | B14: =Global!B108 -> 52.1 | C14: =Global!C108 -> 0.3 | E14: =US!A108 -> 41548 | F14: =US!B108 -> 51.8 | G14: =US!C108 -> -1 | I14: =CA!A108 -> 41548 | J14: =CA!B108 -> 55.6 | K14: =CA!C108 -> 1.4 | M14: =EZ!A108 -> 41548 | N14: =EZ!B108 -> 51.3 | O14: =EZ!C108 -> 0.2 | Q14: =UK!A108 -> 41548 | R14: =UK!B108 -> 56.5 | S14: =UK!C108 -> -0.2 | U14: =DE!A108 -> 41548 | V14: =DE!B108 -> 51.7 | W14: =DE!C108 -> 0.6 | Y14: =FR!A108 -> 41548 | Z14: =FR!B108 -> 49.1 | AA14: =FR!C108 -> -0.7 | AC14: =IT!A108 -> 41548 | AD14: =IT!B108 -> 50.7 | AE14: =IT!C108 -> -0.1 | AG14: =ES!A108 -> 41548 | AH14: =ES!B108 -> 50.9 | AI14: =ES!C108 -> 0.2 | AK14: =ES!A108 -> 41548 | AL14: =EL!B108 -> 47.3 | AM14: =EL!C108 -> -0.2 | AO14: =IR!A108 -> 41548 | AP14: =IR!B108 -> 54.9 | AQ14: =IR!C108 -> 2.2 | AS14: =CH!A108 -> 41554 | AT14: =CH!B108 -> 50.9 | AU14: =CH!C108 -> 0.7 | AW14: =JP!A108 -> 41548 | AX14: =JP!B108 -> 54.2 | AY14: =JP!C108 -> 1.7 | BA14: =BRL!A108 -> 41548 | BB14: =BRL!B108 -> 50.2 | BC14: =BRL!C108 -> 0.3 | BE14: =IND!A108 -> 41548 | BF14: =IND!B108 -> 49.6 | BG14: =IND!C108 -> 0 | BI14: =RS!A108 -> 41548 | BJ14: =RS!B108 -> 51.8 | BK14: =RS!C108 -> 2.4 | BM14: =MX!A108 -> 41548 | BN14: =MX!B108 -> 50.2 | BO14: =MX!C108 -> 0.2 | BQ14: =AU!A108 -> 41548 | BR14: =AU!B108 -> 53.2 | BS14: =AU!C108 -> 1.5 | BU14: =SK!A108 -> 41548 | BV14: =SK!B108 -> 50.2 | BW14: =SK!C108 -> 0.5 | BY14: =INS!A108 -> 41548 | BZ14: =INS!B108 -> 50.9 | CA14: =INS!C108 -> 0.7 | CC14: =TW!A108 -> 41548 | CD14: =TW!B108 -> 52 | CE14: =TW!C108 -> 2 | CG14: =TUR!A108 -> 41548 | CH14: =TUR!B108 -> 53.3 | CI14: =TUR!C108 -> -0.7 | CK14: =CZ!A108 -> 41548 | CL14: =CZ!B108 -> 54.5 | CM14: =CZ!C108 -> 1.1 | CO14: =PL!A108 -> 41548 | CP14: =PL!B108 -> 53.4 | CQ14: =PL!C108 -> 0.8
A15: =Global!A109 -> 41579 | B15: =Global!B109 -> 53.1 | C15: =Global!C109 -> 1 | E15: =US!A109 -> 41579 | F15: =US!B109 -> 54.7 | G15: =US!C109 -> 2.9 | I15: =CA!A109 -> 41579 | J15: =CA!B109 -> 55.3 | K15: =CA!C109 -> -0.3 | M15: =EZ!A109 -> 41579 | N15: =EZ!B109 -> 51.6 | O15: =EZ!C109 -> 0.3 | Q15: =UK!A109 -> 41579 | R15: =UK!B109 -> 58.1 | S15: =UK!C109 -> 1.6 | U15: =DE!A109 -> 41579 | V15: =DE!B109 -> 52.7 | W15: =DE!C109 -> 1 | Y15: =FR!A109 -> 41579 | Z15: =FR!B109 -> 48.4 | AA15: =FR!C109 -> -0.7 | AC15: =IT!A109 -> 41579 | AD15: =IT!B109 -> 51.4 | AE15: =IT!C109 -> 0.7 | AG15: =ES!A109 -> 41579 | AH15: =ES!B109 -> 48.6 | AI15: =ES!C109 -> -2.3 | AK15: =ES!A109 -> 41579 | AL15: =EL!B109 -> 49.2 | AM15: =EL!C109 -> 1.9 | AO15: =IR!A109 -> 41579 | AP15: =IR!B109 -> 52.4 | AQ15: =IR!C109 -> -2.5 | AS15: =CH!A109 -> 41585 | AT15: =CH!B109 -> 50.8 | AU15: =CH!C109 -> -0.1 | AW15: =JP!A109 -> 41579 | AX15: =JP!B109 -> 55.1 | AY15: =JP!C109 -> 0.9 | BA15: =BRL!A109 -> 41579 | BB15: =BRL!B109 -> 49.7 | BC15: =BRL!C109 -> -0.5 | BE15: =IND!A109 -> 41579 | BF15: =IND!B109 -> 51.3 | BG15: =IND!C109 -> 1.7 | BI15: =RS!A109 -> 41579 | BJ15: =RS!B109 -> 49.4 | BK15: =RS!C109 -> -2.4 | BM15: =MX!A109 -> 41579 | BN15: =MX!B109 -> 51.9 | BO15: =MX!C109 -> 1.7 | BQ15: =AU!A109 -> 41579 | BR15: =AU!B109 -> 47.7 | BS15: =AU!C109 -> -5.5 | BU15: =SK!A109 -> 41579 | BV15: =SK!B109 -> 50.4 | BW15: =SK!C109 -> 0.2 | BY15: =INS!A109 -> 41579 | BZ15: =INS!B109 -> 50.3 | CA15: =INS!C109 -> -0.6 | CC15: =TW!A109 -> 41579 | CD15: =TW!B109 -> 53 | CE15: =TW!C109 -> 1 | CG15: =TUR!A109 -> 41579 | CH15: =TUR!B109 -> 55 | CI15: =TUR!C109 -> 1.7 | CK15: =CZ!A109 -> 41579 | CL15: =CZ!B109 -> 55.4 | CM15: =CZ!C109 -> 0.9 | CO15: =PL!A109 -> 41579 | CP15: =PL!B109 -> 54.4 | CQ15: =PL!C109 -> 1
... A25: =Global!A119 -> 41883 | B25: =Global!B119 -> 52.2 | C25: =Global!C119 -> -0.4 | E25: =US!A119 -> 41883 | F25: =US!B119 -> 57.5 | G25: =US!C119 -> -0.4 | I25: =CA!A119 -> 41883 | J25: =CA!B119 -> 53.5 | K25: =CA!C119 -> -1.3 | M25: =EZ!A119 -> 41883 | N25: =EZ!B119 -> 50.3 | O25: =EZ!C119 -> -0.4 | Q25: =UK!A119 -> 41883 | R25: =UK!B119 -> 51.6 | S25: =UK!C119 -> -0.9 | U25: =DE!A119 -> 41883 | V25: =DE!B119 -> 49.9 | W25: =DE!C119 -> -1.5 | Y25: =FR!A119 -> 41883 | Z25: =FR!B119 -> 48.8 | AA25: =FR!C119 -> 1.9 | AC25: =IT!A119 -> 41883 | AD25: =IT!B119 -> 50.7 | AE25: =IT!C119 -> 0.9 | AG25: =ES!A119 -> 41883 | AH25: =ES!B119 -> 52.6 | AI25: =ES!C119 -> -0.2 | AK25: =ES!A119 -> 41883 | AL25: =EL!B119 -> 48.4 | AM25: =EL!C119 -> -1.7 | AO25: =IR!A119 -> 41883 | AP25: =IR!B119 -> 55.7 | AQ25: =IR!C119 -> -1.6 | AS25: =CH!A119 -> 41883 | AT25: =CH!B119 -> 51.1 | AU25: =CH!C119 -> 0.9 | AW25: =JP!A119 -> 41883 | AX25: =JP!B119 -> 51.7 | AY25: =JP!C119 -> -0.5 | BA25: =BRL!A119 -> 41883 | BB25: =BRL!B119 -> 49.3 | BC25: =BRL!C119 -> -0.9 | BE25: =IND!A119 -> 41883 | BF25: =IND!B119 -> 51 | BG25: =IND!C119 -> -1.4 | BI25: =RS!A119 -> 41883 | BJ25: =RS!B119 -> 50.4 | BK25: =RS!C119 -> -0.6 | BM25: =MX!A119 -> 41883 | BN25: =MX!B119 -> 52.6 | BO25: =MX!C119 -> 0.5 | BQ25: =AU!A119 -> 41883 | BR25: =AU!B119 -> 46.5 | BS25: =AU!C119 -> -0.8 | BU25: =SK!A119 -> 41883 | BV25: =SK!B119 -> 48.8 | BW25: =SK!C119 -> -1.5 | BY25: =INS!A119 -> 41883 | BZ25: =INS!B119 -> 50.7 | CA25: =INS!C119 -> 1.2 | CC25: =TW!A119 -> 41883 | CD25: =TW!B119 -> 53.3 | CE25: =TW!C119 -> -2.8 | CG25: =TUR!A119 -> 41883 | CH25: =TUR!B119 -> 50.4 | CI25: =TUR!C119 -> 0.4 | CK25: =CZ!A119 -> 41883 | CL25: =CZ!B119 -> 55.6 | CM25: =CZ!C119 -> 1.3 | CO25: =PL!A119 -> 41883 | CP25: =PL!B119 -> 49.5 | CQ25: =PL!C119 -> 0.5
A26: 46143 | B26: 52.7 | E26: 46143 | F26: 55.1 | I26: 46143 | J26: 52.9 | M26: 46143 | N26: 51.6 | Q26: 46143 | R26: 53.9 | U26: 46143 | V26: 50.1 | Y26: 46143 | Z26: 49.7 | AC26: 46143 | AD26: 52.9 | AG26: 46143 | AH26: 51.2 | AK26: 46143 | AL26: 53.3 | AO26: 46143 | AP26: 55.9 | AS26: 46143 | AT26: 51.8 | AW26: 46143 | AX26: 54.5 | BA26: 46143 | BB26: 49.1 | BE26: 46143 | BF26: 55 | BI26: 46143 | BJ26: 48.8 | BM26: 46143 | BN26: 49.6 | BQ26: 46143 | BR26: 50.7 | BU26: 46143 | BV26: 54.8 | BY26: 46143 | BZ26: 50 | CC26: 46143 | CD26: 56.1 | CG26: 46143 | CH26: 49.8 | CK26: 46143 | CL26: 52.2 | CO26: 46143 | CP26: 49.4
A27: 46174 | B27: 52.2 | C27: -0.5 | E27: 46174 | F27: 53.9 | G27: -1.2 | I27: 46174 | J27: 53 | K27: 0.1 | M27: 46174 | N27: 51.4 | O27: -0.2 | Q27: 46174 | R27: 52.5 | S27: -1.4 | U27: 46174 | V27: 50.3 | W27: 0.2 | Y27: 46174 | Z27: 51.2 | AA27: 1.5 | AC27: 46174 | AD27: 52.2 | AE27: -0.7 | AG27: 46174 | AH27: 49.7 | AI27: -1.5 | AK27: 46174 | AL27: 53.8 | AM27: 0.5 | AO27: 46174 | AP27: 54.9 | AQ27: -1 | AS27: 46174 | AT27: 51.7 | AU27: -0.1 | AW27: 46174 | AX27: 54.8 | AY27: 0.3 | BA27: 46174 | BB27: 50.8 | BC27: 1.7 | BE27: 46174 | BF27: 54.2 | BG27: -0.8 | BI27: 46174 | BJ27: 50.3 | BK27: 1.5 | BM27: 46174 | BN27: 51.3 | BO27: 1.7 | BQ27: 46174 | BR27: 51.5 | BS27: 0.8 | BU27: 46174 | BV27: 52.1 | BW27: -2.7 | BY27: 46174 | BZ27: 46.9 | CA27: -3.1 | CC27: 46174 | CD27: 55.2 | CE27: -0.9 | CG27: 46174 | CH27: 47.1 | CI27: -2.7 | CK27: 46174 | CL27: 53.9 | CM27: 1.7 | CO27: 46174 | CP27: 46.1 | CQ27: -3.3

Sheet Global
A71: Date | B71: Global Manufacturing PMI | C71: Change
A72: 40452 | B72: 53.7
A73: 40483 | B73: 54 | C73: =B73-B72 -> 0.3
A74: 40513 | B74: 54.9 | C74: =B74-B73 -> 0.9
A75: 40544 | B75: 57.2 | C75: =B75-B74 -> 2.3
A76: 40575 | B76: 58.2 | C76: =B76-B75 -> 1
A77: 40603 | B77: 56 | C77: =B77-B76 -> -2.2
A78: 40634 | B78: 55.5 | C78: =B78-B77 -> -0.5
A79: 40664 | B79: 53.1 | C79: =B79-B78 -> -2.4
A80: 40695 | B80: 52.8 | C80: =B80-B79 -> -0.3
A81: 40725 | B81: 50.9 | C81: =B81-B80 -> -1.9
A82: 40756 | B82: 50.4 | C82: =B82-B81 -> -0.5
A83: 40787 | B83: 50.1 | C83: =B83-B82 -> -0.3
A84: 40817 | B84: 49.5 | C84: =B84-B83 -> -0.6
A85: 40848 | B85: 49.6 | C85: =B85-B84 -> 0.1 | G85: Global | H85: Reading | I85: Points
A86: 40878 | B86: 50.4 | C86: =B86-B85 -> 0.8 | G86: Previous | H86: =B114 -> 51.9
A87: 40909 | B87: 51 | C87: =B87-B86 -> 0.6 | G87: Latest | H87: =B115 -> 52.2 | I87: =(H87-H86) -> 0.3
A88: 40940 | B88: 51.2 | C88: =B88-B87 -> 0.2
A89: 40969 | B89: 51.6 | C89: =B89-B88 -> 0.4
A90: 41000 | B90: 51.3 | C90: =B90-B89 -> -0.3
A91: 41030 | B91: 50.3 | C91: =B91-B90 -> -1
A92: 41061 | B92: 49.7 | C92: =B92-B91 -> -0.6
A93: 41091 | B93: 48.8 | C93: =B93-B92 -> -0.9
A94: 41122 | B94: 48.7 | C94: =B94-B93 -> -0.1
A95: 41153 | B95: 48.7 | C95: =B95-B94 -> 0
A96: 41183 | B96: 48.9 | C96: =B96-B95 -> 0.2
A97: 41214 | B97: 49.6 | C97: =B97-B96 -> 0.7
A98: 41244 | B98: 50 | C98: =B98-B97 -> 0.4
A99: 41275 | B99: 51.5 | C99: =B99-B98 -> 1.5
... A121: 41944 | B121: 51.8 | C121: =B121-B120 -> -0.4
A122: 41974 | C122: =B122-B121 -> -51.8
A123: 42005 | C123: =B123-B122 -> 0
A124: 42036 | C124: =B124-B123 -> 0
A125: 42064 | C125: =B125-B124 -> 0
A126: 42095 | C126: =B126-B125 -> 0
A127: 42125 | C127: =B127-B126 -> 0
A128: 42156 | C128: =B128-B127 -> 0
A129: 42186 | C129: =B129-B128 -> 0
A130: 42217 | C130: =B130-B129 -> 0
A131: 42248 | C131: =B131-B130 -> 0
...

Sheet US
A71: Date | B71: US Manufactung PMI | C71: Change | D71: US GDP Growth q/q | E71: SPY ETF
A72: 40452 | B72: 56.9 | E72: 109.7
A73: 40483 | B73: 56.6 | C73: =B73-B72 -> -0.3 | E73: 109.7
A74: 40513 | B74: 57 | C74: =B74-B73 -> 0.4 | D74: 0.039 | E74: 117.03
A75: 40544 | B75: 60.8 | C75: =B75-B74 -> 3.8 | E75: 119.76
A76: 40575 | B76: 61.4 | C76: =B76-B75 -> 0.6 | E76: 123.92
A77: 40603 | B77: 61.2 | C77: =B77-B76 -> -0.2 | D77: -0.015 | E77: 123.93
A78: 40634 | B78: 60.4 | C78: =B78-B77 -> -0.8 | E78: 127.52
A79: 40664 | B79: 53.5 | C79: =B79-B78 -> -6.9 | E79: 126.09
A80: 40695 | B80: 55.3 | C80: =B80-B79 -> 1.8 | D80: 0.029 | E80: 123.96
A81: 40725 | B81: 50.9 | C81: =B81-B80 -> -4.4 | E81: 121.48
A82: 40756 | B82: 50.6 | C82: =B82-B81 -> -0.3 | E82: 114.8
A83: 40787 | B83: 51.6 | C83: =B83-B82 -> 1 | D83: 0.008 | E83: 106.83
A84: 40817 | B84: 50.8 | C84: =B84-B83 -> -0.8 | E84: 118.5
A85: 40848 | B85: 52.7 | C85: =B85-B84 -> 1.9 | E85: 118.01 | H85: US | I85: United States
A86: 40878 | B86: 53.2 | C86: =B86-B85 -> 0.5 | D86: 0.046 | E86: 119.25
A87: 40909 | B87: 54.3 | C87: =B87-B86 -> 1.1 | E87: 124.78
A88: 40940 | B88: 53.6 | C88: =B88-B87 -> -0.7 | E88: 130.19
A89: 40969 | B89: 56 | C89: =B89-B88 -> 2.4 | D89: 0.023 | E89: 134.38
A90: 41000 | B90: 56 | C90: =B90-B89 -> 0 | E90: 133.48
A91: 41030 | B91: 54 | C91: =B91-B90 -> -2 | E91: 125.47
A92: 41061 | B92: 52.5 | C92: =B92-B91 -> -1.5 | D92: 0.016 | E92: 130.56
A93: 41091 | B93: 51.4 | C93: =B93-B92 -> -1.1 | E93: 132.1
A94: 41122 | B94: 51.5 | C94: =B94-B93 -> 0.1 | E94: 135.41
A95: 41153 | B95: 51.1 | C95: =B95-B94 -> -0.4 | D95: 0.025 | E95: 138.85
A96: 41183 | B96: 51 | C96: =B96-B95 -> -0.1 | E96: 136.32
A97: 41214 | B97: 52.8 | C97: =B97-B96 -> 1.8 | E97: 137.09
A98: 41244 | B98: 54 | C98: =B98-B97 -> 1.2 | D98: 0.001 | E98: 138.32
A99: 41275 | B99: 55.8 | C99: =B99-B98 -> 1.8 | E99: 145.4
A100: 41306 | B100: 54.3 | C100: =B100-B99 -> -1.5 | E100: 147.25
A101: 41334 | B101: 54.6 | C101: =B101-B100 -> 0.3 | D101: 0.027 | E101: 152.84
A102: 41365 | B102: 52.1 | C102: =B102-B101 -> -2.5 | E102: 155.78
A103: 41395 | B103: 52.3 | C103: =B103-B102 -> 0.2 | E103: 159.46
A104: 41426 | B104: 51.9 | C104: =B104-B103 -> -0.4 | D104: 0.018 | E104: 157.33
A105: 41456 | B105: 53.7 | C105: =B105-B104 -> 1.8 | E105: 165.46
A106: 41487 | B106: 53.7 | C106: =B106-B105 -> 0 | E106: 160.5
A107: 41518 | B107: 52.8 | C107: =B107-B106 -> -0.9 | D107: 0.045 | E107: 165.58
A108: 41548 | B108: 51.8 | C108: =B108-B107 -> -1 | E108: 173.24
A109: 41579 | B109: 54.7 | C109: =B109-B108 -> 2.9 | E109: 178.38
A110: 41609 | B110: 55 | C110: =B110-B109 -> 0.3 | D110: 0.035 | E110: 183
...

Sheet CA
A77: Date | B77: Canada PMI | C77: Change | D77: Canada GDP Growth q/q | E77: EWC ETF
A78: 40634 | B78: 56.3 | E78: 31.27
A79: 40664 | B79: 54.8 | C79: =B79-B78 -> -1.5 | E79: 30.53
A80: 40695 | B80: 52.8 | C80: =B80-B79 -> -2 | D80: -0.001 | E80: 29.58
A81: 40725 | B81: 53.1 | C81: =B81-B80 -> 0.3 | E81: 28.9
A82: 40756 | B82: 54.9 | C82: =B82-B81 -> 1.8 | E82: 27.92
A83: 40787 | B83: 55 | C83: =B83-B82 -> 0.1 | D83: 0.014 | E83: 23.81
A84: 40817 | B84: 53.7 | C84: =B84-B83 -> -1.3 | E84: 26.38
A85: 40848 | B85: 53.3 | C85: =B85-B84 -> -0.4 | E85: 25.65 | H85: CA | I85: Canada
A86: 40878 | B86: 54 | C86: =B86-B85 -> 0.7 | D86: 0.005 | E86: 25.2
A87: 40909 | B87: 50.6 | C87: =B87-B86 -> -3.4 | E87: 26.63
A88: 40940 | B88: 51.8 | C88: =B88-B87 -> 1.2 | E88: 27.49
A89: 40969 | B89: 52.4 | C89: =B89-B88 -> 0.6 | D89: 0.002 | E89: 26.84
A90: 41000 | B90: 53.3 | C90: =B90-B89 -> 0.9 | E90: 26.86
A91: 41030 | B91: 54.7 | C91: =B91-B90 -> 1.4 | E91: 23.98
A92: 41061 | B92: 54.8 | C92: =B92-B91 -> 0.1 | D92: 0.004 | E92: 24.68
A93: 41091 | B93: 53 | C93: =B93-B92 -> -1.8 | E93: 25.11
A94: 41122 | B94: 53 | C94: =B94-B93 -> 0 | E94: 26.26
A95: 41153 | B95: 52.4 | C95: =B95-B94 -> -0.6 | D95: 0.002 | E95: 27.21
A96: 41183 | B96: 51.4 | C96: =B96-B95 -> -1 | E96: 27.21
A97: 41214 | B97: 50.4 | C97: =B97-B96 -> -1 | E97: 26.85
A98: 41244 | B98: 50.4 | C98: =B98-B97 -> 0 | D98: 0.002 | E98: 27.49
A99: 41275 | B99: 50.5 | C99: =B99-B98 -> 0.1 | E99: 27.94
A100: 41306 | B100: 51.7 | C100: =B100-B99 -> 1.2 | E100: 27.31
A101: 41334 | B101: 49.3 | C101: =B101-B100 -> -2.4 | D101: 0.009 | E101: 27.59
A102: 41365 | B102: 50.1 | C102: =B102-B101 -> 0.8 | E102: 27.12
A103: 41395 | B103: 53.2 | C103: =B103-B102 -> 3.1 | E103: 26.84
A104: 41426 | B104: 52.4 | C104: =B104-B103 -> -0.8 | D104: 0.005 | E104: 25.6
A105: 41456 | B105: 52 | C105: =B105-B104 -> -0.4 | E105: 27.05
A106: 41487 | B106: 52.1 | C106: =B106-B105 -> 0.1 | E106: 26.82
A107: 41518 | B107: 54.2 | C107: =B107-B106 -> 2.1 | D107: 0.007 | E107: 27.72
A108: 41548 | B108: 55.6 | C108: =B108-B107 -> 1.4 | E108: 28.75
A109: 41579 | B109: 55.3 | C109: =B109-B108 -> -0.3 | E109: 28.48
A110: 41609 | B110: 53.5 | C110: =B110-B109 -> -1.8 | D110: 0.007 | E110: 28.94
A111: 41640 | B111: 51.7 | C111: =B111-B110 -> -1.8 | E111: 27.72
A112: 41671 | B112: 52.9 | C112: =B112-B111 -> 1.2 | E112: 28.96
A113: 41699 | B113: 53.3 | C113: =B113-B112 -> 0.4 | D113: 0.003 | E113: 29.33
A114: 41730 | B114: 52.9 | C114: =B114-B113 -> -0.4 | E114: 30.31
A115: 41760 | B115: 52.2 | C115: =B115-B114 -> -0.7 | E115: 30.47
A116: 41791 | B116: 53.5 | C116: =B116-B115 -> 1.3 | D116: 0.008 | E116: 32.21
...

Sheet UK
A1: Date | B1: UK PMI | C1: Change | D1: UK GDP Growth q/q | E1: UK ESI
A2: 38322 | B2: 53.7 | D2: =J8 -> 0.007 | E2: 110.4
A3: 38353 | B3: 51.8 | C3: =B3-B2 -> -1.9 | E3: 109.8
A4: 38384 | B4: 51.8 | C4: =B4-B3 -> 0 | E4: 109.8
A5: 38412 | B5: 52 | C5: =B5-B4 -> 0.2 | D5: =J9 -> 0.008 | E5: 105.4
A6: 38443 | B6: 49.5 | C6: =B6-B5 -> -2.5 | E6: 102.8
A7: 38473 | B7: 47.3 | C7: =B7-B6 -> -2.2 | E7: 100.8
A8: 38504 | B8: 49.6 | C8: =B8-B7 -> 2.3 | D8: =J10 -> 0.013 | E8: 96.3 | I8: 0.7 | J8: =I8/100 -> 0.007
A9: 38534 | B9: 49.2 | C9: =B9-B8 -> -0.4 | E9: 101.7 | I9: 0.8 | J9: =I9/100 -> 0.008
A10: 38565 | B10: 50.1 | C10: =B10-B9 -> 0.9 | E10: 98 | I10: 1.3 | J10: =I10/100 -> 0.013
A11: 38596 | B11: 51.5 | C11: =B11-B10 -> 1.4 | D11: =J11 -> 0.01 | E11: 102 | I11: 1 | J11: =I11/100 -> 0.01
A12: 38626 | B12: 51.7 | C12: =B12-B11 -> 0.2 | E12: 101.5 | I12: 1.3 | J12: =I12/100 -> 0.013
A13: 38657 | B13: 51 | C13: =B13-B12 -> -0.7 | E13: 98.4 | I13: 0.4 | J13: =I13/100 -> 0.004
A14: 38687 | B14: 51.1 | C14: =B14-B13 -> 0.1 | D14: =J12 -> 0.013 | E14: 97.5 | I14: 0.3 | J14: =I14/100 -> 0.003
A15: 38718 | B15: 51.7 | C15: =B15-B14 -> 0.6 | E15: 95.9 | I15: 0.2 | J15: =I15/100 -> 0.002
A16: 38749 | B16: 51.7 | C16: =B16-B15 -> 0 | E16: 103.5 | I16: 0.8 | J16: =I16/100 -> 0.008
A17: 38777 | B17: 50.8 | C17: =B17-B16 -> -0.9 | D17: =J13 -> 0.004 | E17: 100.9 | I17: 1 | J17: =I17/100 -> 0.01
A18: 38808 | B18: 54.1 | C18: =B18-B17 -> 3.3 | E18: 110.3 | I18: 1.3 | J18: =I18/100 -> 0.013
A19: 38838 | B19: 53.2 | C19: =B19-B18 -> -0.9 | E19: 107.6 | I19: 1.2 | J19: =I19/100 -> 0.012
A20: 38869 | B20: 55.1 | C20: =B20-B19 -> 1.9 | D20: =J14 -> 0.003 | E20: 108.4 | I20: 0.1 | J20: =I20/100 -> 0.001
A21: 38899 | B21: 53.8 | C21: =B21-B20 -> -1.3 | E21: 109.4 | I21: 0.1 | J21: =I21/100 -> 0.001
A22: 38930 | B22: 53.1 | C22: =B22-B21 -> -0.7 | E22: 106.1 | I22: -0.9 | J22: =I22/100 -> -0.009
A23: 38961 | B23: 54.4 | C23: =B23-B22 -> 1.3 | D23: =J15 -> 0.002 | E23: 109.4 | I23: -1.4 | J23: =I23/100 -> -0.014
A24: 38991 | B24: 53.7 | C24: =B24-B23 -> -0.7 | E24: 107.9 | I24: -2.1 | J24: =I24/100 -> -0.021
A25: 39022 | B25: 53.6 | C25: =B25-B24 -> -0.1 | E25: 111.7 | I25: -2.5 | J25: =I25/100 -> -0.025
A26: 39052 | B26: 51.9 | C26: =B26-B25 -> -1.7 | D26: =J16 -> 0.008 | E26: 112.6 | I26: -0.4 | J26: =I26/100 -> -0.004
A27: 39083 | B27: 52.8 | C27: =B27-B26 -> 0.9 | E27: 110.7 | I27: 0 | J27: =I27/100 -> 0
A28: 39114 | B28: 55.4 | C28: =B28-B27 -> 2.6 | E28: 110.8 | I28: 0.4 | J28: =I28/100 -> 0.004
A29: 39142 | B29: 54.4 | C29: =B29-B28 -> -1 | D29: =J17 -> 0.01 | E29: 113.3 | I29: 0.5 | J29: =I29/100 -> 0.005
A30: 39173 | B30: 53.9 | C30: =B30-B29 -> -0.5 | E30: 109.9 | I30: 1 | J30: =I30/100 -> 0.01
A31: 39203 | B31: 54.9 | C31: =B31-B30 -> 1 | E31: 113.7 | I31: 0.4 | J31: =I31/100 -> 0.004
A32: 39234 | B32: 54.3 | C32: =B32-B31 -> -0.6 | D32: =J18 -> 0.013 | E32: 115 | I32: -0.2 | J32: =I32/100 -> -0.002
A33: 39264 | B33: 55.7 | C33: =B33-B32 -> 1.4 | E33: 109.5 | I33: 0.5 | J33: =I33/100 -> 0.005
A34: 39295 | B34: 56.3 | C34: =B34-B33 -> 0.6 | E34: 110 | I34: 0.1 | J34: =I34/100 -> 0.001
A35: 39326 | B35: 55.1 | C35: =B35-B34 -> -1.2 | D35: =J19 -> 0.012 | E35: 113.1 | I35: 0.6 | J35: =I35/100 -> 0.006
A36: 39356 | B36: 52.9 | C36: =B36-B35 -> -2.2 | E36: 112.4 | I36: -0.1 | J36: =I36/100 -> -0.001
A37: 39387 | B37: 54.4 | C37: =B37-B36 -> 1.5 | E37: 108.1 | I37: 0 | J37: =I37/100 -> 0
A38: 39417 | B38: 52.9 | C38: =B38-B37 -> -1.5 | D38: =J21 -> 0.001 | E38: 107.7 | I38: -0.4 | J38: =I38/100 -> -0.004
A39: 39448 | B39: 50.6 | C39: =B39-B38 -> -2.3 | E39: 107.7 | I39: 0.8 | J39: =I39/100 -> 0.008
A40: 39479 | B40: 51.3 | C40: =B40-B39 -> 0.7 | E40: 99.7 | I40: -0.1 | J40: =I40/100 -> -0.001
...

Sheet EZ
A32: Date | B32: Euro Area PMI | C32: Change | D32: Euro Area GDP q/q % | E32: Column1
A33: 39264 | B33: 55.6
A34: 39295 | B34: 54.3 | C34: =B34-B33 -> -1.3
A35: 39326 | B35: 53.2 | C35: =B35-B34 -> -1.1 | D35: 0.006
A36: 39356 | B36: 51.5 | C36: =B36-B35 -> -1.7
A37: 39387 | B37: 52.8 | C37: =B37-B36 -> 1.3
A38: 39417 | B38: 52.6 | C38: =B38-B37 -> -0.2 | D38: 0.004
A39: 39448 | B39: 52.8 | C39: =B39-B38 -> 0.2
A40: 39479 | B40: 52.3 | C40: =B40-B39 -> -0.5
A41: 39508 | B41: 52 | C41: =B41-B40 -> -0.3 | D41: 0.006
A42: 39539 | B42: 50.7 | C42: =B42-B41 -> -1.3
A43: 39569 | B43: 50.6 | C43: =B43-B42 -> -0.1
A44: 39600 | B44: 49.2 | C44: =B44-B43 -> -1.4 | D44: -0.004
A45: 39630 | B45: 47.4 | C45: =B45-B44 -> -1.8
A46: 39661 | B46: 47.6 | C46: =B46-B45 -> 0.2
A47: 39692 | B47: 45 | C47: =B47-B46 -> -2.6 | D47: -0.006
A48: 39722 | B48: 38.9 | C48: =B48-B47 -> -6.1
A49: 39753 | B49: 35.6 | C49: =B49-B48 -> -3.3
A50: 39783 | B50: 33.9 | C50: =B50-B49 -> -1.7 | D50: -0.017
A51: 39814 | B51: 34.4 | C51: =B51-B50 -> 0.5
A52: 39845 | B52: 33.5 | C52: =B52-B51 -> -0.9
A53: 39873 | B53: 33.9 | C53: =B53-B52 -> 0.4 | D53: -0.028
A54: 39904 | B54: 36.8 | C54: =B54-B53 -> 2.9 | K54: 0.007
A55: 39934 | B55: 40.7 | C55: =B55-B54 -> 3.9 | K55: -0.002
A56: 39965 | B56: 42.6 | C56: =B56-B55 -> 1.9 | D56: -0.003 | K56: -0.002
A57: 39995 | B57: 46.3 | C57: =B57-B56 -> 3.7 | K57: -0.015
A58: 40026 | B58: 48.2 | C58: =B58-B57 -> 1.9 | K58: -0.025
A59: 40057 | B59: 49.3 | C59: =B59-B58 -> 1.1 | D59: 0.004 | K59: -0.001
A60: 40087 | B60: 50.7 | C60: =B60-B59 -> 1.4 | K60: 0.004
A61: 40118 | B61: 51.2 | C61: =B61-B60 -> 0.5 | K61: 0.001
A62: 40148 | B62: 51.6 | C62: =B62-B61 -> 0.4 | D62: 0.005 | K62: 0.002
A63: 40179 | B63: 52.4 | C63: =B63-B62 -> 0.8 | K63: 0.01
A64: 40210 | B64: 54.2 | C64: =B64-B63 -> 1.8 | K64: 0.004
A65: 40238 | B65: 56.6 | C65: =B65-B64 -> 2.4 | D65: 0.004 | K65: 0.003
A66: 40269 | B66: 57.6 | C66: =B66-B65 -> 1 | K66: 0.008
A67: 40299 | B67: 55.8 | C67: =B67-B66 -> -1.8 | K67: 0.002
A68: 40330 | B68: 55.6 | C68: =B68-B67 -> -0.2 | D68: 0.009 | K68: 0.002
A69: 40360 | B69: 56.7 | C69: =B69-B68 -> 1.1 | K69: -0.003
A70: 40391 | B70: 55.1 | C70: =B70-B69 -> -1.6 | K70: 0
A71: 40422 | B71: 53.7 | C71: =B71-B70 -> -1.4 | D71: =K64 -> 0.004 | K71: -0.002
...

Sheet DE
A38: Date | B38: Germany PMI | C38: Change | D38: Germany GDP q/q | E38: Column1
A39: 39478 | B39: 54.4
A40: 39479 | B40: 54.3 | C40: =B40-B39 -> -0.1
A41: 39508 | B41: 54.9 | C41: =B41-B40 -> 0.6 | D41: 0.016
A42: 39539 | B42: 53.6 | C42: =B42-B41 -> -1.3
A43: 39569 | B43: 53.5 | C43: =B43-B42 -> -0.1
A44: 39600 | B44: 52.3 | C44: =B44-B43 -> -1.2 | D44: -0.006
A45: 39630 | B45: 50.9 | C45: =B45-B44 -> -1.4
A46: 39661 | B46: 49.9 | C46: =B46-B45 -> -1
A47: 39692 | B47: 48.1 | C47: =B47-B46 -> -1.8 | D47: -0.003
A48: 39722 | B48: 43.3 | C48: =B48-B47 -> -4.8
A49: 39753 | B49: 36.7 | C49: =B49-B48 -> -6.6
A50: 39783 | B50: 33.5 | C50: =B50-B49 -> -3.2 | D50: -0.024
A51: 39814 | B51: 32 | C51: =B51-B50 -> -1.5
A52: 39845 | B52: 32.2 | C52: =B52-B51 -> 0.2
A53: 39873 | B53: 32.4 | C53: =B53-B52 -> 0.2 | D53: -0.037
A54: 39904 | B54: 35 | C54: =B54-B53 -> 2.6
A55: 39934 | B55: 39.6 | C55: =B55-B54 -> 4.6 | J55: 0.015
A56: 39965 | B56: 40.9 | C56: =B56-B55 -> 1.3 | D56: 0.005 | J56: -0.005
A57: 39995 | B57: 45.2 | C57: =B57-B56 -> 4.3 | J57: -0.005
A58: 40026 | B58: 49 | C58: =B58-B57 -> 3.8 | J58: -0.021
A59: 40057 | B59: 49.6 | C59: =B59-B58 -> 0.6 | D59: 0.008 | J59: -0.038
A60: 40087 | B60: 51.1 | C60: =B60-B59 -> 1.5 | J60: 0.003
A61: 40118 | B61: 52.4 | C61: =B61-B60 -> 1.3 | J61: 0.007
A62: 40148 | B62: 53.1 | C62: =B62-B61 -> 0.7 | D62: 0.005 | J62: 0
A63: 40179 | B63: 53.4 | C63: =B63-B62 -> 0.3 | J63: 0.002
A64: 40210 | B64: 57.2 | C64: =B64-B63 -> 3.8 | J64: 0.022
A65: 40238 | B65: 59.6 | C65: =B65-B64 -> 2.4 | D65: 0.005 | J65: 0.007
A66: 40269 | B66: 61.5 | C66: =B66-B65 -> 1.9 | J66: 0.004
A67: 40299 | B67: 58.4 | C67: =B67-B66 -> -3.1 | J67: 0.015
A68: 40330 | B68: 58.1 | C68: =B68-B67 -> -0.3 | D68: 0.021 | J68: 0.001
A69: 40360 | B69: 61.2 | C69: =B69-B68 -> 3.1 | J69: 0.005
A70: 40391 | B70: 58.2 | C70: =B70-B69 -> -3 | J70: -0.002
A71: 40422 | B71: 55.3 | C71: =B71-B70 -> -2.9 | D71: 0.008 | J71: 0.005
A72: 40452 | B72: 56.6 | C72: =B72-B71 -> 1.3 | J72: 0.003
A73: 40483 | B73: 58.1 | C73: =B73-B72 -> 1.5 | J73: 0.002
A74: 40513 | B74: 60.9 | C74: =B74-B73 -> 2.8 | D74: =J66 -> 0.004 | J74: -0.006
A75: 40544 | B75: 60.5 | C75: =B75-B74 -> -0.4 | J75: 0.001
A76: 40575 | B76: 62.7 | C76: =B76-B75 -> 2.2 | J76: 0.007
A77: 40603 | B77: 60.9 | C77: =B77-B76 -> -1.8 | D77: =J67 -> 0.015 | J77: 0.003
...

Sheet FR
A45: Date | B45: France PMI | C45: Change | D45: French GDP q/q | E45: ESI
A46: 39661 | B46: 45.1
A47: 39692 | B47: 43.6 | C47: =B47-B46 -> -1.5 | D47: -0.004
A48: 39722 | B48: 40.8 | C48: =B48-B47 -> -2.8
A49: 39753 | B49: 37.9 | C49: =B49-B48 -> -2.9
A50: 39783 | B50: 35.9 | C50: =B50-B49 -> -2 | D50: -0.016
A51: 39814 | B51: 38.1 | C51: =B51-B50 -> 2.2
A52: 39845 | B52: 32.3 | C52: =B52-B51 -> -5.8
A53: 39873 | B53: 36.3 | C53: =B53-B52 -> 4 | D53: -0.017
A54: 39904 | B54: 40 | C54: =B54-B53 -> 3.7
A55: 39934 | B55: 43.1 | C55: =B55-B54 -> 3.1
A56: 39965 | B56: 45.9 | C56: =B56-B55 -> 2.8 | D56: 0 | I56: 0.001
A57: 39995 | B57: 50.2 | C57: =B57-B56 -> 4.3 | I57: -0.012
A58: 40026 | B58: 52.5 | C58: =B58-B57 -> 2.3 | I58: -0.012
A59: 40057 | B59: 53 | C59: =B59-B58 -> 0.5 | D59: 0.001 | I59: 0.003
A60: 40087 | B60: 54.2 | C60: =B60-B59 -> 1.2 | I60: 0.003
A61: 40118 | B61: 54.4 | C61: =B61-B60 -> 0.2 | I61: 0.006
A62: 40148 | B62: 54.7 | C62: =B62-B61 -> 0.3 | D62: 0.007 | I62: 0.001
A63: 40179 | B63: 54.6 | C63: =B63-B62 -> -0.1 | I63: 0.006
A64: 40210 | B64: 56.3 | C64: =B64-B63 -> 1.7 | I64: 0.004
A65: 40238 | B65: 56.7 | C65: =B65-B64 -> 0.4 | D65: 0.003 | I65: 0.003
A66: 40269 | B66: 56.6 | C66: =B66-B65 -> -0.1 | I66: 0.01
A67: 40299 | B67: 55.8 | C67: =B67-B66 -> -0.8 | I67: 0
A68: 40330 | B68: 53.7 | C68: =B68-B67 -> -2.1 | D68: 0.006 | I68: 0.004
A69: 40360 | B69: 54.7 | C69: =B69-B68 -> 1 | I69: 0.002
A70: 40391 | B70: 55.4 | C70: =B70-B69 -> 0.7 | I70: 0
A71: 40422 | B71: 55.2 | C71: =B71-B70 -> -0.2 | D71: 0.005 | I71: 0
A72: 40452 | B72: 57.5 | C72: =B72-B71 -> 2.3 | I72: 0.002
A73: 40483 | B73: 56.3 | C73: =B73-B72 -> -1.2 | I73: -0.003
A74: 40513 | B74: 54.3 | C74: =B74-B73 -> -2 | D74: 0.005 | I74: -0.002
A75: 40544 | B75: 54.9 | C75: =B75-B74 -> 0.6 | E75: 110 | I75: 0.005
A76: 40575 | B76: 56.6 | C76: =B76-B75 -> 1.7 | E76: 110.6 | I76: -0.001
A77: 40603 | B77: 56.9 | C77: =B77-B76 -> 0.3 | D77: 0.011 | E77: 109.8
A78: 40634 | B78: 57.5 | C78: =B78-B77 -> 0.6 | E78: 107.9
A79: 40664 | B79: 54.9 | C79: =B79-B78 -> -2.6 | E79: 107.7
A80: 40695 | B80: 50.1 | C80: =B80-B79 -> -4.8 | D80: -0.001 | E80: 106.2
A81: 40725 | B81: 50.5 | C81: =B81-B80 -> 0.4 | E81: 100.2
A82: 40756 | B82: 49.1 | C82: =B82-B81 -> -1.4 | E82: 98.4
A83: 40787 | B83: 48.2 | C83: =B83-B82 -> -0.9 | D83: 0.003 | E83: 96.7
A84: 40817 | B84: 48.5 | C84: =B84-B83 -> 0.3 | E84: 97
...

Sheet IT
A25: Date | B25: Italy PMI | C25: Change | D25: Italy GDP q/q | E25: Column1
A26: 39052 | B26: 55 | D26: 0.011
A27: 39083 | B27: 53.5 | C27: =B27-B26 -> -1.5
A28: 39114 | B28: 54.2 | C28: =B28-B27 -> 0.7
A29: 39142 | B29: 53.8 | C29: =B29-B28 -> -0.4 | D29: 0
A30: 39173 | B30: 53.9 | C30: =B30-B29 -> 0.1
A31: 39203 | B31: 55 | C31: =B31-B30 -> 1.1
A32: 39234 | B32: 54 | C32: =B32-B31 -> -1 | D32: 0.002
A33: 39264 | B33: 53.3 | C33: =B33-B32 -> -0.7
A34: 39295 | B34: 53.6 | C34: =B34-B33 -> 0.3
A35: 39326 | B35: 52.4 | C35: =B35-B34 -> -1.2 | D35: 0.003
A36: 39356 | B36: 51.3 | C36: =B36-B35 -> -1.1
A37: 39387 | B37: 51.3 | C37: =B37-B36 -> 0
A38: 39417 | B38: 50.7 | C38: =B38-B37 -> -0.6 | D38: -0.004
A39: 39448 | B39: 50.8 | C39: =B39-B38 -> 0.1
A40: 39479 | B40: 50.6 | C40: =B40-B39 -> -0.2
A41: 39508 | B41: 49.4 | C41: =B41-B40 -> -1.2 | D41: 0.004
A42: 39539 | B42: 48.2 | C42: =B42-B41 -> -1.2
A43: 39569 | B43: 48 | C43: =B43-B42 -> -0.2
A44: 39600 | B44: 46.9 | C44: =B44-B43 -> -1.1 | D44: -0.005
A45: 39630 | B45: 45.3 | C45: =B45-B44 -> -1.6
A46: 39661 | B46: 47.1 | C46: =B46-B45 -> 1.8
A47: 39692 | B47: 44.4 | C47: =B47-B46 -> -2.7 | D47: -0.011
A48: 39722 | B48: 39.7 | C48: =B48-B47 -> -4.7
A49: 39753 | B49: 34.9 | C49: =B49-B48 -> -4.8
A50: 39783 | B50: 35.5 | C50: =B50-B49 -> 0.6 | D50: -0.019
A51: 39814 | B51: 36.1 | C51: =B51-B50 -> 0.6
