Workbook

Sheet Countries
A1: TBR - To be released
B4: Country Name | C4: % World GDP | D4: GDP y/y | E4: GDP q/q | F4: Key Rate | G4: Inflation | H4: Service PMI | I4: Summary | M4: Country Name | N4: % World GDP | O4: Nov | P4: Oct | Q4: Change | R4: Trend | S4: Summary
B5: United States | C5: =VLOOKUP($B5,Data!$K$30:$V$250,COLUMN(C5)-1,FALSE)/SUM(Data!$L$30:$L$250) -> 0.19182681 | D5: =VLOOKUP($B5,Data!$K$30:$V$250,COLUMN(D5)-1,FALSE) -> 0.024 | E5: =((1+VLOOKUP($B5,Data!$K$30:$V$250,COLUMN(E5)-1,FALSE))^(1/4))-1 -> 0.0096105657 | F5: =VLOOKUP($B5,Data!$K$30:$V$250,COLUMN(F5)-1,FALSE) -> 0.0025 | G5: =VLOOKUP($B5,Data!$K$30:$V$250,COLUMN(G5)-1,FALSE) -> 0.017 | H5: =Tabs!F28 -> 50.7 | I5: =VLOOKUP(B5,$M$5:$S$18,7,FALSE) -> Growing, slower | M5: Ireland | N5: =VLOOKUP(M5,$B$5:$C$18,2,FALSE) -> 0.0024891812 | O5: =Tabs!AH28 -> TBR | P5: =Tabs!AH27 -> TBR | Q5: =O5-P5 -> #VALUE! | R5: 26 | S5: Growing, faster
B6: Euro Area | C6: =VLOOKUP(B6,Data!$K$30:$V$250,COLUMN(C6)-1,FALSE)/SUM(Data!$L$30:$L$250) -> 0.14558285 | D6: =VLOOKUP($B6,Data!$K$30:$V$250,COLUMN(D6)-1,FALSE) -> 0.008 | E6: =VLOOKUP($B6,Data!$K$30:$V$250,COLUMN(E6)-1,FALSE) -> 0.002 | F6: =VLOOKUP($B6,Data!$K$30:$V$250,COLUMN(F6)-1,FALSE) -> 0.0005 | G6: =VLOOKUP($B6,Data!$K$30:$V$250,COLUMN(G6)-1,FALSE) -> 0.003 | H6: =Tabs!N28 -> 47.7 | I6: =VLOOKUP(B6,$M$5:$S$18,7,FALSE) -> Growing, slower | M6: United Kingdom | N6: =VLOOKUP(M6,$B$5:$C$18,2,FALSE) -> 0.028796858 | O6: 48.7 | P6: 49.3 | Q6: =O6-P6 -> -0.6 | R6: 32 | S6: Growing, faster
B7: China | C7: =VLOOKUP(B7,Data!$K$30:$V$250,COLUMN(C7)-1,FALSE)/SUM(Data!$L$30:$L$250) -> 0.10550474 | D7: =VLOOKUP($B7,Data!$K$30:$V$250,COLUMN(D7)-1,FALSE) -> 0.073 | E7: =VLOOKUP($B7,Data!$K$30:$V$250,COLUMN(E7)-1,FALSE) -> 0.019 | F7: =VLOOKUP($B7,Data!$K$30:$V$250,COLUMN(F7)-1,FALSE) -> 0.056 | G7: =VLOOKUP($B7,Data!$K$30:$V$250,COLUMN(G7)-1,FALSE) -> 0.016 | H7: =Tabs!AX28 -> TBR | I7: =VLOOKUP(B7,$M$5:$S$18,7,FALSE) -> Growing, faster | M7: United States | N7: =VLOOKUP(M7,$B$5:$C$18,2,FALSE) -> 0.19182681 | O7: =Tabs!F28 -> 50.7 | P7: =Tabs!F27 -> 51 | Q7: =O7-P7 -> -0.3 | R7: 11 | S7: Growing, slower
B8: Japan | C8: =VLOOKUP(B8,Data!$K$30:$V$250,COLUMN(C8)-1,FALSE)/SUM(Data!$L$30:$L$250) -> 0.055960904 | D8: =VLOOKUP($B8,Data!$K$30:$V$250,COLUMN(D8)-1,FALSE) -> -0.012 | E8: =VLOOKUP($B8,Data!$K$30:$V$250,COLUMN(E8)-1,FALSE) -> -0.004 | F8: =VLOOKUP($B8,Data!$K$30:$V$250,COLUMN(F8)-1,FALSE) -> 0 | G8: =VLOOKUP($B8,Data!$K$30:$V$250,COLUMN(G8)-1,FALSE) -> 0.029 | H8: =Tabs!AP28 -> 50 | I8: =VLOOKUP(B8,$M$5:$S$18,7,FALSE) -> Growing, from Contracting | M8: China | N8: =VLOOKUP(M8,$B$5:$C$18,2,FALSE) -> 0.10550474 | O8: =Tabs!AX28 -> TBR | P8: =Tabs!AX27 -> TBR | Q8: =O8-P8 -> #VALUE! | R8: 34 | S8: Growing, faster
B9: Germany | C9: =VLOOKUP(B9,Data!$K$30:$V$250,COLUMN(C9)-1,FALSE)/SUM(Data!$L$30:$L$250) -> 0.041505384 | D9: =VLOOKUP($B9,Data!$K$30:$V$250,COLUMN(D9)-1,FALSE) -> 0.012 | E9: =VLOOKUP($B9,Data!$K$30:$V$250,COLUMN(E9)-1,FALSE) -> 0.001 | F9: =VLOOKUP($B9,Data!$K$30:$V$250,COLUMN(F9)-1,FALSE) -> 0.0005 | G9: =VLOOKUP($B9,Data!$K$30:$V$250,COLUMN(G9)-1,FALSE) -> 0.006 | H9: =Tabs!R28 -> TBR | I9: =VLOOKUP(B9,$M$5:$S$18,7,FALSE) -> Growing, slower | M9: Spain | N9: =VLOOKUP(M9,$B$5:$C$18,2,FALSE) -> 0.015506 | O9: =Tabs!AD28 -> TBR | P9: =Tabs!AD27 -> TBR | Q9: =O9-P9 -> #VALUE! | R9: 11 | S9: Growing, slower
B10: France | C10: =VLOOKUP(B10,Data!$K$30:$V$250,COLUMN(C10)-1,FALSE)/SUM(Data!$L$30:$L$250) -> 0.031228948 | D10: =VLOOKUP($B10,Data!$K$30:$V$250,COLUMN(D10)-1,FALSE) -> 0.004 | E10: =VLOOKUP($B10,Data!$K$30:$V$250,COLUMN(E10)-1,FALSE) -> 0.003 | F10: =VLOOKUP($B10,Data!$K$30:$V$250,COLUMN(F10)-1,FALSE) -> 0.0005 | G10: =VLOOKUP($B10,Data!$K$30:$V$250,COLUMN(G10)-1,FALSE) -> 0.005 | H10: =Tabs!V28 -> TBR | I10: =VLOOKUP(B10,$M$5:$S$18,7,FALSE) -> Contracting, faster | M10: India | N10: =VLOOKUP(M10,$B$5:$C$18,2,FALSE) -> 0.021432078 | O10: =Tabs!BB28 -> 59.8 | P10: =Tabs!BB27 -> TBR | Q10: =O10-P10 -> #VALUE! | R10: 6 | S10: Growing, faster
B11: United Kingdom | C11: =VLOOKUP(B11,Data!$K$30:$V$250,COLUMN(C11)-1,FALSE)/SUM(Data!$L$30:$L$250) -> 0.028796858 | D11: =VLOOKUP($B11,Data!$K$30:$V$250,COLUMN(D11)-1,FALSE) -> 0.03 | E11: =VLOOKUP($B11,Data!$K$30:$V$250,COLUMN(E11)-1,FALSE) -> 0.007 | F11: =VLOOKUP($B11,Data!$K$30:$V$250,COLUMN(F11)-1,FALSE) -> 0.005 | G11: =VLOOKUP($B11,Data!$K$30:$V$250,COLUMN(G11)-1,FALSE) -> 0.013 | H11: 48.7 | I11: =VLOOKUP(B11,$M$5:$S$18,7,FALSE) -> Growing, faster | M11: Germany | N11: =VLOOKUP(M11,$B$5:$C$18,2,FALSE) -> 0.041505384 | O11: =Tabs!R28 -> TBR | P11: =Tabs!R27 -> TBR | Q11: =O11-P11 -> #VALUE! | R11: 17 | S11: Growing, slower
B12: Brazil | C12: =VLOOKUP(B12,Data!$K$30:$V$250,COLUMN(C12)-1,FALSE)/SUM(Data!$L$30:$L$250) -> 0.025645417 | D12: =VLOOKUP($B12,Data!$K$30:$V$250,COLUMN(D12)-1,FALSE) -> -0.002 | E12: =VLOOKUP($B12,Data!$K$30:$V$250,COLUMN(E12)-1,FALSE) -> 0.001 | F12: =VLOOKUP($B12,Data!$K$30:$V$250,COLUMN(F12)-1,FALSE) -> 0.1175 | G12: =VLOOKUP($B12,Data!$K$30:$V$250,COLUMN(G12)-1,FALSE) -> 0.0659 | H12: =Tabs!AT28 -> 50.4 | I12: =VLOOKUP(B12,$M$5:$S$18,7,FALSE) -> Contracting, slower | M12: Italy | N12: =VLOOKUP(M12,$B$5:$C$18,2,FALSE) -> 0.023647221 | O12: =Tabs!Z28 -> TBR | P12: =Tabs!Z27 -> TBR | Q12: =O12-P12 -> #VALUE! | R12: 1 | S12: Growing, faster
B13: Russia | C13: =VLOOKUP(B13,Data!$K$30:$V$250,COLUMN(C13)-1,FALSE)/SUM(Data!$L$30:$L$250) -> 0.023944096 | D13: =VLOOKUP($B13,Data!$K$30:$V$250,COLUMN(D13)-1,FALSE) -> 0.007 | E13: =VLOOKUP($B13,Data!$K$30:$V$250,COLUMN(E13)-1,FALSE) -> 0.0025 | F13: =VLOOKUP($B13,Data!$K$30:$V$250,COLUMN(F13)-1,FALSE) -> 0.095 | G13: =VLOOKUP($B13,Data!$K$30:$V$250,COLUMN(G13)-1,FALSE) -> 0.083 | H13: =Tabs!BF28 -> 48.7 | I13: =VLOOKUP(B13,$M$5:$S$18,7,FALSE) -> Contracting, faster | M13: Euro Area | N13: =VLOOKUP(M13,$B$5:$C$18,2,FALSE) -> 0.14558285 | O13: =Tabs!N28 -> 47.7 | P13: =Tabs!N27 -> 47.6 | Q13: =O13-P13 -> 0.1 | R13: 14 | S13: Growing, slower
B14: Italy | C14: =VLOOKUP(B14,Data!$K$30:$V$250,COLUMN(C14)-1,FALSE)/SUM(Data!$L$30:$L$250) -> 0.023647221 | D14: =VLOOKUP($B14,Data!$K$30:$V$250,COLUMN(D14)-1,FALSE) -> -0.005 | E14: =VLOOKUP($B14,Data!$K$30:$V$250,COLUMN(E14)-1,FALSE) -> -0.001 | F14: =VLOOKUP($B14,Data!$K$30:$V$250,COLUMN(F14)-1,FALSE) -> 0.0005 | G14: =VLOOKUP($B14,Data!$K$30:$V$250,COLUMN(G14)-1,FALSE) -> 0.0019 | H14: =Tabs!Z28 -> TBR | I14: =VLOOKUP(B14,$M$5:$S$18,7,FALSE) -> Growing, faster | M14: Japan | N14: =VLOOKUP(M14,$B$5:$C$18,2,FALSE) -> 0.055960904 | O14: =Tabs!AP28 -> 50 | P14: =Tabs!AP27 -> TBR | Q14: =O14-P14 -> #VALUE! | R14: 1 | S14: Growing, from Contracting
B15: India | C15: =VLOOKUP(B15,Data!$K$30:$V$250,COLUMN(C15)-1,FALSE)/SUM(Data!$L$30:$L$250) -> 0.021432078 | D15: =VLOOKUP($B15,Data!$K$30:$V$250,COLUMN(D15)-1,FALSE) -> 0.053 | E15: =VLOOKUP($B15,Data!$K$30:$V$250,COLUMN(E15)-1,FALSE) -> 0.012 | F15: =VLOOKUP($B15,Data!$K$30:$V$250,COLUMN(F15)-1,FALSE) -> 0.08 | G15: =VLOOKUP($B15,Data!$K$30:$V$250,COLUMN(G15)-1,FALSE) -> 0.0552 | H15: =Tabs!BB28 -> 59.8 | I15: =VLOOKUP(B15,$M$5:$S$18,7,FALSE) -> Growing, faster | M15: Brazil | N15: =VLOOKUP(M15,$B$5:$C$18,2,FALSE) -> 0.025645417 | O15: =Tabs!AT28 -> 50.4 | P15: =Tabs!AT27 -> TBR | Q15: =O15-P15 -> #VALUE! | R15: 1 | S15: Contracting, slower
B16: Australia | C16: =VLOOKUP(B16,Data!$K$30:$V$250,COLUMN(C16)-1,FALSE)/SUM(Data!$L$30:$L$250) -> 0.017823908 | D16: =VLOOKUP($B16,Data!$K$30:$V$250,COLUMN(D16)-1,FALSE) -> 0.027 | E16: =VLOOKUP($B16,Data!$K$30:$V$250,COLUMN(E16)-1,FALSE) -> 0.003 | F16: =VLOOKUP($B16,Data!$K$30:$V$250,COLUMN(F16)-1,FALSE) -> 0.025 | G16: =VLOOKUP($B16,Data!$K$30:$V$250,COLUMN(G16)-1,FALSE) -> 0.023 | H16: =Tabs!AL28 -> TBR | I16: =VLOOKUP(B16,$M$5:$S$18,7,FALSE) -> Contracting, slower | M16: France | N16: =VLOOKUP(M16,$B$5:$C$18,2,FALSE) -> 0.031228948 | O16: =Tabs!V28 -> TBR | P16: =Tabs!V27 -> TBR | Q16: =O16-P16 -> #VALUE! | R16: 3 | S16: Contracting, faster
B17: Spain | C17: =VLOOKUP(B17,Data!$K$30:$V$250,COLUMN(C17)-1,FALSE)/SUM(Data!$L$30:$L$250) -> 0.015506 | D17: =VLOOKUP($B17,Data!$K$30:$V$250,COLUMN(D17)-1,FALSE) -> 0.016 | E17: =VLOOKUP($B17,Data!$K$30:$V$250,COLUMN(E17)-1,FALSE) -> 0.005 | F17: =VLOOKUP($B17,Data!$K$30:$V$250,COLUMN(F17)-1,FALSE) -> 0.0005 | G17: =VLOOKUP($B17,Data!$K$30:$V$250,COLUMN(G17)-1,FALSE) -> -0.004 | H17: =Tabs!AD28 -> TBR | I17: =VLOOKUP(B17,$M$5:$S$18,7,FALSE) -> Growing, slower | M17: Russia | N17: =VLOOKUP(M17,$B$5:$C$18,2,FALSE) -> 0.023944096 | O17: =Tabs!BF28 -> 48.7 | P17: =Tabs!BF27 -> TBR | Q17: =O17-P17 -> #VALUE! | R17: 1 | S17: Contracting, faster
B18: Ireland | C18: =VLOOKUP(B18,Data!$K$30:$V$250,COLUMN(C18)-1,FALSE)/SUM(Data!$L$30:$L$250) -> 0.0024891812 | D18: =VLOOKUP($B18,Data!$K$30:$V$250,COLUMN(D18)-1,FALSE) -> 0.077 | E18: =VLOOKUP($B18,Data!$K$30:$V$250,COLUMN(E18)-1,FALSE) -> 0.015 | F18: =VLOOKUP($B18,Data!$K$30:$V$250,COLUMN(F18)-1,FALSE) -> 0.0005 | G18: =VLOOKUP($B18,Data!$K$30:$V$250,COLUMN(G18)-1,FALSE) -> 0.002 | H18: =Tabs!AH28 -> TBR | I18: =VLOOKUP(B18,$M$5:$S$18,7,FALSE) -> Growing, faster | M18: Australia | N18: =VLOOKUP(M18,$B$5:$C$18,2,FALSE) -> 0.017823908 | O18: =Tabs!AL28 -> TBR | P18: =Tabs!AL27 -> TBR | Q18: =O18-P18 -> #VALUE! | R18: 7 | S18: Contracting, slower

Sheet Tabs
A3: Global | E3: US | I3: UK | M3: EZ | Q3: DE | U3: FR | Y3: IT | AC3: ES | AG3: IR | AK3: AU | AO3: JP | AS3: BR | AW3: CH | BA3: IN | BE3: RS
A4: Date | B4: Index | C4: Change | E4: Date | F4: Index | G4: Change | I4: Date | J4: Index | K4: Change | M4: Date | N4: Index | O4: Change | Q4: Date | R4: Index | S4: Change | U4: Date | V4: Index | W4: Change | Y4: Date | Z4: Index | AA4: Change | AC4: Date | AD4: Index | AE4: Change | AG4: Date | AH4: Index | AI4: Change | AK4: Date | AL4: Index | AM4: Change | AO4: Date | AP4: Index | AQ4: Change | AS4: Date | AT4: Index | AU4: Change | AW4: Date | AX4: Index | AY4: Change | BA4: Date | BB4: Index | BC4: Change | BE4: Date | BF4: Index | BG4: Change
A5: =Global!A67 -> 41244 | B5: =Global!B67 -> 54.8 | C5: =Global!C67 -> 0 | E5: =US!A68 -> 41244 | F5: =US!B68 -> No data | G5: =US!C68 -> 0 | I5: =UK!A67 -> 41244 | J5: =UK!B67 -> 50.2 | K5: =UK!C67 -> -0.4 | M5: =EZ!A67 -> 41244 | N5: =EZ!B67 -> 47.2 | O5: =EZ!C67 -> 0.5 | Q5: =DE!A67 -> 41244 | R5: =DE!B67 -> 55.7 | S5: =DE!C67 -> 6 | U5: =FR!A67 -> 41244 | V5: =FR!B67 -> 44.1 | W5: =FR!C67 -> -1.7 | Y5: =IT!A67 -> 41244 | Z5: =IT!B67 -> 43.1 | AA5: =IT!C67 -> -1.5 | AC5: =ES!A67 -> 41244 | AD5: =ES!B67 -> 44.1 | AE5: =ES!C67 -> 1.7 | AG5: =IR!A67 -> 41244 | AH5: =IR!B67 -> 56.5 | AI5: =IR!C67 -> 0.4 | AK5: =AU!A67 -> 41244 | AL5: =AU!B67 -> 46.3 | AM5: =AU!C67 -> -0.8 | AO5: =JP!A67 -> 41244 | AP5: =JP!B67 -> 50.1 | AQ5: =JP!C67 -> 1 | AS5: =BR!A67 -> 41244 | AT5: =BR!B67 -> 53.2 | AU5: =BR!C67 -> 0.7 | AW5: =CH!A67 -> 41244 | AX5: =CH!B67 -> 53.5 | AY5: =CH!C67 -> 1.4 | BA5: =IN!A67 -> 41244 | BB5: =IN!B67 -> 52.1 | BC5: =IN!C67 -> -1.7 | BE5: =RS!A67 -> 41244 | BF5: =RS!B67 -> 56.1 | BG5: =RS!C67 -> -1
A6: =Global!A68 -> 41275 | B6: =Global!B68 -> 53.6 | C6: =Global!C68 -> -1.2 | E6: =US!A69 -> 41275 | F6: =US!B69 -> No data | G6: =US!C69 -> 0 | I6: =UK!A68 -> 41275 | J6: =UK!B68 -> 51.5 | K6: =UK!C68 -> 1.3 | M6: =EZ!A68 -> 41275 | N6: =EZ!B68 -> 48.6 | O6: =EZ!C68 -> 1.4 | Q6: =DE!A68 -> 41275 | R6: =DE!B68 -> 54.7 | S6: =DE!C68 -> -1 | U6: =FR!A68 -> 41275 | V6: =FR!B68 -> 43.6 | W6: =FR!C68 -> -0.5 | Y6: =IT!A68 -> 41275 | Z6: =IT!B68 -> 43.9 | AA6: =IT!C68 -> 0.8 | AC6: =ES!A68 -> 41275 | AD6: =ES!B68 -> 47 | AE6: =ES!C68 -> 2.9 | AG6: =IR!A68 -> 41275 | AH6: =IR!B68 -> 56.8 | AI6: =IR!C68 -> 0.3 | AK6: =AU!A68 -> 41275 | AL6: =AU!B68 -> 45.4 | AM6: =AU!C68 -> -0.9 | AO6: =JP!A68 -> 41275 | AP6: =JP!B68 -> 50.4 | AQ6: =JP!C68 -> 0.3 | AS6: =BR!A68 -> 41275 | AT6: =BR!B68 -> 54.5 | AU6: =BR!C68 -> 1.3 | AW6: =CH!A68 -> 41275 | AX6: =CH!B68 -> 54 | AY6: =CH!C68 -> 0.5 | BA6: =IN!A68 -> 41275 | BB6: =IN!B68 -> 57.5 | BC6: =IN!C68 -> 5.4 | BE6: =RS!A68 -> 41275 | BF6: =RS!B68 -> 55.7 | BG6: =RS!C68 -> -0.4
A7: =Global!A69 -> 41306 | B7: =Global!B69 -> 53.2 | C7: =Global!C69 -> -0.4 | E7: =US!A70 -> 41306 | F7: =US!B70 -> No data | G7: =US!C70 -> 0 | I7: =UK!A69 -> 41306 | J7: =UK!B69 -> 51.8 | K7: =UK!C69 -> 0.3 | M7: =EZ!A69 -> 41306 | N7: =EZ!B69 -> 47.9 | O7: =EZ!C69 -> -0.7 | Q7: =DE!A69 -> 41306 | R7: =DE!B69 -> 50.9 | S7: =DE!C69 -> -3.8 | U7: =FR!A69 -> 41306 | V7: =FR!B69 -> 43.7 | W7: =FR!C69 -> 0.1 | Y7: =IT!A69 -> 41306 | Z7: =IT!B69 -> 43.6 | AA7: =IT!C69 -> -0.3 | AC7: =ES!A69 -> 41306 | AD7: =ES!B69 -> 44.7 | AE7: =ES!C69 -> -2.3 | AG7: =IR!A69 -> 41306 | AH7: =IR!B69 -> 53.6 | AI7: =IR!C69 -> -3.2 | AK7: =AU!A69 -> 41306 | AL7: =AU!B69 -> 48.5 | AM7: =AU!C69 -> 3.1 | AO7: =JP!A69 -> 41306 | AP7: =JP!B69 -> 51.3 | AQ7: =JP!C69 -> 0.9 | AS7: =BR!A69 -> 41306 | AT7: =BR!B69 -> 52.1 | AU7: =BR!C69 -> -2.4 | AW7: =CH!A69 -> 41306 | AX7: =CH!B69 -> 52.1 | AY7: =CH!C69 -> -1.9 | BA7: =IN!A69 -> 41306 | BB7: =IN!B69 -> 54.2 | BC7: =IN!C69 -> -3.3 | BE7: =RS!A69 -> 41306 | BF7: =RS!B69 -> 56.1 | BG7: =RS!C69 -> 0.4
A8: =Global!A70 -> 41334 | B8: =Global!B70 -> 53.4 | C8: =Global!C70 -> 0.2 | E8: =US!A71 -> 41334 | F8: =US!B71 -> No data | G8: =US!C71 -> 0 | I8: =UK!A70 -> 41334 | J8: =UK!B70 -> 52.4 | K8: =UK!C70 -> 0.6 | M8: =EZ!A70 -> 41334 | N8: =EZ!B70 -> 46.4 | O8: =EZ!C70 -> -1.5 | Q8: =DE!A70 -> 41334 | R8: =DE!B70 -> 49.6 | S8: =DE!C70 -> -1.3 | U8: =FR!A70 -> 41334 | V8: =FR!B70 -> 41.3 | W8: =FR!C70 -> -2.4 | Y8: =IT!A70 -> 41334 | Z8: =IT!B70 -> 45.5 | AA8: =IT!C70 -> 1.9 | AC8: =ES!A70 -> 41334 | AD8: =ES!B70 -> 45.3 | AE8: =ES!C70 -> 0.6 | AG8: =IR!A70 -> 41334 | AH8: =IR!B70 -> 52.3 | AI8: =IR!C70 -> -1.3 | AK8: =AU!A70 -> 41334 | AL8: =AU!B70 -> 49.6 | AM8: =AU!C70 -> 1.1 | AO8: =JP!A70 -> 41334 | AP8: =JP!B70 -> 53.4 | AQ8: =JP!C70 -> 2.1 | AS8: =BR!A70 -> 41334 | AT8: =BR!B70 -> 50.3 | AU8: =BR!C70 -> -1.8 | AW8: =CH!A70 -> 41334 | AX8: =CH!B70 -> 54.3 | AY8: =CH!C70 -> 2.2 | BA8: =IN!A70 -> 41334 | BB8: =IN!B70 -> 51.4 | BC8: =IN!C70 -> -2.8 | BE8: =RS!A70 -> 41334 | BF8: =RS!B70 -> 54.6 | BG8: =RS!C70 -> -1.5
A9: =Global!A71 -> 41365 | B9: =Global!B71 -> 52.1 | C9: =Global!C71 -> -1.3 | E9: =US!A72 -> 41365 | F9: =US!B72 -> No data | G9: =US!C72 -> 0 | I9: =UK!A71 -> 41365 | J9: =UK!B71 -> 52.9 | K9: =UK!C71 -> 0.5 | M9: =EZ!A71 -> 41365 | N9: =EZ!B71 -> 47 | O9: =EZ!C71 -> 0.6 | Q9: =DE!A71 -> 41365 | R9: =DE!B71 -> 49.7 | S9: =DE!C71 -> 0.1 | U9: =FR!A71 -> 41365 | V9: =FR!B71 -> 44.3 | W9: =FR!C71 -> 3 | Y9: =IT!A71 -> 41365 | Z9: =IT!B71 -> 47 | AA9: =IT!C71 -> 1.5 | AC9: =ES!A71 -> 41365 | AD9: =ES!B71 -> 44.4 | AE9: =ES!C71 -> -0.9 | AG9: =IR!A71 -> 41365 | AH9: =IR!B71 -> 55.2 | AI9: =IR!C71 -> 2.9 | AK9: =AU!A71 -> 41365 | AL9: =AU!B71 -> 44.1 | AM9: =AU!C71 -> -5.5 | AO9: =JP!A71 -> 41365 | AP9: =JP!B71 -> 52.5 | AQ9: =JP!C71 -> -0.9 | AS9: =BR!A71 -> 41365 | AT9: =BR!B71 -> 51 | AU9: =BR!C71 -> 0.7 | AW9: =CH!A71 -> 41365 | AX9: =CH!B71 -> 51.1 | AY9: =CH!C71 -> -3.2 | BA9: =IN!A71 -> 41365 | BB9: =IN!B71 -> 50.7 | BC9: =IN!C71 -> -0.7 | BE9: =RS!A71 -> 41365 | BF9: =RS!B71 -> 53 | BG9: =RS!C71 -> -1.6
A10: =Global!A72 -> 41395 | B10: =Global!B72 -> 53.7 | C10: =Global!C72 -> 1.6 | E10: =US!A73 -> 41395 | F10: =US!B73 -> No data | G10: =US!C73 -> 0 | I10: =UK!A72 -> 41395 | J10: =UK!B72 -> 54.9 | K10: =UK!C72 -> 2 | M10: =EZ!A72 -> 41395 | N10: =EZ!B72 -> 47.2 | O10: =EZ!C72 -> 0.2 | Q10: =DE!A72 -> 41395 | R10: =DE!B72 -> 50.4 | S10: =DE!C72 -> 0.7 | U10: =FR!A72 -> 41395 | V10: =FR!B72 -> 44.3 | W10: =FR!C72 -> 0 | Y10: =IT!A72 -> 41395 | Z10: =IT!B72 -> 46.5 | AA10: =IT!C72 -> -0.5 | AC10: =ES!A72 -> 41395 | AD10: =ES!B72 -> 47.3 | AE10: =ES!C72 -> 2.9 | AG10: =IR!A72 -> 41395 | AH10: =IR!B72 -> 52.7 | AI10: =IR!C72 -> -2.5 | AK10: =AU!A72 -> 41395 | AL10: =AU!B72 -> 40.6 | AM10: =AU!C72 -> -3.5 | AO10: =JP!A72 -> 41395 | AP10: =JP!B72 -> 54.8 | AQ10: =JP!C72 -> 2.3 | AS10: =BR!A72 -> 41395 | AT10: =BR!B72 -> 51 | AU10: =BR!C72 -> 0 | AW10: =CH!A72 -> 41395 | AX10: =CH!B72 -> 51.2 | AY10: =CH!C72 -> 0.1 | BA10: =IN!A72 -> 41395 | BB10: =IN!B72 -> 53.6 | BC10: =IN!C72 -> 2.9 | BE10: =RS!A72 -> 41395 | BF10: =RS!B72 -> 51.4 | BG10: =RS!C72 -> -1.6
A11: =Global!A73 -> 41426 | B11: =Global!B73 -> 51.3 | C11: =Global!C73 -> -2.4 | E11: =US!A74 -> 41426 | F11: =US!B74 -> No data | G11: =US!C74 -> 0 | I11: =UK!A73 -> 41426 | J11: =UK!B73 -> 56.9 | K11: =UK!C73 -> 2 | M11: =EZ!A73 -> 41426 | N11: =EZ!B73 -> 48.3 | O11: =EZ!C73 -> 1.1 | Q11: =DE!A73 -> 41426 | R11: =DE!B73 -> 51.3 | S11: =DE!C73 -> 0.9 | U11: =FR!A73 -> 41426 | V11: =FR!B73 -> 47.2 | W11: =FR!C73 -> 2.9 | Y11: =IT!A73 -> 41426 | Z11: =IT!B73 -> 45.8 | AA11: =IT!C73 -> -0.7 | AC11: =ES!A73 -> 41426 | AD11: =ES!B73 -> 47.8 | AE11: =ES!C73 -> 0.5 | AG11: =IR!A73 -> 41426 | AH11: =IR!B73 -> 61.6 | AI11: =IR!C73 -> 8.9 | AK11: =AU!A73 -> 41426 | AL11: =AU!B73 -> 41.5 | AM11: =AU!C73 -> 0.9 | AO11: =JP!A73 -> 41426 | AP11: =JP!B73 -> 52.1 | AQ11: =JP!C73 -> -2.7 | AS11: =BR!A73 -> 41426 | AT11: =BR!B73 -> 50.3 | AU11: =BR!C73 -> -0.7 | AW11: =CH!A73 -> 41426 | AX11: =CH!B73 -> 51.3 | AY11: =CH!C73 -> 0.1 | BA11: =IN!A73 -> 41426 | BB11: =IN!B73 -> 51.7 | BC11: =IN!C73 -> -1.9 | BE11: =RS!A73 -> 41426 | BF11: =RS!B73 -> 48.8 | BG11: =RS!C73 -> -2.6
A12: =Global!A74 -> 41456 | B12: =Global!B74 -> 54.9 | C12: =Global!C74 -> 3.6 | E12: =US!A75 -> 41456 | F12: =US!B75 -> No data | G12: =US!C75 -> 0 | I12: =UK!A74 -> 41456 | J12: =UK!B74 -> 60.2 | K12: =UK!C74 -> 3.3 | M12: =EZ!A74 -> 41456 | N12: =EZ!B74 -> 49.8 | O12: =EZ!C74 -> 1.5 | Q12: =DE!A74 -> 41456 | R12: =DE!B74 -> 52.8 | S12: =DE!C74 -> 1.5 | U12: =FR!A74 -> 41456 | V12: =FR!B74 -> 48.6 | W12: =FR!C74 -> 1.4 | Y12: =IT!A74 -> 41456 | Z12: =IT!B74 -> 48.7 | AA12: =IT!C74 -> 2.9 | AC12: =ES!A74 -> 41456 | AD12: =ES!B74 -> 48.5 | AE12: =ES!C74 -> 0.7 | AG12: =IR!A74 -> 41456 | AH12: =IR!B74 -> 59.6 | AI12: =IR!C74 -> -2 | AK12: =AU!A74 -> 41456 | AL12: =AU!B74 -> 39.4 | AM12: =AU!C74 -> -2.1 | AO12: =JP!A74 -> 41456 | AP12: =JP!B74 -> 50.6 | AQ12: =JP!C74 -> -1.5 | AS12: =BR!A74 -> 41456 | AT12: =BR!B74 -> 49.7 | AU12: =BR!C74 -> -0.6 | AW12: =CH!A74 -> 41456 | AX12: =CH!B74 -> 51.3 | AY12: =CH!C74 -> 0 | BA12: =IN!A74 -> 41456 | BB12: =IN!B74 -> 47.9 | BC12: =IN!C74 -> -3.8 | BE12: =RS!A74 -> 41456 | BF12: =RS!B74 -> 48.7 | BG12: =RS!C74 -> -0.1
A13: =Global!A75 -> 41487 | B13: =Global!B75 -> 56 | C13: =Global!C75 -> 1.1 | E13: =US!A76 -> 41487 | F13: =US!B76 -> No data | G13: =US!C76 -> 0 | I13: =UK!A75 -> 41487 | J13: =UK!B75 -> 60.5 | K13: =UK!C75 -> 0.3 | M13: =EZ!A75 -> 41487 | N13: =EZ!B75 -> 50.7 | O13: =EZ!C75 -> 0.9 | Q13: =DE!A75 -> 41487 | R13: =DE!B75 -> 53.7 | S13: =DE!C75 -> 0.9 | U13: =FR!A75 -> 41487 | V13: =FR!B75 -> 48.9 | W13: =FR!C75 -> 0.3 | Y13: =IT!A75 -> 41487 | Z13: =IT!B75 -> 48.8 | AA13: =IT!C75 -> 0.1 | AC13: =ES!A75 -> 41487 | AD13: =ES!B75 -> 50.5 | AE13: =ES!C75 -> 2 | AG13: =IR!A75 -> 41487 | AH13: =IR!B75 -> 57.2 | AI13: =IR!C75 -> -2.4 | AK13: =AU!A75 -> 41487 | AL13: =AU!B75 -> 39 | AM13: =AU!C75 -> -0.4 | AO13: =JP!A75 -> 41487 | AP13: =JP!B75 -> 51.2 | AQ13: =JP!C75 -> 0.6 | AS13: =BR!A75 -> 41487 | AT13: =BR!B75 -> 50.7 | AU13: =BR!C75 -> 1 | AW13: =CH!A75 -> 41487 | AX13: =CH!B75 -> 52.8 | AY13: =CH!C75 -> 1.5 | BA13: =IN!A75 -> 41487 | BB13: =IN!B75 -> 47.6 | BC13: =IN!C75 -> -0.3 | BE13: =RS!A75 -> 41487 | BF13: =RS!B75 -> 51.8 | BG13: =RS!C75 -> 3.1
A14: =Global!A76 -> 41518 | B14: =Global!B76 -> 53.6 | C14: =Global!C76 -> -2.4 | E14: =US!A77 -> 41518 | F14: =US!B77 -> No data | G14: =US!C77 -> 0 | I14: =UK!A76 -> 41518 | J14: =UK!B76 -> 60.3 | K14: =UK!C76 -> -0.2 | M14: =EZ!A76 -> 41518 | N14: =EZ!B76 -> 52.2 | O14: =EZ!C76 -> 1.5 | Q14: =DE!A76 -> 41518 | R14: =DE!B76 -> 52.9 | S14: =DE!C76 -> -0.8 | U14: =FR!A76 -> 41518 | V14: =FR!B76 -> 51 | W14: =FR!C76 -> 2.1 | Y14: =IT!A76 -> 41518 | Z14: =IT!B76 -> 52.7 | AA14: =IT!C76 -> 3.9 | AC14: =ES!A76 -> 41518 | AD14: =ES!B76 -> 49 | AE14: =ES!C76 -> -1.5 | AG14: =IR!A76 -> 41518 | AH14: =IR!B76 -> 56.8 | AI14: =IR!C76 -> -0.4 | AK14: =AU!A76 -> 41518 | AL14: =AU!B76 -> 47.1 | AM14: =AU!C76 -> 8.1 | AO14: =JP!A76 -> 41518 | AP14: =JP!B76 -> 53 | AQ14: =JP!C76 -> 1.8 | AS14: =BR!A76 -> 41518 | AT14: =BR!B76 -> 52.1 | AU14: =BR!C76 -> 1.4 | AW14: =CH!A76 -> 41518 | AX14: =CH!B76 -> 52.4 | AY14: =CH!C76 -> -0.4 | BA14: =IN!A76 -> 41518 | BB14: =IN!B76 -> 44.6 | BC14: =IN!C76 -> -3 | BE14: =RS!A76 -> 41518 | BF14: =RS!B76 -> 51.5 | BG14: =RS!C76 -> -0.3
A15: =Global!A77 -> 41548 | B15: =Global!B77 -> 51.8 | C15: =Global!C77 -> -1.8 | E15: =US!A78 -> 41548 | F15: =US!B78 -> 49.3 | G15: =US!C78 -> 0 | I15: =UK!A77 -> 41548 | J15: =UK!B77 -> 62.5 | K15: =UK!C77 -> 2.2 | M15: =EZ!A77 -> 41548 | N15: =EZ!B77 -> 51.6 | O15: =EZ!C77 -> -0.6 | Q15: =DE!A77 -> 41548 | R15: =DE!B77 -> 55.7 | S15: =DE!C77 -> 2.8 | U15: =FR!A77 -> 41548 | V15: =FR!B77 -> 50.9 | W15: =FR!C77 -> -0.1 | Y15: =IT!A77 -> 41548 | Z15: =IT!B77 -> 50.5 | AA15: =IT!C77 -> -2.2 | AC15: =ES!A77 -> 41548 | AD15: =ES!B77 -> 49.6 | AE15: =ES!C77 -> 0.6 | AG15: =IR!A77 -> 41548 | AH15: =IR!B77 -> 60.1 | AI15: =IR!C77 -> 3.3 | AK15: =AU!A77 -> 41548 | AL15: =AU!B77 -> 47.9 | AM15: =AU!C77 -> 0.8 | AO15: =JP!A77 -> 41548 | AP15: =JP!B77 -> 55.3 | AQ15: =JP!C77 -> 2.3 | AS15: =BR!A77 -> 41548 | AT15: =BR!B77 -> 52.3 | AU15: =BR!C77 -> 0.2 | AW15: =CH!A77 -> 41548 | AX15: =CH!B77 -> 52.6 | AY15: =CH!C77 -> 0.2 | BA15: =IN!A77 -> 41548 | BB15: =IN!B77 -> 47.1 | BC15: =IN!C77 -> 2.5 | BE15: =RS!A77 -> 41548 | BF15: =RS!B77 -> 52.5 | BG15: =RS!C77 -> 1
A16: =Global!A78 -> 41579 | B16: =Global!B78 -> 53.9 | C16: =Global!C78 -> 2.1 | E16: =US!A79 -> 41579 | F16: =US!B79 -> 55.9 | G16: =US!C79 -> 6.6 | I16: =UK!A78 -> 41579 | J16: =UK!B78 -> 60 | K16: =UK!C78 -> -2.5 | M16: =EZ!A78 -> 41579 | N16: =EZ!B78 -> 51.2 | O16: =EZ!C78 -> -0.4 | Q16: =DE!A78 -> 41579 | R16: =DE!B78 -> 53.5 | S16: =DE!C78 -> -2.2 | U16: =FR!A78 -> 41579 | V16: =FR!B78 -> 48 | W16: =FR!C78 -> -2.9 | Y16: =IT!A78 -> 41579 | Z16: =IT!B78 -> 47.2 | AA16: =IT!C78 -> -3.3 | AC16: =ES!A78 -> 41579 | AD16: =ES!B78 -> 51.5 | AE16: =ES!C78 -> 1.9 | AG16: =IR!A78 -> 41579 | AH16: =IR!B78 -> 57.1 | AI16: =IR!C78 -> -3 | AK16: =AU!A78 -> 41579 | AL16: =AU!B78 -> 48.9 | AM16: =AU!C78 -> 1 | AO16: =JP!A78 -> 41579 | AP16: =JP!B78 -> 51.8 | AQ16: =JP!C78 -> -3.5 | AS16: =BR!A78 -> 41579 | AT16: =BR!B78 -> 51.7 | AU16: =BR!C78 -> -0.6 | AW16: =CH!A78 -> 41579 | AX16: =CH!B78 -> 52.5 | AY16: =CH!C78 -> -0.1 | BA16: =IN!A78 -> 41579 | BB16: =IN!B78 -> 47.2 | BC16: =IN!C78 -> 0.1 | BE16: =RS!A78 -> 41579 | BF16: =RS!B78 -> 52.9 | BG16: =RS!C78 -> 0.4
... A26: =Global!A88 -> 41883 | B26: =Global!B88 -> 55.3 | C26: =Global!C88 -> -0.2 | E26: =US!A89 -> 41883 | F26: =US!B89 -> 58.9 | G26: =US!C89 -> -0.6 | I26: =UK!A88 -> 41883 | J26: =UK!B88 -> 58.7 | K26: =UK!C88 -> -1.8 | M26: =EZ!A88 -> 41883 | N26: =EZ!B88 -> 52.4 | O26: =EZ!C88 -> -0.7 | Q26: =DE!A88 -> 41883 | R26: =DE!B88 -> 55.7 | S26: =DE!C88 -> 0.8 | U26: =FR!A88 -> 41883 | V26: =FR!B88 -> 48.4 | W26: =FR!C88 -> -1.9 | Y26: =IT!A88 -> 41883 | Z26: =IT!B88 -> 48.8 | AA26: =IT!C88 -> -1 | AC26: =ES!A88 -> 41883 | AD26: =ES!B88 -> 55.8 | AE26: =ES!C88 -> -2.3 | AG26: =IR!A88 -> 41883 | AH26: =IR!B88 -> 62.5 | AI26: =IR!C88 -> 0.1 | AK26: =AU!A88 -> 41883 | AL26: =AU!B88 -> 45.5 | AM26: =AU!C88 -> -3.9 | AO26: =JP!A88 -> 41883 | AP26: =JP!B88 -> 52.5 | AQ26: =JP!C88 -> 2.6 | AS26: =BR!A88 -> 41883 | AT26: =BR!B88 -> 51.2 | AU26: =BR!C88 -> 2 | AW26: =CH!A88 -> 41883 | AX26: =CH!B88 -> 53.5 | AY26: =CH!C88 -> -0.6 | BA26: =IN!A88 -> 41883 | BB26: =IN!B88 -> 51.6 | BC26: =IN!C88 -> 1 | BE26: =RS!A88 -> 41883 | BF26: =RS!B88 -> 50.5 | BG26: =RS!C88 -> 0.2
A27: =Global!A227 -> 46113 | B27: =Global!B227 -> TBR | C27: =Global!C227 | E27: =US!A363 -> 46113 | F27: =US!B363 -> 51 | G27: =US!C363 -> -2.8 | I27: =UK!A226 -> 46113 | J27: =UK!B226 -> 52.7 | K27: =UK!C226 -> 2.2 | M27: =EZ!A227 -> 46113 | N27: =EZ!B227 -> 47.6 | O27: =EZ!C227 | Q27: =DE!A227 -> 46113 | R27: =DE!B227 -> TBR | S27: =DE!C227 | U27: =FR!A227 -> 46113 | V27: =FR!B227 -> TBR | W27: =FR!C227 | Y27: =IT!A227 -> 46113 | Z27: =IT!B227 -> TBR | AA27: =IT!C227 | AC27: =ES!A227 -> 46113 | AD27: =ES!B227 -> TBR | AE27: =ES!C227 | AG27: =IR!A227 -> 46113 | AH27: =IR!B227 -> TBR | AI27: =IR!C227 | AK27: =AU!A227 -> 46113 | AL27: =AU!B227 -> TBR | AM27: =AU!C227 | AO27: =JP!A227 -> 46113 | AP27: =JP!B227 -> TBR | AQ27: =JP!C227 | AS27: =BR!A227 -> 46113 | AT27: =BR!B227 -> TBR | AU27: =BR!C227 | AW27: =CH!A227 -> 46113 | AX27: =CH!B227 -> TBR | AY27: =CH!C227 | BA27: =IN!A227 -> 46113 | BB27: =IN!B227 -> TBR | BC27: =IN!C227 | BE27: =RS!A227 -> 46113 | BF27: =RS!B227 -> TBR | BG27: =RS!C227
A28: =Global!A228 -> 46143 | B28: =Global!B228 -> TBR | C28: =Global!C228 | E28: =US!A364 -> 46143 | F28: =US!B364 -> 50.7 | G28: =US!C364 -> -0.3 | I28: =UK!A227 -> 46143 | J28: =UK!B227 -> 49.3 | K28: =UK!C227 -> -3.4 | M28: =EZ!A228 -> 46143 | N28: =EZ!B228 -> 47.7 | O28: =EZ!C228 -> 0.1 | Q28: =DE!A228 -> 46143 | R28: =DE!B228 -> TBR | S28: =DE!C228 | U28: =FR!A228 -> 46143 | V28: =FR!B228 -> TBR | W28: =FR!C228 | Y28: =IT!A228 -> 46143 | Z28: =IT!B228 -> TBR | AA28: =IT!C228 | AC28: =ES!A228 -> 46143 | AD28: =ES!B228 -> TBR | AE28: =ES!C228 | AG28: =IR!A228 -> 46143 | AH28: =IR!B228 -> TBR | AI28: =IR!C228 | AK28: =AU!A228 -> 46143 | AL28: =AU!B228 -> TBR | AM28: =AU!C228 | AO28: =JP!A228 -> 46143 | AP28: =JP!B228 -> 50 | AQ28: =JP!C228 | AS28: =BR!A228 -> 46143 | AT28: =BR!B228 -> 50.4 | AU28: =BR!C228 | AW28: =CH!A228 -> 46143 | AX28: =CH!B228 -> TBR | AY28: =CH!C228 | BA28: =IN!A228 -> 46143 | BB28: =IN!B228 -> 59.8 | BC28: =IN!C228 | BE28: =RS!A228 -> 46143 | BF28: =RS!B228 -> 48.7 | BG28: =RS!C228

Sheet Global
A40: Date | B40: Global Service PMI | C40: Change
A41: 40452 | B41: 54.6
A42: 40483 | B42: 54.8 | C42: =B42-B41 -> 0.2
A43: 40513 | B43: 56.3 | C43: =B43-B42 -> 1.5
A44: 40544 | B44: 57.1 | C44: =B44-B43 -> 0.8
A45: 40575 | B45: 59.3 | C45: =B45-B44 -> 2.2
A46: 40603 | B46: 54 | C46: =B46-B45 -> -5.3
A47: 40634 | B47: 51 | C47: =B47-B46 -> -3
A48: 40664 | B48: 52.5 | C48: =B48-B47 -> 1.5
A49: 40695 | B49: 52.1 | C49: =B49-B48 -> -0.4
A50: 40725 | B50: 53.1 | C50: =B50-B49 -> 1
A51: 40756 | B51: 52.4 | C51: =B51-B50 -> -0.7
A52: 40787 | B52: 52.6 | C52: =B52-B51 -> 0.2
A53: 40817 | B53: 51.8 | C53: =B53-B52 -> -0.8
... A90: 41944 | B90: 53.5 | C90: =B90-B89 -> -0.2
A91: 41974 | B91: TBR | C91: =IFERROR(B91-B90,"")
A92: 42005 | B92: TBR | C92: =IFERROR(B92-B91,"")
A93: 42036 | B93: TBR | C93: =IFERROR(B93-B92,"")
A94: 42064 | B94: TBR | C94: =IFERROR(B94-B93,"")
A95: 42095 | B95: TBR | C95: =IFERROR(B95-B94,"")
A96: 42125 | B96: TBR | C96: =IFERROR(B96-B95,"")
A97: 42156 | B97: TBR | C97: =IFERROR(B97-B96,"")
A98: 42186 | B98: TBR | C98: =IFERROR(B98-B97,"")
A99: 42217 | B99: TBR | C99: =IFERROR(B99-B98,"")
A100: 42248 | B100: TBR | C100: =IFERROR(B100-B99,"")
A101: 42278 | B101: TBR | C101: =IFERROR(B101-B100,"")
A102: 42309 | B102: TBR | C102: =IFERROR(B102-B101,"")
... A228: 46143 | B228: TBR | C228: =IFERROR(B228-B227,"")

Sheet US
A1: Date | B1: US Service PMI | C1: Change | D1: US GDP q/q
A41: Column1 | B41: Column2 | C41: Column3 | D41: Column4
A42: 40452 | B42: 54.3
A43: 40483 | B43: 55 | C43: =B43-B42 -> 0.7
A44: 40513 | C44: =B44-B43 -> -55
A45: 40544 | C45: =B45-B44 -> 0
A46: 40575 | B46: 59.7 | C46: =B46-B45 -> 59.7
A47: 40603 | B47: 57.3 | C47: =B47-B46 -> -2.4
A48: 40634 | B48: 52.8 | C48: =B48-B47 -> -4.5
A49: 40664 | B49: 53.6 | C49: =B49-B48 -> 0.8
A50: 40695 | B50: 53.3 | C50: =B50-B49 -> -0.3
A51: 40725 | B51: 52.7 | C51: =B51-B50 -> -0.6
A52: 40756 | C52: =B52-B51 -> -52.7
A53: 40787 | B53: 53 | C53: =B53-B52 -> 53
A54: 40817 | B54: 52.9 | C54: =B54-B53 -> -0.1
A55: 40848 | B55: 52 | C55: =B55-B54 -> -0.9
A56: 40878 | B56: 52.6 | C56: =B56-B55 -> 0.6
A57: 40909 | C57: =B57-B56 -> -52.6
A58: 40940 | C58: =B58-B57 -> 0
A59: 40969 | C59: =B59-B58 -> 0
A60: 41000 | C60: =B60-B59 -> 0
A61: 41030 | C61: =B61-B60 -> 0
A62: 41061 | B62: No data | C62: 0
A63: 41091 | B63: No data | C63: 0
A64: 41122 | B64: No data | C64: 0
A65: 41153 | B65: No data | C65: 0
A66: 41183 | B66: No data | C66: 0
A67: 41214 | B67: No data | C67: 0
A68: 41244 | B68: No data | C68: 0
A69: 41275 | B69: No data | C69: 0
A70: 41306 | B70: No data | C70: 0
A71: 41334 | B71: No data | C71: 0
A72: 41365 | B72: No data | C72: 0
A73: 41395 | B73: No data | C73: 0
... A77: 41518 | B77: No data | C77: 0
A78: 41548 | B78: 49.3 | C78: 0
A79: 41579 | B79: 55.9 | C79: =B79-B78 -> 6.6
A80: 41609 | B80: 55.7 | C80: =B80-B79 -> -0.2 | D80: 0.0065
A81: 41640 | B81: 56.7 | C81: =B81-B80 -> 1
A82: 41671 | B82: 53.3 | C82: =B82-B81 -> -3.4
...

Sheet UK
A40: Date | B40: UK Service PMI | C40: Change | D40: UK GDP Growth q/q
A41: 40452 | B41: 53.2 | C41: =IF(AND(ISNUMBER(B41),ISNUMBER(B40)),B41-B40,"")
A42: 40483 | B42: 53 | C42: =IF(AND(ISNUMBER(B42),ISNUMBER(B41)),B42-B41,"") -> -0.2
A43: 40513 | B43: 53.9 | C43: =IF(AND(ISNUMBER(B43),ISNUMBER(B42)),B43-B42,"") -> 0.9 | D43: -0.002
A44: 40544 | B44: 54.5 | C44: =IF(AND(ISNUMBER(B44),ISNUMBER(B43)),B44-B43,"") -> 0.6
A45: 40575 | B45: 52.6 | C45: =IF(AND(ISNUMBER(B45),ISNUMBER(B44)),B45-B44,"") -> -1.9
A46: 40603 | B46: 57.1 | C46: =IF(AND(ISNUMBER(B46),ISNUMBER(B45)),B46-B45,"") -> 4.5 | D46: 0.005
A47: 40634 | B47: 54.3 | C47: =IF(AND(ISNUMBER(B47),ISNUMBER(B46)),B47-B46,"") -> -2.8
A48: 40664 | B48: 53.8 | C48: =IF(AND(ISNUMBER(B48),ISNUMBER(B47)),B48-B47,"") -> -0.5
A49: 40695 | B49: 53.9 | C49: =IF(AND(ISNUMBER(B49),ISNUMBER(B48)),B49-B48,"") -> 0.1 | D49: 0.001
A50: 40725 | B50: 55.4 | C50: =IF(AND(ISNUMBER(B50),ISNUMBER(B49)),B50-B49,"") -> 1.5
A51: 40756 | B51: 51.1 | C51: =IF(AND(ISNUMBER(B51),ISNUMBER(B50)),B51-B50,"") -> -4.3
A52: 40787 | B52: 52.9 | C52: =IF(AND(ISNUMBER(B52),ISNUMBER(B51)),B52-B51,"") -> 1.8 | D52: 0.006
A53: 40817 | B53: 51.3 | C53: =IF(AND(ISNUMBER(B53),ISNUMBER(B52)),B53-B52,"") -> -1.6
A54: 40848 | B54: 52.1 | C54: =IF(AND(ISNUMBER(B54),ISNUMBER(B53)),B54-B53,"") -> 0.8
A55: 40878 | B55: 54 | C55: =IF(AND(ISNUMBER(B55),ISNUMBER(B54)),B55-B54,"") -> 1.9 | D55: -0.001
A56: 40909 | B56: 56 | C56: =IF(AND(ISNUMBER(B56),ISNUMBER(B55)),B56-B55,"") -> 2
A57: 40940 | B57: 53.8 | C57: =IF(AND(ISNUMBER(B57),ISNUMBER(B56)),B57-B56,"") -> -2.2
A58: 40969 | B58: 55.3 | C58: =IF(AND(ISNUMBER(B58),ISNUMBER(B57)),B58-B57,"") -> 1.5 | D58: 0
A59: 41000 | B59: 53.3 | C59: =IF(AND(ISNUMBER(B59),ISNUMBER(B58)),B59-B58,"") -> -2
A60: 41030 | B60: 53.3 | C60: =IF(AND(ISNUMBER(B60),ISNUMBER(B59)),B60-B59,"") -> 0
A61: 41061 | B61: 51.3 | C61: =IF(AND(ISNUMBER(B61),ISNUMBER(B60)),B61-B60,"") -> -2 | D61: -0.004
A62: 41091 | B62: 51.3 | C62: =IF(AND(ISNUMBER(B62),ISNUMBER(B61)),B62-B61,"") -> 0
A63: 41122 | B63: 51 | C63: =IF(AND(ISNUMBER(B63),ISNUMBER(B62)),B63-B62,"") -> -0.3
A64: 41153 | B64: 53.7 | C64: =IF(AND(ISNUMBER(B64),ISNUMBER(B63)),B64-B63,"") -> 2.7 | D64: 0.008
A65: 41183 | B65: 52.2 | C65: =IF(AND(ISNUMBER(B65),ISNUMBER(B64)),B65-B64,"") -> -1.5
A66: 41214 | B66: 50.6 | C66: =IF(AND(ISNUMBER(B66),ISNUMBER(B65)),B66-B65,"") -> -1.6
A67: 41244 | B67: 50.2 | C67: =IF(AND(ISNUMBER(B67),ISNUMBER(B66)),B67-B66,"") -> -0.4 | D67: -0.001
A68: 41275 | B68: 51.5 | C68: =IF(AND(ISNUMBER(B68),ISNUMBER(B67)),B68-B67,"") -> 1.3
A69: 41306 | B69: 51.8 | C69: =IF(AND(ISNUMBER(B69),ISNUMBER(B68)),B69-B68,"") -> 0.3
A70: 41334 | B70: 52.4 | C70: =IF(AND(ISNUMBER(B70),ISNUMBER(B69)),B70-B69,"") -> 0.6 | D70: 0.005
A71: 41365 | B71: 52.9 | C71: =IF(AND(ISNUMBER(B71),ISNUMBER(B70)),B71-B70,"") -> 0.5
A72: 41395 | B72: 54.9 | C72: =IF(AND(ISNUMBER(B72),ISNUMBER(B71)),B72-B71,"") -> 2
A73: 41426 | B73: 56.9 | C73: =IF(AND(ISNUMBER(B73),ISNUMBER(B72)),B73-B72,"") -> 2 | D73: 0.008
A74: 41456 | B74: 60.2 | C74: =IF(AND(ISNUMBER(B74),ISNUMBER(B73)),B74-B73,"") -> 3.3
A75: 41487 | B75: 60.5 | C75: =IF(AND(ISNUMBER(B75),ISNUMBER(B74)),B75-B74,"") -> 0.3
A76: 41518 | B76: 60.3 | C76: =IF(AND(ISNUMBER(B76),ISNUMBER(B75)),B76-B75,"") -> -0.2 | D76: 0.008
A77: 41548 | B77: 62.5 | C77: =IF(AND(ISNUMBER(B77),ISNUMBER(B76)),B77-B76,"") -> 2.2
A78: 41579 | B78: 60 | C78: =IF(AND(ISNUMBER(B78),ISNUMBER(B77)),B78-B77,"") -> -2.5
A79: 41609 | B79: 58.8 | C79: =IF(AND(ISNUMBER(B79),ISNUMBER(B78)),B79-B78,"") -> -1.2 | D79: 0.007
...

Sheet EZ
A1: Date | B1: Euro-Zone Service PMI | C1: Change | D1: Euro Zone GDP q/q %
A2: 39264 | B2: 58.3
A3: 39295 | B3: 58 | C3: =B3-B2 -> -0.3
A4: 39326 | B4: 54.2 | C4: =B4-B3 -> -3.8 | D4: 0.006
A5: 39356 | B5: 55.8 | C5: =B5-B4 -> 1.6
A6: 39387 | B6: 54.1 | C6: =B6-B5 -> -1.7
A7: 39417 | B7: 53.1 | C7: =B7-B6 -> -1 | D7: 0.004
A8: 39448 | B8: 50.6 | C8: =B8-B7 -> -2.5
A9: 39479 | B9: 51.7 | C9: =B9-B8 -> 1.1
A10: 39508 | B10: 51.6 | C10: =B10-B9 -> -0.1 | D10: 0.006
A11: 39539 | B11: 52 | C11: =B11-B10 -> 0.4
A12: 39569 | B12: 50.6 | C12: =B12-B11 -> -1.4
A13: 39600 | B13: 49.1 | C13: =B13-B12 -> -1.5 | D13: -0.004
A14: 39630 | B14: 48.3 | C14: =B14-B13 -> -0.8
A15: 39661 | B15: 48.5 | C15: =B15-B14 -> 0.2
A16: 39692 | B16: 48.4 | C16: =B16-B15 -> -0.1 | D16: -0.006
A17: 39722 | B17: 45.8 | C17: =B17-B16 -> -2.6
A18: 39753 | B18: 42.5 | C18: =B18-B17 -> -3.3
A19: 39783 | B19: 42.3 | C19: =B19-B18 -> -0.2 | D19: -0.017
A20: 39814 | B20: 42.2 | C20: =B20-B19 -> -0.1
A21: 39845 | B21: 39.2 | C21: =B21-B20 -> -3
A22: 39873 | B22: 40.9 | C22: =B22-B21 -> 1.7 | D22: -0.028
A23: 39904 | B23: 43.8 | C23: =B23-B22 -> 2.9
A24: 39934 | B24: 44.8 | C24: =B24-B23 -> 1
A25: 39965 | B25: 44.7 | C25: =B25-B24 -> -0.1 | D25: -0.003
A26: 39995 | B26: 45.7 | C26: =B26-B25 -> 1
A27: 40026 | B27: 49.9 | C27: =B27-B26 -> 4.2
A28: 40057 | B28: 50.9 | C28: =B28-B27 -> 1 | D28: 0.004
A29: 40087 | B29: 52.6 | C29: =B29-B28 -> 1.7
A30: 40118 | B30: 53 | C30: =B30-B29 -> 0.4
A31: 40148 | B31: 52.9 | C31: =B31-B30 -> -0.1 | D31: 0.005
A32: 40179 | B32: 52.5 | C32: =B32-B31 -> -0.4
A33: 40210 | B33: 51.8 | C33: =B33-B32 -> -0.7
A34: 40238 | B34: 54.1 | C34: =B34-B33 -> 2.3 | D34: 0.004
A35: 40269 | B35: 55.6 | C35: =B35-B34 -> 1.5
A36: 40299 | B36: 56.2 | C36: =B36-B35 -> 0.6
A37: 40330 | B37: 55.5 | C37: =B37-B36 -> -0.7 | D37: 0.009
A38: 40360 | B38: 55.8 | C38: =B38-B37 -> 0.3
A39: 40391 | B39: 55.9 | C39: =B39-B38 -> 0.1
A40: 40422 | B40: 54.1 | C40: =B40-B39 -> -1.8 | D40: 0.004
...

Sheet DE
A1: Date | B1: Germany Service PMI | C1: Change | D1: Germany GDP q/q
A2: 39264 | B2: 58.9
A3: 39295 | B3: 59.8 | C3: =B3-B2 -> 0.9
A4: 39326 | B4: 53.1 | C4: =B4-B3 -> -6.7 | D4: 0.008
A5: 39356 | B5: 55.1 | C5: =B5-B4 -> 2
A6: 39387 | B6: 53.1 | C6: =B6-B5 -> -2
A7: 39417 | B7: 51.5 | C7: =B7-B6 -> -1.6 | D7: 0.001
A8: 39448 | B8: 49.2 | C8: =B8-B7 -> -2.3
A9: 39479 | B9: 52.2 | C9: =B9-B8 -> 3
A10: 39508 | B10: 51.8 | C10: =B10-B9 -> -0.4 | D10: 0.016
A11: 39539 | B11: 54.9 | C11: =B11-B10 -> 3.1
A12: 39569 | B12: 53.8 | C12: =B12-B11 -> -1.1
A13: 39600 | B13: 52.1 | C13: =B13-B12 -> -1.7 | D13: -0.006
A14: 39630 | B14: 53.1 | C14: =B14-B13 -> 1
A15: 39661 | B15: 51.4 | C15: =B15-B14 -> -1.7
A16: 39692 | B16: 50.2 | C16: =B16-B15 -> -1.2 | D16: -0.003
A17: 39722 | B17: 48.3 | C17: =B17-B16 -> -1.9
A18: 39753 | B18: 45.1 | C18: =B18-B17 -> -3.2
A19: 39783 | B19: 43.1 | C19: =B19-B18 -> -2 | D19: -0.024
A20: 39814 | B20: 45.2 | C20: =B20-B19 -> 2.1
A21: 39845 | B21: 41.3 | C21: =B21-B20 -> -3.9
A22: 39873 | B22: 42.3 | C22: =B22-B21 -> 1 | D22: -0.037
A23: 39904 | B23: 43.8 | C23: =B23-B22 -> 1.5
A24: 39934 | B24: 45.2 | C24: =B24-B23 -> 1.4
A25: 39965 | B25: 45.2 | C25: =B25-B24 -> 0 | D25: 0.005
A26: 39995 | B26: 48.1 | C26: =B26-B25 -> 2.9
A27: 40026 | B27: 53.8 | C27: =B27-B26 -> 5.7
A28: 40057 | B28: 52.2 | C28: =B28-B27 -> -1.6 | D28: 0.008
A29: 40087 | B29: 50.7 | C29: =B29-B28 -> -1.5
A30: 40118 | B30: 51.4 | C30: =B30-B29 -> 0.7
A31: 40148 | B31: 52.1 | C31: =B31-B30 -> 0.7 | D31: 0.005
A32: 40179 | B32: 52.2 | C32: =B32-B31 -> 0.1
A33: 40210 | B33: 51.9 | C33: =B33-B32 -> -0.3
A34: 40238 | B34: 54.9 | C34: =B34-B33 -> 3 | D34: 0.005
A35: 40269 | B35: 53.7 | C35: =B35-B34 -> -1.2
A36: 40299 | B36: 54.8 | C36: =B36-B35 -> 1.1
A37: 40330 | B37: 54.8 | C37: =B37-B36 -> 0 | D37: 0.021
A38: 40360 | B38: 56.5 | C38: =B38-B37 -> 1.7
A39: 40391 | B39: 57.2 | C39: =B39-B38 -> 0.7
A40: 40422 | B40: 54.9 | C40: =B40-B39 -> -2.3 | D40: 0.008
...

Sheet FR
A14: Date | B14: France Service PMI | C14: Change | D14: French GDP q/q
A15: 39661 | B15: 48
A16: 39692 | B16: 50.1 | C16: =B16-B15 -> 2.1 | D16: -0.004
A17: 39722 | B17: 47.5 | C17: =B17-B16 -> -2.6
A18: 39753 | B18: 46.2 | C18: =B18-B17 -> -1.3
A19: 39783 | B19: 44.2 | C19: =B19-B18 -> -2 | D19: -0.016
A20: 39814 | B20: 42.6 | C20: =B20-B19 -> -1.6
A21: 39845 | B21: 40.2 | C21: =B21-B20 -> -2.4
A22: 39873 | B22: 43.6 | C22: =B22-B21 -> 3.4 | D22: -0.017
A23: 39904 | B23: 46.5 | C23: =B23-B22 -> 2.9
A24: 39934 | B24: 48.3 | C24: =B24-B23 -> 1.8
A25: 39965 | B25: 47.2 | C25: =B25-B24 -> -1.1 | D25: 0
A26: 39995 | B26: 45.5 | C26: =B26-B25 -> -1.7
A27: 40026 | B27: 49.3 | C27: =B27-B26 -> 3.8
A28: 40057 | B28: 53.2 | C28: =B28-B27 -> 3.9 | D28: 0.001
A29: 40087 | B29: 57.7 | C29: =B29-B28 -> 4.5
A30: 40118 | B30: 60.9 | C30: =B30-B29 -> 3.2
A31: 40148 | B31: 58.2 | C31: =B31-B30 -> -2.7 | D31: 0.007
A32: 40179 | B32: 56.3 | C32: =B32-B31 -> -1.9
A33: 40210 | B33: 54.6 | C33: =B33-B32 -> -1.7
A34: 40238 | B34: 53.8 | C34: =B34-B33 -> -0.8 | D34: 0.003
A35: 40269 | B35: 59.2 | C35: =B35-B34 -> 5.4
A36: 40299 | B36: 61.4 | C36: =B36-B35 -> 2.2
A37: 40330 | B37: 60.8 | C37: =B37-B36 -> -0.6 | D37: 0.006
A38: 40360 | B38: 61.1 | C38: =B38-B37 -> 0.3
A39: 40391 | B39: 60.4 | C39: =B39-B38 -> -0.7
A40: 40422 | B40: 58.2 | C40: =B40-B39 -> -2.2 | D40: 0.005
A41: 40452 | B41: 54.8 | C41: =B41-B40 -> -3.4
A42: 40483 | B42: 55 | C42: =B42-B41 -> 0.2
A43: 40513 | B43: 57.1 | C43: =B43-B42 -> 2.1 | D43: 0.005
A44: 40544 | B44: 58.3 | C44: =B44-B43 -> 1.2
A45: 40575 | B45: 59.7 | C45: =B45-B44 -> 1.4
A46: 40603 | B46: 60.4 | C46: =B46-B45 -> 0.7 | D46: 0.011
A47: 40634 | B47: 62.9 | C47: =B47-B46 -> 2.5
A48: 40664 | B48: 62.5 | C48: =B48-B47 -> -0.4
A49: 40695 | B49: 56.1 | C49: =B49-B48 -> -6.4 | D49: -0.001
A50: 40725 | B50: 54.2 | C50: =B50-B49 -> -1.9
A51: 40756 | B51: 52.3 | C51: =B51-B50 -> -1.9
A52: 40787 | B52: 51.5 | C52: =B52-B51 -> -0.8 | D52: 0.003
A53: 40817 | B53: 44.6 | C53: =B53-B52 -> -6.9
...

Sheet IT
A40: Date | B40: Italy Service PMI | C40: Change | D40: Italy GDP q/q
A41: 40452 | B41: 51
A42: 40483 | B42: 54.4 | C42: =B42-B41 -> 3.4
A43: 40513 | B43: 52.1 | C43: =B43-B42 -> -2.3 | D43: 0.003
A44: 40544 | B44: 53.5 | C44: =B44-B43 -> 1.4
A45: 40575 | B45: 53.1 | C45: =B45-B44 -> -0.4
A46: 40603 | B46: 53.3 | C46: =B46-B45 -> 0.2 | D46: 0.001
A47: 40634 | B47: 52.2 | C47: =B47-B46 -> -1.1
A48: 40664 | B48: 50.1 | C48: =B48-B47 -> -2.1
A49: 40695 | B49: 47.4 | C49: =B49-B48 -> -2.7 | D49: 0.002
A50: 40725 | B50: 48.6 | C50: =B50-B49 -> 1.2
A51: 40756 | B51: 48.4 | C51: =B51-B50 -> -0.2
A52: 40787 | B52: 45.8 | C52: =B52-B51 -> -2.6 | D52: -0.002
A53: 40817 | B53: 43.9 | C53: =B53-B52 -> -1.9
A54: 40848 | B54: 45.8 | C54: =B54-B53 -> 1.9
A55: 40878 | B55: 44.5 | C55: =B55-B54 -> -1.3 | D55: -0.007
A56: 40909 | B56: 44.8 | C56: =B56-B55 -> 0.3
A57: 40940 | B57: 44.1 | C57: =B57-B56 -> -0.7
A58: 40969 | B58: 44.3 | C58: =B58-B57 -> 0.2 | D58: -0.011
A59: 41000 | B59: 42.3 | C59: =B59-B58 -> -2
A60: 41030 | B60: 42.8 | C60: =B60-B59 -> 0.5
A61: 41061 | B61: 43.1 | C61: =B61-B60 -> 0.3 | D61: 0.005
A62: 41091 | B62: 43 | C62: =B62-B61 -> -0.1
A63: 41122 | B63: 44 | C63: =B63-B62 -> 1
A64: 41153 | B64: 44.5 | C64: =B64-B63 -> 0.5 | D64: -0.004
A65: 41183 | B65: 46 | C65: =B65-B64 -> 1.5
A66: 41214 | B66: 44.6 | C66: =B66-B65 -> -1.4
A67: 41244 | B67: 43.1 | C67: =B67-B66 -> -1.5 | D67: -0.009
A68: 41275 | B68: 43.9 | C68: =B68-B67 -> 0.8
A69: 41306 | B69: 43.6 | C69: =B69-B68 -> -0.3
A70: 41334 | B70: 45.5 | C70: =B70-B69 -> 1.9 | D70: -0.006
A71: 41365 | B71: 47 | C71: =B71-B70 -> 1.5
A72: 41395 | B72: 46.5 | C72: =B72-B71 -> -0.5
A73: 41426 | B73: 45.8 | C73: =B73-B72 -> -0.7 | D73: -0.003
A74: 41456 | B74: 48.7 | C74: =B74-B73 -> 2.9
A75: 41487 | B75: 48.8 | C75: =B75-B74 -> 0.1
A76: 41518 | B76: 52.7 | C76: =B76-B75 -> 3.9 | D76: -0.001
A77: 41548 | B77: 50.5 | C77: =B77-B76 -> -2.2
A78: 41579 | B78: 47.2 | C78: =B78-B77 -> -3.3
A79: 41609 | B79: 48.6 | C79: =B79-B78 -> 1.4 | D79: 0.001
...

Sheet ES
A40: Date | B40: Spain Service PMI | C40: Change | D40: Spanish GDP q/q
A41: 40452 | B41: 46.5
A42: 40483 | B42: 48.3 | C42: =B42-B41 -> 1.8
A43: 40513 | B43: 49.1 | C43: =B43-B42 -> 0.8 | D43: 0.002
A44: 40544 | B44: 50.1 | C44: =B44-B43 -> 1
A45: 40575 | B45: 50.8 | C45: =B45-B44 -> 0.7
A46: 40603 | B46: 48.7 | C46: =B46-B45 -> -2.1 | D46: 0.002
A47: 40634 | B47: 50.4 | C47: =B47-B46 -> 1.7
A48: 40664 | B48: 50.9 | C48: =B48-B47 -> 0.5
A49: 40695 | B49: 50.2 | C49: =B49-B48 -> -0.7 | D49: -0.001
A50: 40725 | B50: 46.5 | C50: =B50-B49 -> -3.7
A51: 40756 | B51: 45.2 | C51: =B51-B50 -> -1.3
A52: 40787 | B52: 44.8 | C52: =B52-B51 -> -0.4 | D52: -0.003
A53: 40817 | B53: 41.8 | C53: =B53-B52 -> -3
A54: 40848 | B54: 36.8 | C54: =B54-B53 -> -5
A55: 40878 | B55: 42.1 | C55: =B55-B54 -> 5.3 | D55: -0.004
A56: 40909 | B56: 46.1 | C56: =B56-B55 -> 4
A57: 40940 | B57: 41.9 | C57: =B57-B56 -> -4.2
A58: 40969 | B58: 46.3 | C58: =B58-B57 -> 4.4 | D58: -0.004
A59: 41000 | B59: 42.1 | C59: =B59-B58 -> -4.2
A60: 41030 | B60: 41.8 | C60: =B60-B59 -> -0.3
A61: 41061 | B61: 43.4 | C61: =B61-B60 -> 1.6 | D61: -0.005
A62: 41091 | B62: 43.7 | C62: =B62-B61 -> 0.3
A63: 41122 | B63: 44 | C63: =B63-B62 -> 0.3
A64: 41153 | B64: 40.2 | C64: =B64-B63 -> -3.8 | D64: -0.004
A65: 41183 | B65: 41.2 | C65: =B65-B64 -> 1
A66: 41214 | B66: 42.4 | C66: =B66-B65 -> 1.2
A67: 41244 | B67: 44.1 | C67: =B67-B66 -> 1.7 | D67: -0.008
A68: 41275 | B68: 47 | C68: =B68-B67 -> 2.9
A69: 41306 | B69: 44.7 | C69: =B69-B68 -> -2.3
A70: 41334 | B70: 45.3 | C70: =B70-B69 -> 0.6 | D70: -0.003
A71: 41365 | B71: 44.4 | C71: =B71-B70 -> -0.9
A72: 41395 | B72: 47.3 | C72: =B72-B71 -> 2.9
A73: 41426 | B73: 47.8 | C73: =B73-B72 -> 0.5 | D73: -0.001
A74: 41456 | B74: 48.5 | C74: =B74-B73 -> 0.7
A75: 41487 | B75: 50.5 | C75: =B75-B74 -> 2
A76: 41518 | B76: 49 | C76: =B76-B75 -> -1.5 | D76: 0.001
A77: 41548 | B77: 49.6 | C77: =B77-B76 -> 0.6
A78: 41579 | B78: 51.5 | C78: =B78-B77 -> 1.9
A79: 41609 | B79: 53.2 | C79: =B79-B78 -> 1.7 | D79: 0.002
...

Sheet IR
A40: Date | B40: Ireland Service PMI | C40: Change | D40: Ireland GDP Growth q/q
A41: 40452 | B41: 50.9
A42: 40483 | B42: 50.8 | C42: =B42-B41 -> -0.1
A43: 40513 | B43: 52.1 | C43: =B43-B42 -> 1.3 | D43: -0.01
A44: 40544 | B44: 53.6 | C44: =B44-B43 -> 1.5
A45: 40575 | B45: 55.1 | C45: =B45-B44 -> 1.5
A46: 40603 | B46: 51.1 | C46: =B46-B45 -> -4 | D46: 0.015
A47: 40634 | B47: 50.2 | C47: =B47-B46 -> -0.9
A48: 40664 | B48: 50.5 | C48: =B48-B47 -> 0.3
A49: 40695 | B49: 52.4 | C49: =B49-B48 -> 1.9 | D49: 0.015
A50: 40725 | B50: 51.7 | C50: =B50-B49 -> -0.7
A51: 40756 | B51: 51.1 | C51: =B51-B50 -> -0.6
A52: 40787 | B52: 51.3 | C52: =B52-B51 -> 0.2 | D52: -0.01
A53: 40817 | B53: 51.5 | C53: =B53-B52 -> 0.2
A54: 40848 | B54: 52.7 | C54: =B54-B53 -> 1.2
A55: 40878 | B55: 48.4 | C55: =B55-B54 -> -4.3 | D55: 0.01
A56: 40909 | B56: 48.3 | C56: =B56-B55 -> -0.1
A57: 40940 | B57: 53.3 | C57: =B57-B56 -> 5
A58: 40969 | B58: 52.1 | C58: =B58-B57 -> -1.2 | D58: -0.005
A59: 41000 | B59: 52.2 | C59: =B59-B58 -> 0.1
A60: 41030 | B60: 48.9 | C60: =B60-B59 -> -3.3
A61: 41061 | B61: 49.7 | C61: =B61-B60 -> 0.8 | D61: 0.007
A62: 41091 | B62: 49.1 | C62: =B62-B61 -> -0.6
A63: 41122 | B63: 51.7 | C63: =B63-B62 -> 2.6
A64: 41153 | B64: 53.9 | C64: =B64-B63 -> 2.2 | D64: -0.019
A65: 41183 | B65: 56.1 | C65: =B65-B64 -> 2.2
A66: 41214 | B66: 56.1 | C66: =B66-B65 -> 0
A67: 41244 | B67: 56.5 | C67: =B67-B66 -> 0.4 | D67: 0.008
A68: 41275 | B68: 56.8 | C68: =B68-B67 -> 0.3
A69: 41306 | B69: 53.6 | C69: =B69-B68 -> -3.2
A70: 41334 | B70: 52.3 | C70: =B70-B69 -> -1.3 | D70: -0.014
A71: 41365 | B71: 55.2 | C71: =B71-B70 -> 2.9
A72: 41395 | B72: 52.7 | C72: =B72-B71 -> -2.5
A73: 41426 | B73: 61.6 | C73: =B73-B72 -> 8.9 | D73: 0.011
A74: 41456 | B74: 59.6 | C74: =B74-B73 -> -2
A75: 41487 | B75: 57.2 | C75: =B75-B74 -> -2.4
A76: 41518 | B76: 56.8 | C76: =B76-B75 -> -0.4 | D76: 0.021
A77: 41548 | B77: 60.1 | C77: =B77-B76 -> 3.3
A78: 41579 | B78: 57.1 | C78: =B78-B77 -> -3
A79: 41609 | B79: 59.3 | C79: =B79-B78 -> 2.2 | D79: -0.023
...

Sheet CH
A40: Date | B40: China Service PMI | C40: Change | D40: China GDP Growth q/q
A41: 40452 | B41: 60.5
A42: 40483 | B42: 53.2 | C42: =B42-B41 -> -7.3
A43: 40513 | B43: 48.1 | C43: =B43-B42 -> -5.1 | D43: 0.024
A44: 40544 | B44: 46.5 | C44: =B44-B43 -> -1.6
A45: 40575 | B45: 44.1 | C45: =B45-B44 -> -2.4
A46: 40603 | B46: 60.2 | C46: =B46-B45 -> 16.1 | D46: 0.023
A47: 40634 | B47: 62.5 | C47: =B47-B46 -> 2.3
A48: 40664 | B48: 61.9 | C48: =B48-B47 -> -0.6
A49: 40695 | B49: 57 | C49: =B49-B48 -> -4.9 | D49: 0.025
A50: 40725 | B50: 59.6 | C50: =B50-B49 -> 2.6
A51: 40756 | B51: 58.1 | C51: =B51-B50 -> -1.5
A52: 40787 | B52: 57 | C52: =B52-B51 -> -1.1 | D52: 0.022
A53: 40817 | B53: 54.6 | C53: =B53-B52 -> -2.4
A54: 40848 | B54: 49.7 | C54: =B54-B53 -> -4.9
A55: 40878 | B55: 56 | C55: =B55-B54 -> 6.3 | D55: 0.018
A56: 40909 | B56: 52.5 | C56: =B56-B55 -> -3.5
A57: 40940 | B57: 53.9 | C57: =B57-B56 -> 1.4
A58: 40969 | B58: 53.3 | C58: =B58-B57 -> -0.6 | D58: 0.014
A59: 41000 | B59: 54.1 | C59: =B59-B58 -> 0.8
A60: 41030 | B60: 54.7 | C60: =B60-B59 -> 0.6
A61: 41061 | B61: 52.3 | C61: =B61-B60 -> -2.4 | D61: 0.021
A62: 41091 | B62: 53.1 | C62: =B62-B61 -> 0.8
A63: 41122 | B63: 52 | C63: =B63-B62 -> -1.1
A64: 41153 | B64: 54.3 | C64: =B64-B63 -> 2.3 | D64: 0.02
A65: 41183 | B65: 53.5 | C65: =B65-B64 -> -0.8
A66: 41214 | B66: 52.1 | C66: =B66-B65 -> -1.4
A67: 41244 | B67: 53.5 | C67: =B67-B66 -> 1.4 | D67: 0.019
A68: 41275 | B68: 54 | C68: =B68-B67 -> 0.5
A69: 41306 | B69: 52.1 | C69: =B69-B68 -> -1.9
A70: 41334 | B70: 54.3 | C70: =B70-B69 -> 2.2 | D70: 0.015
A71: 41365 | B71: 51.1 | C71: =B71-B70 -> -3.2
A72: 41395 | B72: 51.2 | C72: =B72-B71 -> 0.1
A73: 41426 | B73: 51.3 | C73: =B73-B72 -> 0.1 | D73: 0.018
A74: 41456 | B74: 51.3 | C74: =B74-B73 -> 0
A75: 41487 | B75: 52.8 | C75: =B75-B74 -> 1.5
A76: 41518 | B76: 52.4 | C76: =B76-B75 -> -0.4 | D76: 0.023
A77: 41548 | B77: 52.6 | C77: =B77-B76 -> 0.2
A78: 41579 | B78: 52.5 | C78: =B78-B77 -> -0.1
A79: 41609 | B79: 51.4 | C79: =B79-B78 -> -1.1 | D79: 0.017
...

Sheet AU
A40: Date | B40: Australia Service PMI | C40: Change | D40: GDP Change q/q
A41: 40452 | B41: 50.7
A42: 40483 | B42: 46.2 | C42: =B42-B41 -> -4.5
A43: 40513 | B43: 47.1 | C43: =B43-B42 -> 0.9 | D43: 0.006
A44: 40544 | B44: 45.5 | C44: =B44-B43 -> -1.6
A45: 40575 | B45: 48.7 | C45: =B45-B44 -> 3.2
A46: 40603 | B46: 46.5 | C46: =B46-B45 -> -2.2 | D46: -0.005
A47: 40634 | B47: 51.5 | C47: =B47-B46 -> 5
A48: 40664 | B48: 49.9 | C48: =B48-B47 -> -1.6
A49: 40695 | B49: 48.5 | C49: =B49-B48 -> -1.4 | D49: 0.012
A50: 40725 | B50: 48.8 | C50: =B50-B49 -> 0.3
A51: 40756 | B51: 52.1 | C51: =B51-B50 -> 3.3
A52: 40787 | B52: 50.3 | C52: =B52-B51 -> -1.8 | D52: 0.012
A53: 40817 | B53: 48.8 | C53: =B53-B52 -> -1.5
A54: 40848 | B54: 47.7 | C54: =B54-B53 -> -1.1
A55: 40878 | B55: 49 | C55: =B55-B54 -> 1.3 | D55: 0.006
A56: 40909 | B56: 51.9 | C56: =B56-B55 -> 2.9
A57: 40940 | B57: 46.7 | C57: =B57-B56 -> -5.2
A58: 40969 | B58: 47 | C58: =B58-B57 -> 0.3 | D58: 0.013
A59: 41000 | B59: 39.6 | C59: =B59-B58 -> -7.4
A60: 41030 | B60: 43.5 | C60: =B60-B59 -> 3.9
A61: 41061 | B61: 48.8 | C61: =B61-B60 -> 5.3 | D61: 0.005
A62: 41091 | B62: 46.5 | C62: =B62-B61 -> -2.3
A63: 41122 | B63: 42.4 | C63: =B63-B62 -> -4.1
A64: 41153 | B64: 41.9 | C64: =B64-B63 -> -0.5 | D64: 0.008
A65: 41183 | B65: 42.8 | C65: =B65-B64 -> 0.9
A66: 41214 | B66: 47.1 | C66: =B66-B65 -> 4.3
A67: 41244 | B67: 46.3 | C67: =B67-B66 -> -0.8 | D67: 0.007
A68: 41275 | B68: 45.4 | C68: =B68-B67 -> -0.9
A69: 41306 | B69: 48.5 | C69: =B69-B68 -> 3.1
A70: 41334 | B70: 49.6 | C70: =B70-B69 -> 1.1 | D70: 0.005
A71: 41365 | B71: 44.1 | C71: =B71-B70 -> -5.5
A72: 41395 | B72: 40.6 | C72: =B72-B71 -> -3.5
A73: 41426 | B73: 41.5 | C73: =B73-B72 -> 0.9 | D73: 0.007
A74: 41456 | B74: 39.4 | C74: =B74-B73 -> -2.1
A75: 41487 | B75: 39 | C75: =B75-B74 -> -0.4
A76: 41518 | B76: 47.1 | C76: =B76-B75 -> 8.1 | D76: 0.006
A77: 41548 | B77: 47.9 | C77: =B77-B76 -> 0.8
A78: 41579 | B78: 48.9 | C78: =B78-B77 -> 1
A79: 41609 | B79: 46.1 | C79: =B79-B78 -> -2.8 | D79: 0.008
...

Sheet JP
A40: Date | B40: Japan Service PMI | C40: Change | D40: Japan GDP Growth q/q
A41: 40452 | B41: 47.2
A42: 40483 | B42: 49.5 | C42: =B42-B41 -> 2.3
A43: 40513 | B43: 50.1 | C43: =B43-B42 -> 0.6 | D43: -0.005
A44: 40544 | B44: 48.1 | C44: =B44-B43 -> -2
A45: 40575 | B45: 49.8 | C45: =B45-B44 -> 1.7
A46: 40603 | B46: 35.3 | C46: =B46-B45 -> -14.5 | D46: -0.018
A47: 40634 | B47: 35 | C47: =B47-B46 -> -0.3
A48: 40664 | B48: 43.8 | C48: =B48-B47 -> 8.8
A49: 40695 | B49: 45.4 | C49: =B49-B48 -> 1.6 | D49: -0.007
A50: 40725 | B50: 45.3 | C50: =B50-B49 -> -0.1
A51: 40756 | B51: 44.1 | C51: =B51-B50 -> -1.2
A52: 40787 | B52: 46.4 | C52: =B52-B51 -> 2.3 | D52: 0.026
A53: 40817 | B53: 52.3 | C53: =B53-B52 -> 5.9
A54: 40848 | B54: 49.5 | C54: =B54-B53 -> -2.8
A55: 40878 | B55: 50.4 | C55: =B55-B54 -> 0.9 | D55: 0.002
A56: 40909 | B56: 51 | C56: =B56-B55 -> 0.6
A57: 40940 | B57: 51.2 | C57: =B57-B56 -> 0.2
A58: 40969 | B58: 53.7 | C58: =B58-B57 -> 2.5 | D58: 0.009
A59: 41000 | B59: 51 | C59: =B59-B58 -> -2.7
A60: 41030 | B60: 50.5 | C60: =B60-B59 -> -0.5
A61: 41061 | B61: 49.5 | C61: =B61-B60 -> -1 | D61: -0.005
A62: 41091 | B62: 48.7 | C62: =B62-B61 -> -0.8
A63: 41122 | B63: 47.5 | C63: =B63-B62 -> -1.2
A64: 41153 | B64: 48.8 | C64: =B64-B63 -> 1.3 | D64: -0.008
A65: 41183 | B65: 49.7 | C65: =B65-B64 -> 0.9
A66: 41214 | B66: 49.1 | C66: =B66-B65 -> -0.6
A67: 41244 | B67: 50.1 | C67: =B67-B66 -> 1 | D67: 0.001
A68: 41275 | B68: 50.4 | C68: =B68-B67 -> 0.3
A69: 41306 | B69: 51.3 | C69: =B69-B68 -> 0.9
A70: 41334 | B70: 53.4 | C70: =B70-B69 -> 2.1 | D70: 0.012
A71: 41365 | B71: 52.5 | C71: =B71-B70 -> -0.9
A72: 41395 | B72: 54.8 | C72: =B72-B71 -> 2.3
A73: 41426 | B73: 52.1 | C73: =B73-B72 -> -2.7 | D73: 0.009
A74: 41456 | B74: 50.6 | C74: =B74-B73 -> -1.5
A75: 41487 | B75: 51.2 | C75: =B75-B74 -> 0.6
A76: 41518 | B76: 53 | C76: =B76-B75 -> 1.8 | D76: 0.003
A77: 41548 | B77: 55.3 | C77: =B77-B76 -> 2.3
A78: 41579 | B78: 51.8 | C78: =B78-B77 -> -3.5
A79: 41609 | B79: 52.1 | C79: =B79-B78 -> 0.3 | D79: 0.001
...

Sheet BR
A40: Date | B40: Brazil Service PMI | C40: Change | D40: Brazil GDP Growth q/q
A41: 40452 | B41: 51.8
A42: 40483 | B42: 52.1 | C42: =B42-B41 -> 0.3
A43: 40513 | B43: 50.2 | C43: =B43-B42 -> -1.9 | D43: 0.011
A44: 40544 | B44: 51.2 | C44: =B44-B43 -> 1
A45: 40575 | B45: 52.7 | C45: =B45-B44 -> 1.5
A46: 40603 | B46: 53.5 | C46: =B46-B45 -> 0.8 | D46: 0.006
A47: 40634 | B47: 53.2 | C47: =B47-B46 -> -0.3
A48: 40664 | B48: 53.3 | C48: =B48-B47 -> 0.1
A49: 40695 | B49: 52.1 | C49: =B49-B48 -> -1.2 | D49: 0.005
A50: 40725 | B50: 53.7 | C50: =B50-B49 -> 1.6
A51: 40756 | B51: 52.1 | C51: =B51-B50 -> -1.6
A52: 40787 | B52: 50.5 | C52: =B52-B51 -> -1.6 | D52: -0.001
A53: 40817 | B53: 53.6 | C53: =B53-B52 -> 3.1
A54: 40848 | B54: 52.6 | C54: =B54-B53 -> -1
A55: 40878 | B55: 54.8 | C55: =B55-B54 -> 2.2 | D55: 0.001
A56: 40909 | B56: 55 | C56: =B56-B55 -> 0.2
A57: 40940 | B57: 57.1 | C57: =B57-B56 -> 2.1
A58: 40969 | B58: 53.8 | C58: =B58-B57 -> -3.3 | D58: 0.001
A59: 41000 | B59: 54.4 | C59: =B59-B58 -> 0.6
A60: 41030 | B60: 49.7 | C60: =B60-B59 -> -4.7
A61: 41061 | B61: 53 | C61: =B61-B60 -> 3.3 | D61: 0.001
A62: 41091 | B62: 48.9 | C62: =B62-B61 -> -4.1
A63: 41122 | B63: 48.1 | C63: =B63-B62 -> -0.8
A64: 41153 | B64: 52.8 | C64: =B64-B63 -> 4.7 | D64: 0.006
A65: 41183 | B65: 50.4 | C65: =B65-B64 -> -2.4
A66: 41214 | B66: 52.5 | C66: =B66-B65 -> 2.1
A67: 41244 | B67: 53.2 | C67: =B67-B66 -> 0.7 | D67: 0.009
A68: 41275 | B68: 54.5 | C68: =B68-B67 -> 1.3
A69: 41306 | B69: 52.1 | C69: =B69-B68 -> -2.4
A70: 41334 | B70: 50.3 | C70: =B70-B69 -> -1.8 | D70: 0
A71: 41365 | B71: 51 | C71: =B71-B70 -> 0.7
A72: 41395 | B72: 51 | C72: =B72-B71 -> 0
A73: 41426 | B73: 50.3 | C73: =B73-B72 -> -0.7 | D73: 0.018
A74: 41456 | B74: 49.7 | C74: =B74-B73 -> -0.6
A75: 41487 | B75: 50.7 | C75: =B75-B74 -> 1
A76: 41518 | B76: 52.1 | C76: =B76-B75 -> 1.4 | D76: -0.005
A77: 41548 | B77: 52.3 | C77: =B77-B76 -> 0.2
A78: 41579 | B78: 51.7 | C78: =B78-B77 -> -0.6
A79: 41609 | B79: 50.5 | C79: =B79-B78 -> -1.2 | D79: 0.007
...

Sheet IN
A40: Date | B40: India Service PMI | C40: Change | D40: India GDP Growth q/q
A41: 40452 | B41: 58.4
A42: 40483 | B42: 61.3 | C42: =B42-B41 -> 2.9
A43: 40513 | B43: 62.1 | C43: =B43-B42 -> 0.8 | D43: 0.023
A44: 40544 | B44: 59.4 | C44: =B44-B43 -> -2.7
A45: 40575 | B45: 61 | C45: =B45-B44 -> 1.6
A46: 40603 | B46: 60 | C46: =B46-B45 -> -1 | D46: 0.019
A47: 40634 | B47: 59.2 | C47: =B47-B46 -> -0.8
A48: 40664 | B48: 57.7 | C48: =B48-B47 -> -1.5
A49: 40695 | B49: 56.1 | C49: =B49-B48 -> -1.6 | D49: 0.016
A50: 40725 | B50: 58.2 | C50: =B50-B49 -> 2.1
A51: 40756 | B51: 56.7 | C51: =B51-B50 -> -1.5
A52: 40787 | B52: 49.8 | C52: =B52-B51 -> -6.9 | D52: 0.011
A53: 40817 | B53: 49.1 | C53: =B53-B52 -> -0.7
A54: 40848 | B54: 53.2 | C54: =B54-B53 -> 4.1
A55: 40878 | B55: 54.2 | C55: =B55-B54 -> 1 | D55: 0.011
A56: 40909 | B56: 55.1 | C56: =B56-B55 -> 0.9
A57: 40940 | B57: 53.4 | C57: =B57-B56 -> -1.7
A58: 40969 | B58: 54.1 | C58: =B58-B57 -> 0.7 | D58: 0.013
A59: 41000 | B59: 52.3 | C59: =B59-B58 -> -1.8
A60: 41030 | B60: 52.8 | C60: =B60-B59 -> 0.5
A61: 41061 | B61: 54.7 | C61: =B61-B60 -> 1.9 | D61: 0.014
A62: 41091 | B62: 54.3 | C62: =B62-B61 -> -0.4
A63: 41122 | B63: 54.2 | C63: =B63-B62 -> -0.1
A64: 41153 | B64: 55 | C64: =B64-B63 -> 0.8 | D64: 0.007
A65: 41183 | B65: 55.8 | C65: =B65-B64 -> 0.8
A66: 41214 | B66: 53.8 | C66: =B66-B65 -> -2
A67: 41244 | B67: 52.1 | C67: =B67-B66 -> -1.7 | D67: 0.015
A68: 41275 | B68: 57.5 | C68: =B68-B67 -> 5.4
A69: 41306 | B69: 54.2 | C69: =B69-B68 -> -3.3
A70: 41334 | B70: 51.4 | C70: =B70-B69 -> -2.8 | D70: 0.01
A71: 41365 | B71: 50.7 | C71: =B71-B70 -> -0.7
A72: 41395 | B72: 53.6 | C72: =B72-B71 -> 2.9
A73: 41426 | B73: 51.7 | C73: =B73-B72 -> -1.9 | D73: 0.007
A74: 41456 | B74: 47.9 | C74: =B74-B73 -> -3.8
A75: 41487 | B75: 47.6 | C75: =B75-B74 -> -0.3
A76: 41518 | B76: 44.6 | C76: =B76-B75 -> -3 | D76: 0.018
A77: 41548 | B77: 47.1 | C77: =B77-B76 -> 2.5
A78: 41579 | B78: 47.2 | C78: =B78-B77 -> 0.1
A79: 41609 | B79: 47.9 | C79: =B79-B78 -> 0.7 | D79: 0.01
...

Sheet RS
A40: Date | B40: Russia Service PMI | C40: Change | D40: Russian GDP Growth q/q
A41: 40452 | B41: 54.7
A42: 40483 | B42: 54.1 | C42: =B42-B41 -> -0.6
A43: 40513 | B43: 53.4 | C43: =B43-B42 -> -0.7 | D43: 0.01
A44: 40544 | B44: 52.4 | C44: =B44-B43 -> -1
A45: 40575 | B45: 53.4 | C45: =B45-B44 -> 1
A46: 40603 | B46: 53.3 | C46: =B46-B45 -> -0.1 | D46: 0.009
A47: 40634 | B47: 55.8 | C47: =B47-B46 -> 2.5
A48: 40664 | B48: 57.6 | C48: =B48-B47 -> 1.8
A49: 40695 | B49: 55.1 | C49: =B49-B48 -> -2.5 | D49: 0.013
A50: 40725 | B50: 56.9 | C50: =B50-B49 -> 1.8
A51: 40756 | B51: 55.1 | C51: =B51-B50 -> -1.8
A52: 40787 | B52: 53.3 | C52: =B52-B51 -> -1.8 | D52: 0.014
A53: 40817 | B53: 53.5 | C53: =B53-B52 -> 0.2
A54: 40848 | B54: 54.8 | C54: =B54-B53 -> 1.3
A55: 40878 | B55: 53.8 | C55: =B55-B54 -> -1 | D55: 0.015
A56: 40909 | B56: 56.5 | C56: =B56-B55 -> 2.7
A57: 40940 | B57: 55.3 | C57: =B57-B56 -> -1.2
A58: 40969 | B58: 54.4 | C58: =B58-B57 -> -0.9 | D58: 0.008
A59: 41000 | B59: 52.6 | C59: =B59-B58 -> -1.8
A60: 41030 | B60: 54.9 | C60: =B60-B59 -> 2.3
A61: 41061 | B61: 53.2 | C61: =B61-B60 -> -1.7 | D61: 0.006
A62: 41091 | B62: 52 | C62: =B62-B61 -> -1.2
A63: 41122 | B63: 52.6 | C63: =B63-B62 -> 0.6
A64: 41153 | B64: 54.5 | C64: =B64-B63 -> 1.9 | D64: 0.003
A65: 41183 | B65: 57.3 | C65: =B65-B64 -> 2.8
A66: 41214 | B66: 57.1 | C66: =B66-B65 -> -0.2
A67: 41244 | B67: 56.1 | C67: =B67-B66 -> -1 | D67: -0.001
A68: 41275 | B68: 55.7 | C68: =B68-B67 -> -0.4
A69: 41306 | B69: 56.1 | C69: =B69-B68 -> 0.4
A70: 41334 | B70: 54.6 | C70: =B70-B69 -> -1.5 | D70: 0.002
A71: 41365 | B71: 53 | C71: =B71-B70 -> -1.6
A72: 41395 | B72: 51.4 | C72: =B72-B71 -> -1.6
A73: 41426 | B73: 48.8 | C73: =B73-B72 -> -2.6 | D73: 0.004
A74: 41456 | B74: 48.7 | C74: =B74-B73 -> -0.1
A75: 41487 | B75: 51.8 | C75: =B75-B74 -> 3.1
A76: 41518 | B76: 51.5 | C76: =B76-B75 -> -0.3 | D76: 0.006
A77: 41548 | B77: 52.5 | C77: =B77-B76 -> 1
A78: 41579 | B78: 52.9 | C78: =B78-B77 -> 0.4
A79: 41609 | B79: 51.4 | C79: =B79-B78 -> -1.5 | D79: 0.009
...

Sheet All
A1: Date | B1: Global | C1: US | D1: China | E1: EA | F1: Japan | G1: Germany | H1: France | I1: UK | J1: Italy | K1: Spain | L1: Brazil | M1: Russia | N1: India | O1: Australia | P1: Ireland
A2: 41091 | B2: =Global!B62 -> 49.2 | C2: =US!B63 -> No data | D2: =CH!B62 -> 53.1 | E2: =EZ!B62 -> 47.9 | F2: =JP!B62 -> 48.7 | G2: =DE!B62 -> 50.3 | H2: =FR!B62 -> 50 | I2: =UK!B62 -> 51.3 | J2: =IT!B62 -> 43 | K2: =ES!B62 -> 43.7 | L2: =BR!B62 -> 48.9 | M2: =RS!B62 -> 52 | N2: =IN!B62 -> 54.3 | O2: =AU!B62 -> 46.5 | P2: =IR!B62 -> 49.1
A3: 41122 | B3: =Global!B63 -> 52.4 | C3: =US!B64 -> No data | D3: =CH!B63 -> 52 | E3: =EZ!B63 -> 47.2 | F3: =JP!B63 -> 47.5 | G3: =DE!B63 -> 48.3 | H3: =FR!B63 -> 49.2 | I3: =UK!B63 -> 51 | J3: =IT!B63 -> 44 | K3: =ES!B63 -> 44 | L3: =BR!B63 -> 48.1 | M3: =RS!B63 -> 52.6 | N3: =IN!B63 -> 54.2 | O3: =AU!B63 -> 42.4 | P3: =IR!B63 -> 51.7
A4: 41153 | B4: =Global!B64 -> 53.1 | C4: =US!B65 -> No data | D4: =CH!B64 -> 54.3 | E4: =EZ!B64 -> 46.1 | F4: =JP!B64 -> 48.8 | G4: =DE!B64 -> 49.7 | H4: =FR!B64 -> 45 | I4: =UK!B64 -> 53.7 | J4: =IT!B64 -> 44.5 | K4: =ES!B64 -> 40.2 | L4: =BR!B64 -> 52.8 | M4: =RS!B64 -> 54.5 | N4: =IN!B64 -> 55 | O4: =AU!B64 -> 41.9 | P4: =IR!B64 -> 53.9
A5: 41183 | B5: =Global!B65 -> 53.6 | C5: =US!B66 -> No data | D5: =CH!B65 -> 53.5 | E5: =EZ!B65 -> 46 | F5: =JP!B65 -> 49.7 | G5: =DE!B65 -> 48.4 | H5: =FR!B65 -> 44.6 | I5: =UK!B65 -> 52.2 | J5: =IT!B65 -> 46 | K5: =ES!B65 -> 41.2 | L5: =BR!B65 -> 50.4 | M5: =RS!B65 -> 57.3 | N5: =IN!B65 -> 55.8 | O5: =AU!B65 -> 42.8 | P5: =IR!B65 -> 56.1
A6: 41214 | B6: =Global!B66 -> 54.8 | C6: =US!B67 -> No data | D6: =CH!B66 -> 52.1 | E6: =EZ!B66 -> 46.7 | F6: =JP!B66 -> 49.1 | G6: =DE!B66 -> 49.7 | H6: =FR!B66 -> 45.8 | I6: =UK!B66 -> 50.6 | J6: =IT!B66 -> 44.6 | K6: =ES!B66 -> 42.4 | L6: =BR!B66 -> 52.5 | M6: =RS!B66 -> 57.1 | N6: =IN!B66 -> 53.8 | O6: =AU!B66 -> 47.1 | P6: =IR!B66 -> 56.1
A7: 41244 | B7: =Global!B67 -> 54.8 | C7: =US!B68 -> No data | D7: =CH!B67 -> 53.5 | E7: =EZ!B67 -> 47.2 | F7: =JP!B67 -> 50.1 | G7: =DE!B67 -> 55.7 | H7: =FR!B67 -> 44.1 | I7: =UK!B67 -> 50.2 | J7: =IT!B67 -> 43.1 | K7: =ES!B67 -> 44.1 | L7: =BR!B67 -> 53.2 | M7: =RS!B67 -> 56.1 | N7: =IN!B67 -> 52.1 | O7: =AU!B67 -> 46.3 | P7: =IR!B67 -> 56.5
A8: 41275 | B8: =Global!B68 -> 53.6 | C8: =US!B69 -> No data | D8: =CH!B68 -> 54 | E8: =EZ!B68 -> 48.6 | F8: =JP!B68 -> 50.4 | G8: =DE!B68 -> 54.7 | H8: =FR!B68 -> 43.6 | I8: =UK!B68 -> 51.5 | J8: =IT!B68 -> 43.9 | K8: =ES!B68 -> 47 | L8: =BR!B68 -> 54.5 | M8: =RS!B68 -> 55.7 | N8: =IN!B68 -> 57.5 | O8: =AU!B68 -> 45.4 | P8: =IR!B68 -> 56.8
A9: 41306 | B9: =Global!B69 -> 53.2 | C9: =US!B70 -> No data | D9: =CH!B69 -> 52.1 | E9: =EZ!B69 -> 47.9 | F9: =JP!B69 -> 51.3 | G9: =DE!B69 -> 50.9 | H9: =FR!B69 -> 43.7 | I9: =UK!B69 -> 51.8 | J9: =IT!B69 -> 43.6 | K9: =ES!B69 -> 44.7 | L9: =BR!B69 -> 52.1 | M9: =RS!B69 -> 56.1 | N9: =IN!B69 -> 54.2 | O9: =AU!B69 -> 48.5 | P9: =IR!B69 -> 53.6
A10: 41334 | B10: =Global!B70 -> 53.4 | C10: =US!B71 -> No data | D10: =CH!B70 -> 54.3 | E10: =EZ!B70 -> 46.4 | F10: =JP!B70 -> 53.4 | G10: =DE!B70 -> 49.6 | H10: =FR!B70 -> 41.3 | I10: =UK!B70 -> 52.4 | J10: =IT!B70 -> 45.5 | K10: =ES!B70 -> 45.3 | L10: =BR!B70 -> 50.3 | M10: =RS!B70 -> 54.6 | N10: =IN!B70 -> 51.4 | O10: =AU!B70 -> 49.6 | P10: =IR!B70 -> 52.3
